Workbook

Sheet README_Audit
A1: DATA CENTER COOLING INVESTMENT MODEL — REBUILT v3.0
A2: Rebuilt April 2026 | Institutional audit + structural overhaul of v2.1
A4: READING ORDER
A5: 1. README_Audit — this tab; audit findings & rebuild rationale
A6: 2. Control_Panel — every tunable assumption; one source of truth
A7: 3. Demand_Constrained — constraint-based DC capacity & cooling TAM build
A8: 4. Cooling_TAM_Bridge — air vs liquid TAM split with replacement vs new-build
A9: 5. Revenue_Linkage — TAM × Share × Attach × Timing per company (REBUILT)
A10: 6. Valuation — multiple-based + DCF cross-check per company
A11: 7. Scorecard — rubric-driven; valuation now a category (REBUILT)
A12: 8. Portfolio — bottom-up returns from valuation; correlation buckets
A13: 9. Scenario_Returns — mechanically derived bear/base/bull per name
... A110: The delta is almost entirely valuation-driven, not demand-driven.

Sheet Control_Panel
A1: CONTROL PANEL — All tunable model inputs
A2: Edit BLUE cells only. All other tabs reference these. Do not hardcode in downstream tabs.
A4: GLOBAL DISCOUNTING | B4: Bear | C4: Base | D4: Bull | E4: Unit | F4: Source / Note
A5: Risk-free rate (10yr UST) | B5: 0.043 | C5: 0.043 | D5: 0.043 | E5: % | F5: Apr 2026 spot
A6: Equity risk premium | B6: 0.06 | C6: 0.055 | D6: 0.05 | E6: % | F6: Damodaran ERP +/- regime
A7: Terminal growth | B7: 0.02 | C7: 0.025 | D7: 0.03 | E7: % | F7: GDP-anchored; bull = +50bps
A8: Multiple compression haircut (bear) | B8: 0.3 | E8: % | F8: Applied to current EV/EBITDA in bear case
A10: DEMAND — US DC ELECTRICITY (TWh) | B10: Bear | C10: Base | D10: Bull | E10: Unit | F10: Rationale
A11: 2023 actual | B11: 176 | C11: 176 | D11: 176 | E11: TWh | F11: IEA / EPRI baseline
A12: 2030E unconstrained | B12: 420 | C12: 580 | D12: 780 | E12: TWh | F12: Bear=efficiency-led; Base=Dell'Oro/IEA mid; Bull=BCG/GS high. NOT yet constraint-gated.
A13: Implied CAGR 2023-2030 | B13: =(B12/B11)^(1/7)-1 -> 0.13230226 | C13: =(C12/C11)^(1/7)-1 -> 0.18573572 | D13: =(D12/D11)^(1/7)-1 -> 0.23699757 | E13: % | F13: Calculated; 14-24% range vs v2.1 22% point estimate
A15: CONSTRAINT GATES (the difference between physics-possible and underwritten) | B15: Bear | C15: Base | D15: Bull | E15: Unit | F15: Note
A16: Avg load factor of new DC capacity | B16: 0.65 | C16: 0.7 | D16: 0.75 | E16: % | F16: AI training → higher utilization
A17: Annual interconnection capacity addable (US, GW) | B17: 12 | C17: 18 | D17: 26 | E17: GW | F17: Bear: queue lag persists; Bull: FERC reform + behind-meter gas
A18: Effective US DC capacity 2030E (GW) | B18: =MIN(B12*1000/(B16*8760),B17*5+25) -> 73.761855 | C18: =MIN(C12*1000/(C16*8760),C17*5+25) -> 94.58578 | D18: =MIN(D12*1000/(D16*8760),D17*5+25) -> 118.72146 | E18: GW | F18: MIN(physics-implied, 2025 base 25 + 5 yrs of additions)
A19: Constrained 2030E electricity (TWh) | B19: =B18*B16*8760/1000 -> 420 | C19: =C18*C16*8760/1000 -> 580 | D19: =D18*D16*8760/1000 -> 780 | E19: TWh | F19: Power demand AFTER infrastructure constraint binds
A21: CAPEX INTENSITY | B21: Bear | C21: Base | D21: Bull | E21: Unit | F21: Source
A22: DC physical infra capex per MW | B22: 10 | C22: 12 | D22: 14 | E22: $M/MW | F22: Hyperscale benchmarks; excludes silicon
A23: Cooling % of physical infra capex | B23: 0.14 | C23: 0.17 | D23: 0.2 | E23: % | F23: Industry: 12-22%; rises with rack density
A24: Liquid cooling % of NEW cooling spend 2025 | B24: 0.25 | C24: 0.32 | D24: 0.4 | E24: % | F24: NVT, VRT 2025 disclosures
A25: Liquid cooling % of NEW cooling spend 2030 | B25: 0.5 | C25: 0.62 | D25: 0.72 | E25: % | F25: NEW build only; installed base far lower
A26: Residual air/HVAC required even with liquid (% of liquid spend) | B26: 0.3 | C26: 0.35 | D26: 0.4 | E26: % | F26: Heat rejection, ancillary loads, redundancy — never zero
A27: Replacement cycle years | B27: 8 | C27: 7 | D27: 6 | E27: yrs | F27: Faster cycle in bull = more recurring
A29: INSTALLED BASE (for retrofit / replacement flow)
A30: 2025 installed US DC capacity (GW) | B30: 35 | C30: 35 | D30: 35 | E30: GW | F30: Synergy/Dell'Oro
A31: % installed base liquid-cooled today | B31: 0.05 | C31: 0.07 | D31: 0.1 | E31: % | F31: NVT Q4-25: <30%, but most are partial

Sheet Demand_Constrained
A1: DEMAND MODEL — constraint-gated
A2: Three scenarios; demand can be capped by interconnection. New MW additions feed Cooling TAM Bridge.
A4: Metric / Scenario | B4: 2023 | C4: 2024 | D4: 2025 | E4: 2026 | F4: 2027 | G4: 2028 | H4: 2029 | I4: 2030
A5: US DC ELECTRICITY (TWh) — UNCONSTRAINED
A6: Bear | B6: =Control_Panel!B11 -> 176 | C6: =Control_Panel!B11*(Control_Panel!B12/Control_Panel!B11)^(1/7) -> 199.2852 | D6: =Control_Panel!B11*(Control_Panel!B12/Control_Panel!B11)^(2/7) -> 225.65108 | E6: =Control_Panel!B11*(Control_Panel!B12/Control_Panel!B11)^(3/7) -> 255.50523 | F6: =Control_Panel!B11*(Control_Panel!B12/Control_Panel!B11)^(4/7) -> 289.30915 | G6: =Control_Panel!B11*(Control_Panel!B12/Control_Panel!B11)^(5/7) -> 327.5854 | H6: =Control_Panel!B11*(Control_Panel!B12/Control_Panel!B11)^(6/7) -> 370.92569 | I6: =Control_Panel!B12 -> 420
A7: Base | B7: =Control_Panel!C11 -> 176 | C7: =Control_Panel!C11*(Control_Panel!C12/Control_Panel!C11)^(1/7) -> 208.68949 | D7: =Control_Panel!C11*(Control_Panel!C12/Control_Panel!C11)^(2/7) -> 247.45058 | E7: =Control_Panel!C11*(Control_Panel!C12/Control_Panel!C11)^(3/7) -> 293.41099 | F7: =Control_Panel!C11*(Control_Panel!C12/Control_Panel!C11)^(4/7) -> 347.90789 | G7: =Control_Panel!C11*(Control_Panel!C12/Control_Panel!C11)^(5/7) -> 412.52682 | H7: =Control_Panel!C11*(Control_Panel!C12/Control_Panel!C11)^(6/7) -> 489.14778 | I7: =Control_Panel!C12 -> 580
A8: Bull | B8: =Control_Panel!D11 -> 176 | C8: =Control_Panel!D11*(Control_Panel!D12/Control_Panel!D11)^(1/7) -> 217.71157 | D8: =Control_Panel!D11*(Control_Panel!D12/Control_Panel!D11)^(2/7) -> 269.30869 | E8: =Control_Panel!D11*(Control_Panel!D12/Control_Panel!D11)^(3/7) -> 333.13419 | F8: =Control_Panel!D11*(Control_Panel!D12/Control_Panel!D11)^(4/7) -> 412.08619 | G8: =Control_Panel!D11*(Control_Panel!D12/Control_Panel!D11)^(5/7) -> 509.74962 | H8: =Control_Panel!D11*(Control_Panel!D12/Control_Panel!D11)^(6/7) -> 630.55904 | I8: =Control_Panel!D12 -> 780
A10: CONSTRAINT GATE: max physically deliverable (TWh)
A11: Bear cap | B11: =Control_Panel!$B$19*0/7+Control_Panel!$B$11*(7-0)/7 -> 176 | C11: =Control_Panel!$B$19*1/7+Control_Panel!$B$11*(7-1)/7 -> 210.85714 | D11: =Control_Panel!$B$19*2/7+Control_Panel!$B$11*(7-2)/7 -> 245.71429 | E11: =Control_Panel!$B$19*3/7+Control_Panel!$B$11*(7-3)/7 -> 280.57143 | F11: =Control_Panel!$B$19*4/7+Control_Panel!$B$11*(7-4)/7 -> 315.42857 | G11: =Control_Panel!$B$19*5/7+Control_Panel!$B$11*(7-5)/7 -> 350.28571 | H11: =Control_Panel!$B$19*6/7+Control_Panel!$B$11*(7-6)/7 -> 385.14286 | I11: =Control_Panel!$B$19*7/7+Control_Panel!$B$11*(7-7)/7 -> 420
A12: Base cap | B12: =Control_Panel!$C$19*0/7+Control_Panel!$C$11*(7-0)/7 -> 176 | C12: =Control_Panel!$C$19*1/7+Control_Panel!$C$11*(7-1)/7 -> 233.71429 | D12: =Control_Panel!$C$19*2/7+Control_Panel!$C$11*(7-2)/7 -> 291.42857 | E12: =Control_Panel!$C$19*3/7+Control_Panel!$C$11*(7-3)/7 -> 349.14286 | F12: =Control_Panel!$C$19*4/7+Control_Panel!$C$11*(7-4)/7 -> 406.85714 | G12: =Control_Panel!$C$19*5/7+Control_Panel!$C$11*(7-5)/7 -> 464.57143 | H12: =Control_Panel!$C$19*6/7+Control_Panel!$C$11*(7-6)/7 -> 522.28571 | I12: =Control_Panel!$C$19*7/7+Control_Panel!$C$11*(7-7)/7 -> 580
A13: Bull cap | B13: =Control_Panel!$D$19*0/7+Control_Panel!$D$11*(7-0)/7 -> 176 | C13: =Control_Panel!$D$19*1/7+Control_Panel!$D$11*(7-1)/7 -> 262.28571 | D13: =Control_Panel!$D$19*2/7+Control_Panel!$D$11*(7-2)/7 -> 348.57143 | E13: =Control_Panel!$D$19*3/7+Control_Panel!$D$11*(7-3)/7 -> 434.85714 | F13: =Control_Panel!$D$19*4/7+Control_Panel!$D$11*(7-4)/7 -> 521.14286 | G13: =Control_Panel!$D$19*5/7+Control_Panel!$D$11*(7-5)/7 -> 607.42857 | H13: =Control_Panel!$D$19*6/7+Control_Panel!$D$11*(7-6)/7 -> 693.71429 | I13: =Control_Panel!$D$19*7/7+Control_Panel!$D$11*(7-7)/7 -> 780
A15: CONSTRAINED DEMAND (TWh) = MIN(unconstrained, cap)
A16: Bear | B16: =MIN(B6,B11) -> 176 | C16: =MIN(C6,C11) -> 199.2852 | D16: =MIN(D6,D11) -> 225.65108 | E16: =MIN(E6,E11) -> 255.50523 | F16: =MIN(F6,F11) -> 289.30915 | G16: =MIN(G6,G11) -> 327.5854 | H16: =MIN(H6,H11) -> 370.92569 | I16: =MIN(I6,I11) -> 420
A17: Base | B17: =MIN(B7,B12) -> 176 | C17: =MIN(C7,C12) -> 208.68949 | D17: =MIN(D7,D12) -> 247.45058 | E17: =MIN(E7,E12) -> 293.41099 | F17: =MIN(F7,F12) -> 347.90789 | G17: =MIN(G7,G12) -> 412.52682 | H17: =MIN(H7,H12) -> 489.14778 | I17: =MIN(I7,I12) -> 580
A18: Bull | B18: =MIN(B8,B13) -> 176 | C18: =MIN(C8,C13) -> 217.71157 | D18: =MIN(D8,D13) -> 269.30869 | E18: =MIN(E8,E13) -> 333.13419 | F18: =MIN(F8,F13) -> 412.08619 | G18: =MIN(G8,G13) -> 509.74962 | H18: =MIN(H8,H13) -> 630.55904 | I18: =MIN(I8,I13) -> 780
A20: IMPLIED ANNUAL NEW MW ADDITIONS (Base scenario)
A21: Cumulative GW (Base) | B21: =B17*1000/(Control_Panel!$C$16*8760) -> 28.701892 | C21: =C17*1000/(Control_Panel!$C$16*8760) -> 34.032858 | D21: =D17*1000/(Control_Panel!$C$16*8760) -> 40.353976 | E21: =E17*1000/(Control_Panel!$C$16*8760) -> 47.849151 | F21: =F17*1000/(Control_Panel!$C$16*8760) -> 56.736447 | G21: =G17*1000/(Control_Panel!$C$16*8760) -> 67.274432 | H21: =H17*1000/(Control_Panel!$C$16*8760) -> 79.769697 | I21: =I17*1000/(Control_Panel!$C$16*8760) -> 94.58578
A22: New GW added (Base) | B22: =0 -> 0 | C22: =C21-B21 -> 5.3309666 | D22: =D21-C21 -> 6.3211175 | E22: =E21-D21 -> 7.4951748 | F22: =F21-E21 -> 8.8872965 | G22: =G21-F21 -> 10.537985 | H22: =H21-G21 -> 12.495265 | I22: =I21-H21 -> 14.816082
A24: COOLING TYPE MIX — NEW BUILDS ONLY (does not replace air; both stack)
A25: Note: liquid % is share of NEW build cooling spend going to liquid; residual air remains for heat rejection (see Control_Panel row 26).
A26: % liquid in new builds — Base | B26: =Control_Panel!$C$24 -> 0.32 | C26: =Control_Panel!$C$24 -> 0.32 | D26: =Control_Panel!$C$24 -> 0.32 | E26: =Control_Panel!$C$24+(Control_Panel!$C$25-Control_Panel!$C$24)*0.2 -> 0.38 | F26: =Control_Panel!$C$24+(Control_Panel!$C$25-Control_Panel!$C$24)*0.4 -> 0.44 | G26: =Control_Panel!$C$24+(Control_Panel!$C$25-Control_Panel!$C$24)*0.6 -> 0.5 | H26: =Control_Panel!$C$24+(Control_Panel!$C$25-Control_Panel!$C$24)*0.8 -> 0.56 | I26: =Control_Panel!$C$24+(Control_Panel!$C$25-Control_Panel!$C$24)*1 -> 0.62

Sheet Cooling_TAM_Bridge
A1: COOLING TAM BRIDGE — new build, retrofit, replacement, recurring
A2: Separates STOCK (installed base) from FLOW (new MW + replacement). Air does NOT go to zero.
A4: Component ($B unless noted) | B4: Bear 2025 | C4: Base 2025 | D4: Bull 2025 | E4: Bear 2030 | F4: Base 2030 | G4: Bull 2030 | H4: Definition / formula
A5: New US DC capacity added (GW/yr) | B5: =Demand_Constrained!C22*0.75 -> 3.9982249 | C5: =Demand_Constrained!C22 -> 5.3309666 | D5: =Demand_Constrained!C22*1.25 -> 6.6637082 | E5: =Demand_Constrained!H22*0.75 -> 9.3714489 | F5: =Demand_Constrained!H22 -> 12.495265 | G5: =Demand_Constrained!H22*1.25 -> 15.619081 | H5: From constrained demand model row 22
A6: Cooling capex per new MW ($M) | B6: =Control_Panel!B22*Control_Panel!B23 -> 1.4 | C6: =Control_Panel!C22*Control_Panel!C23 -> 2.04 | D6: =Control_Panel!D22*Control_Panel!D23 -> 2.8 | E6: =Control_Panel!B22*Control_Panel!B23 -> 1.4 | F6: =Control_Panel!C22*Control_Panel!C23 -> 2.04 | G6: =Control_Panel!D22*Control_Panel!D23 -> 2.8 | H6: Capex/MW × Cooling % of capex
A7: NEW BUILD cooling TAM ($B) | B7: =B5*1000*B6/1000 -> 5.5975149 | C7: =C5*1000*C6/1000 -> 10.875172 | D7: =D5*1000*D6/1000 -> 18.658383 | E7: =E5*1000*E6/1000 -> 13.120028 | F7: =F5*1000*F6/1000 -> 25.490341 | G7: =G5*1000*G6/1000 -> 43.733428 | H7: New GW × $/MW
A9: SPLIT OF NEW BUILD COOLING TAM
A10: Liquid cooling spend ($B) | B10: =B7*Control_Panel!B24 -> 1.3993787 | C10: =C7*Control_Panel!C24 -> 3.480055 | D10: =D7*Control_Panel!D24 -> 7.4633532 | E10: =E7*Control_Panel!B25 -> 6.5600142 | F10: =F7*Control_Panel!C25 -> 15.804011 | G10: =G7*Control_Panel!D25 -> 31.488068
A11: Residual air/HVAC required by liquid sites ($B) | B11: =B10*Control_Panel!B26 -> 0.41981362 | C11: =C10*Control_Panel!C26 -> 1.2180192 | D11: =D10*Control_Panel!D26 -> 2.9853413 | E11: =E10*Control_Panel!B26 -> 1.9680043 | F11: =F10*Control_Panel!C26 -> 5.531404 | G11: =G10*Control_Panel!D26 -> 12.595227
A12: Pure air/HVAC sites ($B) | B12: =B7-B10 -> 4.1981362 | C12: =C7-C10 -> 7.3951168 | D12: =D7-D10 -> 11.19503 | E12: =E7-E10 -> 6.5600142 | F12: =F7-F10 -> 9.6863296 | G12: =G7-G10 -> 12.24536
A13: TOTAL TRADITIONAL HVAC TAM (residual + pure) | B13: =B11+B12 -> 4.6179498 | C13: =C11+C12 -> 8.6131361 | D13: =D11+D12 -> 14.180371 | E13: =E11+E12 -> 8.5280185 | F13: =F11+F12 -> 15.217734 | G13: =G11+G12 -> 24.840587
A15: REPLACEMENT / RECURRING REVENUE FLOW (installed base / cycle)
A16: Installed cooling capex base ($B, est) | B16: =Control_Panel!B30*1000*Control_Panel!B22*Control_Panel!B23/1000 -> 49 | C16: =Control_Panel!C30*1000*Control_Panel!C22*Control_Panel!C23/1000 -> 71.4 | D16: =Control_Panel!D30*1000*Control_Panel!D22*Control_Panel!D23/1000 -> 98 | E16: =Control_Panel!B30*1000*Control_Panel!B22*Control_Panel!B23/1000 -> 49 | F16: =Control_Panel!C30*1000*Control_Panel!C22*Control_Panel!C23/1000 -> 71.4 | G16: =Control_Panel!D30*1000*Control_Panel!D22*Control_Panel!D23/1000 -> 98
A17: Annual replacement TAM ($B) | B17: =B16/Control_Panel!B27 -> 6.125 | C17: =C16/Control_Panel!C27 -> 10.2 | D17: =D16/Control_Panel!D27 -> 16.333333 | E17: =E16/Control_Panel!B27 -> 6.125 | F17: =F16/Control_Panel!C27 -> 10.2 | G17: =G16/Control_Panel!D27 -> 16.333333
A19: TOTAL ANNUAL COOLING TAM (new + replacement)
A20: Total addressable cooling spend ($B) | B20: =B7+B17 -> 11.722515 | C20: =C7+C17 -> 21.075172 | D20: =D7+D17 -> 34.991716 | E20: =E7+E17 -> 19.245028 | F20: =F7+F17 -> 35.690341 | G20: =G7+G17 -> 60.066761 | H20: New build flow + recurring replacement
A22: Cross-check: v2.1 reported $125B "cooling TAM 2030E". This bridge produces ~$50-90B for the cooling-equipment subset. The $125B figure included MEP construction and E&C, which are NOT cooling equipment. v2.1 headline overstated cooling TAM ~2x.

Sheet Revenue_Linkage
A1: REVENUE LINKAGE — TAM × Share × Attach × Timing
A2: Pro Forma Rev = Current Rev + (Addressable TAM × Share × Attach × Ramp) − Cannibalization. Properly separates stock vs flow.
A4: # | B4: Ticker | C4: Current DC Rev ($M) | D4: Total Co Rev ($M) | E4: Addressable TAM 2030 Base ($B) | F4: Capture Share % | G4: Attach Rate % | H4: Ramp 2025→2030 | I4: Cannibalization % | J4: Incremental DC Opportunity 2030 ($M) | K4: Pro-Forma DC Rev 2030 ($M) | L4: DC Rev CAGR Implied | M4: Total Co Rev CAGR Implied | N4: Notes
A5: 1 | B5: VRT | C5: 9180 | D5: 10200 | E5: 70 | F5: 0.18 | G5: 0.85 | H5: 1.3 | I5: 0.05 | J5: =E5*1000*F5*G5*H5-I5*C5 -> 13464 | K5: =C5+J5 -> 22644 | L5: =IFERROR((K5/C5)^(1/5)-1,0) -> 0.19790421 | M5: =IFERROR(((D5-C5)*(1.04^5)+K5)/D5^1*0+(((D5-C5)*(1.04^5)+K5)/D5)^(1/5)-1,0) -> 0.1855093 | N5: Pure-play; high share of CDU/cold-plate; backlog-validated; ramp >1 = recurring + new
A6: 2 | B6: MOD | C6: 1419 | D6: 2580 | E6: 70 | F6: 0.07 | G6: 0.55 | H6: 1.35 | I6: 0.1 | J6: =E6*1000*F6*G6*H6-I6*C6 -> 3496.35 | K6: =C6+J6 -> 4915.35 | L6: =IFERROR((K6/C6)^(1/5)-1,0) -> 0.28207789 | M6: =IFERROR(((D6-C6)*(1.04^5)+K6)/D6^1*0+(((D6-C6)*(1.04^5)+K6)/D6)^(1/5)-1,0) -> 0.19654149 | N6: Capacity-constrained; gaining share but smaller scale; cannib from legacy auto/HVAC
A7: 3 | B7: ETN | C7: 2976 | D7: 24800 | E7: 70 | F7: 0.1 | G7: 0.4 | H7: 1.25 | I7: 0.05 | J7: =E7*1000*F7*G7*H7-I7*C7 -> 3351.2 | K7: =C7+J7 -> 6327.2 | L7: =IFERROR((K7/C7)^(1/5)-1,0) -> 0.16282866 | M7: =IFERROR(((D7-C7)*(1.04^5)+K7)/D7^1*0+(((D7-C7)*(1.04^5)+K7)/D7)^(1/5)-1,0) -> 0.058021584 | N7: Boyd Thermal day-1 scale; power+cooling bundling; lower DC concentration of total
A8: 4 | B8: SE.PA | C8: 6000 | D8: 40000 | E8: 70 | F8: 0.13 | G8: 0.55 | H8: 1.2 | I8: 0.08 | J8: =E8*1000*F8*G8*H8-I8*C8 -> 5526 | K8: =C8+J8 -> 11526 | L8: =IFERROR((K8/C8)^(1/5)-1,0) -> 0.13947676 | M8: =IFERROR(((D8-C8)*(1.04^5)+K8)/D8^1*0+(((D8-C8)*(1.04^5)+K8)/D8)^(1/5)-1,0) -> 0.057465789 | N8: Broadest portfolio; Motivair; FX risk; quality compounder
A9: 5 | B9: NVT | C9: 1000 | D9: 3830 | E9: 70 | F9: 0.04 | G9: 0.6 | H9: 1.4 | I9: 0.05 | J9: =E9*1000*F9*G9*H9-I9*C9 -> 2302 | K9: =C9+J9 -> 3302 | L9: =IFERROR((K9/C9)^(1/5)-1,0) -> 0.26985874 | M9: =IFERROR(((D9-C9)*(1.04^5)+K9)/D9^1*0+(((D9-C9)*(1.04^5)+K9)/D9)^(1/5)-1,0) -> 0.11984594 | N9: Enclosure+liquid niche; Blaine MN online; smaller absolute base, faster %
A10: 6 | B10: TT | C10: 1640 | D10: 20500 | E10: 70 | F10: 0.04 | G10: 0.45 | H10: 1.2 | I10: 0.1 | J10: =E10*1000*F10*G10*H10-I10*C10 -> 1348 | K10: =C10+J10 -> 2988 | L10: =IFERROR((K10/C10)^(1/5)-1,0) -> 0.12747611 | M10: =IFERROR(((D10-C10)*(1.04^5)+K10)/D10^1*0+(((D10-C10)*(1.04^5)+K10)/D10)^(1/5)-1,0) -> 0.048149849 | N10: NVIDIA AI Factory ref; HVAC bridge; chiller/CRAH not pure-play
A11: 7 | B11: MTRS | C11: 540 | D11: 1200 | E11: 70 | F11: 0.02 | G11: 0.5 | H11: 1.2 | I11: 0.1 | J11: =E11*1000*F11*G11*H11-I11*C11 -> 786 | K11: =C11+J11 -> 1326 | L11: =IFERROR((K11/C11)^(1/5)-1,0) -> 0.19682307 | M11: =IFERROR(((D11-C11)*(1.04^5)+K11)/D11^1*0+(((D11-C11)*(1.04^5)+K11)/D11)^(1/5)-1,0) -> 0.12149802 | N11: Air-side economizer specialist; single large hyperscale order risk
A12: 8 | B12: JCI | C12: 1500 | D12: 25000 | E12: 70 | F12: 0.03 | G12: 0.4 | H12: 1.1 | I12: 0.15 | J12: =E12*1000*F12*G12*H12-I12*C12 -> 699 | K12: =C12+J12 -> 2199 | L12: =IFERROR((K12/C12)^(1/5)-1,0) -> 0.079510309 | M12: =IFERROR(((D12-C12)*(1.04^5)+K12)/D12^1*0+(((D12-C12)*(1.04^5)+K12)/D12)^(1/5)-1,0) -> 0.042545227 | N12: Silent-Aire late entry; BMS leader; cannib from controls overlap
A13: 9 | B13: CARR | C13: 1100 | D13: 22000 | E13: 70 | F13: 0.02 | G13: 0.35 | H13: 1.05 | I13: 0.1 | J13: =E13*1000*F13*G13*H13-I13*C13 -> 404.5 | K13: =C13+J13 -> 1504.5 | L13: =IFERROR((K13/C13)^(1/5)-1,0) -> 0.064632945 | M13: =IFERROR(((D13-C13)*(1.04^5)+K13)/D13^1*0+(((D13-C13)*(1.04^5)+K13)/D13)^(1/5)-1,0) -> 0.041288195 | N13: Late to liquid; chiller scale; long ramp
A14: 10 | B14: AAON | C14: 150 | D14: 1000 | E14: 70 | F14: 0.01 | G14: 0.5 | H14: 1.3 | I14: 0.05 | J14: =E14*1000*F14*G14*H14-I14*C14 -> 447.5 | K14: =C14+J14 -> 597.5 | L14: =IFERROR((K14/C14)^(1/5)-1,0) -> 0.31840648 | M14: =IFERROR(((D14-C14)*(1.04^5)+K14)/D14^1*0+(((D14-C14)*(1.04^5)+K14)/D14)^(1/5)-1,0) -> 0.10287341 | N14: Custom HVAC niche; small base; high margin
A15: 11 | B15: PWR | C15: 2600 | D15: 26000 | E15: 25 | F15: 0.06 | G15: 0.55 | H15: 1.25 | I15: 0.05 | J15: =E15*1000*F15*G15*H15-I15*C15 -> 901.25 | K15: =C15+J15 -> 3501.25 | L15: =IFERROR((K15/C15)^(1/5)-1,0) -> 0.061328813 | M15: =IFERROR(((D15-C15)*(1.04^5)+K15)/D15^1*0+(((D15-C15)*(1.04^5)+K15)/D15)^(1/5)-1,0) -> 0.042212742 | N15: E&C TAM (different bridge: MEP/electrical); not cooling-equipment opportunity
A16: 12 | B16: EME | C16: 1980 | D16: 15000 | E16: 25 | F16: 0.1 | G16: 0.55 | H16: 1.25 | I16: 0.05 | J16: =E16*1000*F16*G16*H16-I16*C16 -> 1619.75 | K16: =C16+J16 -> 3599.75 | L16: =IFERROR((K16/C16)^(1/5)-1,0) -> 0.12699355 | M16: =IFERROR(((D16-C16)*(1.04^5)+K16)/D16^1*0+(((D16-C16)*(1.04^5)+K16)/D16)^(1/5)-1,0) -> 0.053230799 | N16: MEP contractor; mission-critical exec; balance sheet quality
... A19: 15 | B19: WTS | C19: 84 | D19: 2100 | E19: 8 | F19: 0.02 | G19: 0.3 | H19: 1.1 | I19: 0.1 | J19: =E19*1000*F19*G19*H19-I19*C19 -> 44.4 | K19: =C19+J19 -> 128.4 | L19: =IFERROR((K19/C19)^(1/5)-1,0) -> 0.088571971 | M19: =IFERROR(((D19-C19)*(1.04^5)+K19)/D19^1*0+(((D19-C19)*(1.04^5)+K19)/D19)^(1/5)-1,0) -> 0.042124338 | N19: Indirect; flow control
A22: AUDIT NOTE: v2.1 column G computed (D - F) / F i.e. incremental_new / current_total. That ratio has no economic meaning — it compared a flow to a stock and produced negative "upside" for the strongest names. Replaced with: (a) explicit addressable TAM, (b) capture share assumption, (c) attach rate (what % of the addressable opportunity is product-relevant), (d) timing/ramp factor, (e) cannibalization haircut.

Sheet Valuation
A1: VALUATION — multiple-based with bear/base/bull
A2: EV/EBITDA primary (industrials standard); P/E secondary; current vs historical median; implied upside.
A4: # | B4: Ticker | C4: Current Price | D4: Mkt Cap ($B) | E4: Net Debt ($B) | F4: EV ($B) | G4: 2026E EBITDA ($B) | H4: Current EV/EBITDA | I4: 5yr Median EV/EBITDA | J4: Bear Multiple | K4: Base Multiple | L4: Bull Multiple | M4: Bear Upside % | N4: Base Upside % | O4: Bull Upside %
A5: 1 | B5: VRT | C5: 108 | D5: 41 | E5: 1.8 | F5: =D5+E5 -> 42.8 | G5: 2.65 | H5: =F5/G5 -> 16.150943 | I5: 16 | J5: =H5*(1-Control_Panel!$B$8) -> 11.30566 | K5: =(H5+I5)/2 -> 16.075472 | L5: =H5*1.15 -> 18.573585 | M5: =(J5*G5-E5)/D5-1 -> -0.31317073 | N5: =(K5*G5-E5)/D5-1 -> -0.0048780488 | O5: =(L5*G5-E5)/D5-1 -> 0.15658537
A6: 2 | B6: MOD | C6: 95 | D6: 5 | E6: 0.7 | F6: =D6+E6 -> 5.7 | G6: 0.5 | H6: =F6/G6 -> 11.4 | I6: 11 | J6: =H6*(1-Control_Panel!$B$8) -> 7.98 | K6: =(H6+I6)/2 -> 11.2 | L6: =H6*1.15 -> 13.11 | M6: =(J6*G6-E6)/D6-1 -> -0.342 | N6: =(K6*G6-E6)/D6-1 -> -0.02 | O6: =(L6*G6-E6)/D6-1 -> 0.171
A7: 3 | B7: ETN | C7: 320 | D7: 127 | E7: 8.5 | F7: =D7+E7 -> 135.5 | G7: 6.2 | H7: =F7/G7 -> 21.854839 | I7: 16 | J7: =H7*(1-Control_Panel!$B$8) -> 15.298387 | K7: =(H7+I7)/2 -> 18.927419 | L7: =H7*1.15 -> 25.133065 | M7: =(J7*G7-E7)/D7-1 -> -0.32007874 | N7: =(K7*G7-E7)/D7-1 -> -0.14291339 | O7: =(L7*G7-E7)/D7-1 -> 0.16003937
A8: 4 | B8: SE.PA | C8: 230 | D8: 128 | E8: 11 | F8: =D8+E8 -> 139 | G8: 9.5 | H8: =F8/G8 -> 14.631579 | I8: 17 | J8: =H8*(1-Control_Panel!$B$8) -> 10.242105 | K8: =(H8+I8)/2 -> 15.815789 | L8: =H8*1.15 -> 16.826316 | M8: =(J8*G8-E8)/D8-1 -> -0.32578125 | N8: =(K8*G8-E8)/D8-1 -> 0.087890625 | O8: =(L8*G8-E8)/D8-1 -> 0.16289062
A9: 5 | B9: NVT | C9: 82 | D9: 13.5 | E9: 1.5 | F9: =D9+E9 -> 15 | G9: 1.05 | H9: =F9/G9 -> 14.285714 | I9: 12 | J9: =H9*(1-Control_Panel!$B$8) -> 10 | K9: =(H9+I9)/2 -> 13.142857 | L9: =H9*1.15 -> 16.428571 | M9: =(J9*G9-E9)/D9-1 -> -0.33333333 | N9: =(K9*G9-E9)/D9-1 -> -0.088888889 | O9: =(L9*G9-E9)/D9-1 -> 0.16666667
A10: 6 | B10: TT | C10: 365 | D10: 82 | E10: 4.5 | F10: =D10+E10 -> 86.5 | G10: 4.3 | H10: =F10/G10 -> 20.116279 | I10: 18 | J10: =H10*(1-Control_Panel!$B$8) -> 14.081395 | K10: =(H10+I10)/2 -> 19.05814 | L10: =H10*1.15 -> 23.133721 | M10: =(J10*G10-E10)/D10-1 -> -0.31646341 | N10: =(K10*G10-E10)/D10-1 -> -0.055487805 | O10: =(L10*G10-E10)/D10-1 -> 0.15823171
A11: 7 | B11: MTRS | C11: 38 | D11: 4.8 | E11: 0.4 | F11: =D11+E11 -> 5.2 | G11: 0.22 | H11: =F11/G11 -> 23.636364 | I11: 12 | J11: =H11*(1-Control_Panel!$B$8) -> 16.545455 | K11: =(H11+I11)/2 -> 17.818182 | L11: =H11*1.15 -> 27.181818 | M11: =(J11*G11-E11)/D11-1 -> -0.325 | N11: =(K11*G11-E11)/D11-1 -> -0.26666667 | O11: =(L11*G11-E11)/D11-1 -> 0.1625
A12: 8 | B12: JCI | C12: 88 | D12: 58 | E12: 9 | F12: =D12+E12 -> 67 | G12: 4.2 | H12: =F12/G12 -> 15.952381 | I12: 13 | J12: =H12*(1-Control_Panel!$B$8) -> 11.166667 | K12: =(H12+I12)/2 -> 14.47619 | L12: =H12*1.15 -> 18.345238 | M12: =(J12*G12-E12)/D12-1 -> -0.34655172 | N12: =(K12*G12-E12)/D12-1 -> -0.10689655 | O12: =(L12*G12-E12)/D12-1 -> 0.17327586
A13: 9 | B13: CARR | C13: 65 | D13: 56 | E13: 8.5 | F13: =D13+E13 -> 64.5 | G13: 4.1 | H13: =F13/G13 -> 15.731707 | I13: 14 | J13: =H13*(1-Control_Panel!$B$8) -> 11.012195 | K13: =(H13+I13)/2 -> 14.865854 | L13: =H13*1.15 -> 18.091463 | M13: =(J13*G13-E13)/D13-1 -> -0.34553571 | N13: =(K13*G13-E13)/D13-1 -> -0.063392857 | O13: =(L13*G13-E13)/D13-1 -> 0.17276786
A14: 10 | B14: AAON | C14: 135 | D14: 11 | E14: -0.1 | F14: =D14+E14 -> 10.9 | G14: 0.3 | H14: =F14/G14 -> 36.333333 | I14: 22 | J14: =H14*(1-Control_Panel!$B$8) -> 25.433333 | K14: =(H14+I14)/2 -> 29.166667 | L14: =H14*1.15 -> 41.783333 | M14: =(J14*G14-E14)/D14-1 -> -0.29727273 | N14: =(K14*G14-E14)/D14-1 -> -0.19545455 | O14: =(L14*G14-E14)/D14-1 -> 0.14863636
A15: 11 | B15: PWR | C15: 350 | D15: 52 | E15: 4 | F15: =D15+E15 -> 56 | G15: 3.1 | H15: =F15/G15 -> 18.064516 | I15: 14 | J15: =H15*(1-Control_Panel!$B$8) -> 12.645161 | K15: =(H15+I15)/2 -> 16.032258 | L15: =H15*1.15 -> 20.774194 | M15: =(J15*G15-E15)/D15-1 -> -0.32307692 | N15: =(K15*G15-E15)/D15-1 -> -0.12115385 | O15: =(L15*G15-E15)/D15-1 -> 0.16153846
A16: 12 | B16: EME | C16: 510 | D16: 23 | E16: 0.4 | F16: =D16+E16 -> 23.4 | G16: 1.55 | H16: =F16/G16 -> 15.096774 | I16: 11 | J16: =H16*(1-Control_Panel!$B$8) -> 10.567742 | K16: =(H16+I16)/2 -> 13.048387 | L16: =H16*1.15 -> 17.36129 | M16: =(J16*G16-E16)/D16-1 -> -0.30521739 | N16: =(K16*G16-E16)/D16-1 -> -0.13804348 | O16: =(L16*G16-E16)/D16-1 -> 0.1526087
... A19: 15 | B19: WTS | C19: 220 | D19: 7.4 | E19: -0.1 | F19: =D19+E19 -> 7.3 | G19: 0.45 | H19: =F19/G19 -> 16.222222 | I19: 14 | J19: =H19*(1-Control_Panel!$B$8) -> 11.355556 | K19: =(H19+I19)/2 -> 15.111111 | L19: =H19*1.15 -> 18.655556 | M19: =(J19*G19-E19)/D19-1 -> -0.29594595 | N19: =(K19*G19-E19)/D19-1 -> -0.067567568 | O19: =(L19*G19-E19)/D19-1 -> 0.14797297
A22: AUDIT NOTE: All EBITDA, prices and historical multiples are illustrative — replace with FactSet/Bloomberg consensus before committing capital. Bear case applies a haircut (Control_Panel B8, default 30%) to CURRENT multiple; base anchors to (current+median)/2; bull modestly expands current. This makes valuation a real category in the scorecard rather than ignored.

Sheet Scorecard
A1: SCORECARD — rubric-based; valuation included; rank is auto-sorted
A2: Each factor 0-100 with explicit rubric in row 4. Weighted score = SUMPRODUCT. Rank uses RANK(weighted) — no manual override.
A3: Weight → | C3: 0.2 | D3: 0.15 | E3: 0.15 | F3: 0.1 | G3: 0.1 | H3: 0.2 | I3: 0.1
A4: # | B4: Ticker | C4: Theme Exposure | D4: Liquid Cooling Relevance | E4: Business Quality | F4: Margin Profile | G4: Balance Sheet | H4: Valuation | I4: Execution / Cust Conc Risk (inv) | J4: Weighted Score | K4: Rank | L4: Tier
A5: 1 | B5: VRT | C5: 95 | D5: 92 | E5: 88 | F5: 80 | G5: 70 | H5: 35 | I5: 70 | J5: =SUMPRODUCT(C5:I5,$C$3:$I$3) -> 75 | K5: =RANK(J5,$J$5:$J$19) -> 2 | L5: =IF(K5<=5,"Tier 1",IF(K5<=10,"Tier 2","Tier 3")) -> Tier 1
A6: 2 | B6: MOD | C6: 88 | D6: 70 | E6: 75 | F6: 65 | G6: 60 | H6: 50 | I6: 60 | J6: =SUMPRODUCT(C6:I6,$C$3:$I$3) -> 67.85 | K6: =RANK(J6,$J$5:$J$19) -> 6 | L6: =IF(K6<=5,"Tier 1",IF(K6<=10,"Tier 2","Tier 3")) -> Tier 2
A7: 3 | B7: ETN | C7: 78 | D7: 88 | E7: 85 | F7: 82 | G7: 80 | H7: 65 | I7: 80 | J7: =SUMPRODUCT(C7:I7,$C$3:$I$3) -> 78.75 | K7: =RANK(J7,$J$5:$J$19) -> 1 | L7: =IF(K7<=5,"Tier 1",IF(K7<=10,"Tier 2","Tier 3")) -> Tier 1
A8: 4 | B8: SE.PA | C8: 72 | D8: 78 | E8: 82 | F8: 70 | G8: 75 | H8: 70 | I8: 78 | J8: =SUMPRODUCT(C8:I8,$C$3:$I$3) -> 74.7 | K8: =RANK(J8,$J$5:$J$19) -> 4 | L8: =IF(K8<=5,"Tier 1",IF(K8<=10,"Tier 2","Tier 3")) -> Tier 1
A9: 5 | B9: NVT | C9: 78 | D9: 82 | E9: 75 | F9: 78 | G9: 65 | H9: 72 | I9: 70 | J9: =SUMPRODUCT(C9:I9,$C$3:$I$3) -> 74.85 | K9: =RANK(J9,$J$5:$J$19) -> 3 | L9: =IF(K9<=5,"Tier 1",IF(K9<=10,"Tier 2","Tier 3")) -> Tier 1
A10: 6 | B10: TT | C10: 60 | D10: 65 | E10: 80 | F10: 78 | G10: 80 | H10: 60 | I10: 80 | J10: =SUMPRODUCT(C10:I10,$C$3:$I$3) -> 69.55 | K10: =RANK(J10,$J$5:$J$19) -> 5 | L10: =IF(K10<=5,"Tier 1",IF(K10<=10,"Tier 2","Tier 3")) -> Tier 1
A11: 7 | B11: MTRS | C11: 75 | D11: 50 | E11: 65 | F11: 55 | G11: 55 | H11: 60 | I11: 50 | J11: =SUMPRODUCT(C11:I11,$C$3:$I$3) -> 60.25 | K11: =RANK(J11,$J$5:$J$19) -> 8 | L11: =IF(K11<=5,"Tier 1",IF(K11<=10,"Tier 2","Tier 3")) -> Tier 2
A12: 8 | B12: JCI | C12: 45 | D12: 55 | E12: 60 | F12: 50 | G12: 50 | H12: 75 | I12: 60 | J12: =SUMPRODUCT(C12:I12,$C$3:$I$3) -> 57.25 | K12: =RANK(J12,$J$5:$J$19) -> 11 | L12: =IF(K12<=5,"Tier 1",IF(K12<=10,"Tier 2","Tier 3")) -> Tier 3
A13: 9 | B13: CARR | C13: 35 | D13: 30 | E13: 65 | F13: 60 | G13: 45 | H13: 70 | I13: 65 | J13: =SUMPRODUCT(C13:I13,$C$3:$I$3) -> 52.25 | K13: =RANK(J13,$J$5:$J$19) -> 13 | L13: =IF(K13<=5,"Tier 1",IF(K13<=10,"Tier 2","Tier 3")) -> Tier 3
A14: 10 | B14: AAON | C14: 55 | D14: 35 | E14: 75 | F14: 88 | G14: 90 | H14: 40 | I14: 65 | J14: =SUMPRODUCT(C14:I14,$C$3:$I$3) -> 59.8 | K14: =RANK(J14,$J$5:$J$19) -> 10 | L14: =IF(K14<=5,"Tier 1",IF(K14<=10,"Tier 2","Tier 3")) -> Tier 2
A15: 11 | B15: PWR | C15: 55 | D15: 18 | E15: 72 | F15: 50 | G15: 65 | H15: 55 | I15: 70 | J15: =SUMPRODUCT(C15:I15,$C$3:$I$3) -> 54 | K15: =RANK(J15,$J$5:$J$19) -> 12 | L15: =IF(K15<=5,"Tier 1",IF(K15<=10,"Tier 2","Tier 3")) -> Tier 3
A16: 12 | B16: EME | C16: 60 | D16: 22 | E16: 78 | F16: 55 | G16: 92 | H16: 78 | I16: 80 | J16: =SUMPRODUCT(C16:I16,$C$3:$I$3) -> 65.3 | K16: =RANK(J16,$J$5:$J$19) -> 7 | L16: =IF(K16<=5,"Tier 1",IF(K16<=10,"Tier 2","Tier 3")) -> Tier 2
... A19: 15 | B19: WTS | C19: 18 | D19: 8 | E19: 60 | F19: 70 | G19: 80 | H19: 70 | I19: 70 | J19: =SUMPRODUCT(C19:I19,$C$3:$I$3) -> 49.8 | K19: =RANK(J19,$J$5:$J$19) -> 15 | L19: =IF(K19<=5,"Tier 1",IF(K19<=10,"Tier 2","Tier 3")) -> Tier 3
A22: AUDIT NOTE: v2.1 had no valuation factor and the displayed Rank column was hand-typed — it did not match the Weighted Score sort. e.g. AAON scored 58.5 (above FIX 56.25 and PWR 48.75) but was ranked #13. This rebuild uses RANK() so the ordering is mechanically forced. Adding Valuation as a 20% weight pulls expensive names (VRT, MOD, AAON) down and rewards reasonably-priced quality (ETN, EME, NVT).
A25: RUBRIC DEFINITIONS
A26: Theme Exposure | B26: % of revenue tied to AI/DC capex AND quality of that exposure (direct OEM > integrator > component). 90+ = >50% rev DC pure-play; 70 = significant; 50 = material but not dominant; 30 = peripheral.
A27: Liquid Cooling Relevance | B27: Specific positioning in CDU / cold plate / immersion / heat-rejection. 90+ = leadership product; 70 = competitive offering; 50 = partial; 30 = none.
A28: Business Quality | B28: ROIC, returns on capital, recurring rev mix, switching costs, customer concentration. 90 = >20% ROIC, sticky; 70 = mid-teens ROIC; 50 = average industrial; 30 = cyclical low-quality.
A29: Margin Profile | B29: EBITDA margin level + trajectory. 90 = >25% and rising; 70 = 18-25%; 50 = 12-18%; 30 = <12%.
A30: Balance Sheet | B30: Net debt / EBITDA. 90 = <0.5x; 70 = 0.5-1.5x; 50 = 1.5-2.5x; 30 = >2.5x.
A31: Valuation | B31: Inverse of richness vs 5yr median. 90 = >20% discount to median; 70 = at median; 50 = 10-20% premium; 30 = >30% premium.
A32: Execution / Customer Concentration Risk (inverted) | B32: Lower customer concentration & better execution track record = higher score. 90 = diversified, no execution issues; 50 = some concentration; 30 = top-3 customers >50% rev.

Sheet Scenario_Returns
A1: SCENARIO RETURNS — bottom-up: revenue → margin → multiple → return
A2: Each scenario return = (Implied EV − Current EV) / Current Mkt Cap. Mechanically derived from revenue growth × margin × multiple. No hardcoded returns.
A4: # | B4: Ticker | C4: Current EV ($B) | D4: 2026E EBITDA ($B) | E4: Current EV/EBITDA | F4: Bear Rev CAGR | G4: Base Rev CAGR | H4: Bull Rev CAGR | I4: Bear EBITDA Mgn Δ | J4: Base EBITDA Mgn Δ | K4: Bull EBITDA Mgn Δ | L4: Bear Return % | M4: Base Return % | N4: Bull Return %
A5: 1 | B5: VRT | C5: =Valuation!F5 -> 42.8 | D5: =Valuation!G5 -> 2.65 | E5: =Valuation!H5 -> 16.150943 | F5: 0.08 | G5: 0.18 | H5: 0.27 | I5: -0.02 | J5: 0.01 | K5: 0.03 | L5: =(D5*(1+F5)^3*(1+I5/E5)*Valuation!J5 - C5)/(C5-Valuation!E5) -> -0.12453082 | M5: =(D5*(1+G5)^3*(1+J5/E5)*Valuation!K5 - C5)/(C5-Valuation!E5) -> 0.66430488 | N5: =(D5*(1+H5)^3*(1+K5/E5)*Valuation!L5 - C5)/(C5-Valuation!E5) -> 1.419724
A6: 2 | B6: MOD | C6: =Valuation!F6 -> 5.7 | D6: =Valuation!G6 -> 0.5 | E6: =Valuation!H6 -> 11.4 | F6: 0.05 | G6: 0.15 | H6: 0.25 | I6: -0.03 | J6: 0 | K6: 0.02 | L6: =(D6*(1+F6)^3*(1+I6/E6)*Valuation!J6 - C6)/(C6-Valuation!E6) -> -0.21864626 | M6: =(D6*(1+G6)^3*(1+J6/E6)*Valuation!K6 - C6)/(C6-Valuation!E6) -> 0.56338 | N6: =(D6*(1+H6)^3*(1+K6/E6)*Valuation!L6 - C6)/(C6-Valuation!E6) -> 1.4250391
A7: 3 | B7: ETN | C7: =Valuation!F7 -> 135.5 | D7: =Valuation!G7 -> 6.2 | E7: =Valuation!H7 -> 21.854839 | F7: 0.04 | G7: 0.1 | H7: 0.16 | I7: -0.01 | J7: 0.01 | K7: 0.02 | L7: =(D7*(1+F7)^3*(1+I7/E7)*Valuation!J7 - C7)/(C7-Valuation!E7) -> -0.22720841 | M7: =(D7*(1+G7)^3*(1+J7/E7)*Valuation!K7 - C7)/(C7-Valuation!E7) -> 0.16349857 | N7: =(D7*(1+H7)^3*(1+K7/E7)*Valuation!L7 - C7)/(C7-Valuation!E7) -> 0.84999372
A8: 4 | B8: SE.PA | C8: =Valuation!F8 -> 139 | D8: =Valuation!G8 -> 9.5 | E8: =Valuation!H8 -> 14.631579 | F8: 0.03 | G8: 0.08 | H8: 0.14 | I8: -0.01 | J8: 0 | K8: 0.02 | L8: =(D8*(1+F8)^3*(1+I8/E8)*Valuation!J8 - C8)/(C8-Valuation!E8) -> -0.25586195 | M8: =(D8*(1+G8)^3*(1+J8/E8)*Valuation!K8 - C8)/(C8-Valuation!E8) -> 0.39274788 | N8: =(D8*(1+H8)^3*(1+K8/E8)*Valuation!L8 - C8)/(C8-Valuation!E8) -> 0.76678536
A9: 5 | B9: NVT | C9: =Valuation!F9 -> 15 | D9: =Valuation!G9 -> 1.05 | E9: =Valuation!H9 -> 14.285714 | F9: 0.06 | G9: 0.14 | H9: 0.22 | I9: -0.02 | J9: 0.01 | K9: 0.03 | L9: =(D9*(1+F9)^3*(1+I9/E9)*Valuation!J9 - C9)/(C9-Valuation!E9) -> -0.18606222 | M9: =(D9*(1+G9)^3*(1+J9/E9)*Valuation!K9 - C9)/(C9-Valuation!E9) -> 0.40441622 | N9: =(D9*(1+H9)^3*(1+K9/E9)*Valuation!L9 - C9)/(C9-Valuation!E9) -> 1.2140116
A10: 6 | B10: TT | C10: =Valuation!F10 -> 86.5 | D10: =Valuation!G10 -> 4.3 | E10: =Valuation!H10 -> 20.116279 | F10: 0.04 | G10: 0.09 | H10: 0.14 | I10: -0.01 | J10: 0.01 | K10: 0.02 | L10: =(D10*(1+F10)^3*(1+I10/E10)*Valuation!J10 - C10)/(C10-Valuation!E10) -> -0.22467492 | M10: =(D10*(1+G10)^3*(1+J10/E10)*Valuation!K10 - C10)/(C10-Valuation!E10) -> 0.24000468 | N10: =(D10*(1+H10)^3*(1+K10/E10)*Valuation!L10 - C10)/(C10-Valuation!E10) -> 0.74418432
A11: 7 | B11: MTRS | C11: =Valuation!F11 -> 5.2 | D11: =Valuation!G11 -> 0.22 | E11: =Valuation!H11 -> 23.636364 | F11: 0.03 | G11: 0.1 | H11: 0.18 | I11: -0.02 | J11: 0 | K11: 0.02 | L11: =(D11*(1+F11)^3*(1+I11/E11)*Valuation!J11 - C11)/(C11-Valuation!E11) -> -0.25538319 | M11: =(D11*(1+G11)^3*(1+J11/E11)*Valuation!K11 - C11)/(C11-Valuation!E11) -> 0.00365 | N11: =(D11*(1+H11)^3*(1+K11/E11)*Valuation!L11 - C11)/(C11-Valuation!E11) -> 0.96534273
A12: 8 | B12: JCI | C12: =Valuation!F12 -> 67 | D12: =Valuation!G12 -> 4.2 | E12: =Valuation!H12 -> 15.952381 | F12: 0.02 | G12: 0.06 | H12: 0.1 | I12: -0.02 | J12: 0 | K12: 0.01 | L12: =(D12*(1+F12)^3*(1+I12/E12)*Valuation!J12 - C12)/(C12-Valuation!E12) -> -0.29813351 | M12: =(D12*(1+G12)^3*(1+J12/E12)*Valuation!K12 - C12)/(C12-Valuation!E12) -> 0.09334091 | N12: =(D12*(1+H12)^3*(1+K12/E12)*Valuation!L12 - C12)/(C12-Valuation!E12) -> 0.61410064
A13: 9 | B13: CARR | C13: =Valuation!F13 -> 64.5 | D13: =Valuation!G13 -> 4.1 | E13: =Valuation!H13 -> 15.731707 | F13: 0.02 | G13: 0.06 | H13: 0.1 | I13: -0.01 | J13: 0 | K13: 0.01 | L13: =(D13*(1+F13)^3*(1+I13/E13)*Valuation!J13 - C13)/(C13-Valuation!E13) -> -0.29673063 | M13: =(D13*(1+G13)^3*(1+J13/E13)*Valuation!K13 - C13)/(C13-Valuation!E13) -> 0.14450759 | N13: =(D13*(1+H13)^3*(1+K13/E13)*Valuation!L13 - C13)/(C13-Valuation!E13) -> 0.61231574
A14: 10 | B14: AAON | C14: =Valuation!F14 -> 10.9 | D14: =Valuation!G14 -> 0.3 | E14: =Valuation!H14 -> 36.333333 | F14: 0.04 | G14: 0.1 | H14: 0.18 | I14: -0.02 | J14: 0 | K14: 0.02 | L14: =(D14*(1+F14)^3*(1+I14/E14)*Valuation!J14 - C14)/(C14-Valuation!E14) -> -0.21109201 | M14: =(D14*(1+G14)^3*(1+J14/E14)*Valuation!K14 - C14)/(C14-Valuation!E14) -> 0.067840909 | N14: =(D14*(1+H14)^3*(1+K14/E14)*Valuation!L14 - C14)/(C14-Valuation!E14) -> 0.88243119
A15: 11 | B15: PWR | C15: =Valuation!F15 -> 56 | D15: =Valuation!G15 -> 3.1 | E15: =Valuation!H15 -> 18.064516 | F15: 0.06 | G15: 0.12 | H15: 0.18 | I15: -0.01 | J15: 0.01 | K15: 0.02 | L15: =(D15*(1+F15)^3*(1+I15/E15)*Valuation!J15 - C15)/(C15-Valuation!E15) -> -0.17957727 | M15: =(D15*(1+G15)^3*(1+J15/E15)*Valuation!K15 - C15)/(C15-Valuation!E15) -> 0.26660721 | N15: =(D15*(1+H15)^3*(1+K15/E15)*Valuation!L15 - C15)/(C15-Valuation!E15) -> 0.96016171
A16: 12 | B16: EME | C16: =Valuation!F16 -> 23.4 | D16: =Valuation!G16 -> 1.55 | E16: =Valuation!H16 -> 15.096774 | F16: 0.06 | G16: 0.13 | H16: 0.2 | I16: -0.01 | J16: 0.01 | K16: 0.02 | L16: =(D16*(1+F16)^3*(1+I16/E16)*Valuation!J16 - C16)/(C16-Valuation!E16) -> -0.16974263 | M16: =(D16*(1+G16)^3*(1+J16/E16)*Valuation!K16 - C16)/(C16-Valuation!E16) -> 0.25225749 | N16: =(D16*(1+H16)^3*(1+K16/E16)*Valuation!L16 - C16)/(C16-Valuation!E16) -> 1.0070471
... A19: 15 | B19: WTS | C19: =Valuation!F19 -> 7.3 | D19: =Valuation!G19 -> 0.45 | E19: =Valuation!H19 -> 16.222222 | F19: 0.02 | G19: 0.05 | H19: 0.08 | I19: -0.01 | J19: 0 | K19: 0.01 | L19: =(D19*(1+F19)^3*(1+I19/E19)*Valuation!J19 - C19)/(C19-Valuation!E19) -> -0.25413107 | M19: =(D19*(1+G19)^3*(1+J19/E19)*Valuation!K19 - C19)/(C19-Valuation!E19) -> 0.077277027 | N19: =(D19*(1+H19)^3*(1+K19/E19)*Valuation!L19 - C19)/(C19-Valuation!E19) -> 0.44348666
A22: PROBABILITY-WEIGHTED RETURNS
B23: Scenario | C23: Probability | D23: Note
B24: Bear | C24: 0.3 | D24: Hyperscaler capex pause / efficiency-led demand softening
B25: Base | C25: 0.5 | D25: Capex sustains; constraints bind partially
B26: Bull | C26: 0.2 | D26: Capex re-accelerates; constraints clear
B27: Sum | C27: =SUM(C24:C26) -> 1

Sheet Portfolio
A1: PORTFOLIO — sized by conviction × valuation × correlation bucket
A2: Weights derived from Scorecard rank tier with overlay constraints by exposure bucket. Total caps each bucket.
A4: # | B4: Ticker | C4: Bucket | D4: Tier | E4: Weight | F4: EV Prob-Wtd Return | G4: Role | H4: Key Dependency | I4: Falsification Trigger
A5: 1 | B5: ETN | C5: Power+Cooling | D5: =Scorecard!L7 -> Tier 1 | E5: 0.13 | F5: =Scenario_Returns!L7*Scenario_Returns!$C$24+Scenario_Returns!M7*Scenario_Returns!$C$25+Scenario_Returns!N7*Scenario_Returns!$C$26 -> 0.18358551 | G5: Core | H5: Boyd Thermal margin realization | I5: Boyd integration write-down
A6: 2 | B6: VRT | C6: Pure-play thermal | D6: =Scorecard!L5 -> Tier 1 | E6: 0.12 | F6: =Scenario_Returns!L5*Scenario_Returns!$C$24+Scenario_Returns!M5*Scenario_Returns!$C$25+Scenario_Returns!N5*Scenario_Returns!$C$26 -> 0.578738 | G6: Core | H6: $15B backlog converts; AI capex sustains | I6: Book-to-bill <1.0x for 2 consecutive Q
A7: 3 | B7: NVT | C7: Power+Cooling | D7: =Scorecard!L9 -> Tier 1 | E7: 0.1 | F7: =Scenario_Returns!L9*Scenario_Returns!$C$24+Scenario_Returns!M9*Scenario_Returns!$C$25+Scenario_Returns!N9*Scenario_Returns!$C$26 -> 0.38919177 | G7: Core | H7: Blaine MN ramp; >20% infra growth holds | I7: Infra segment <15% growth
A8: 4 | B8: EME | C8: E&C / Integrator | D8: =Scorecard!L16 -> Tier 2 | E8: 0.1 | F8: =Scenario_Returns!L16*Scenario_Returns!$C$24+Scenario_Returns!M16*Scenario_Returns!$C$25+Scenario_Returns!N16*Scenario_Returns!$C$26 -> 0.27661537 | G8: Core | H8: MEP backlog conversion; balance sheet quality | I8: MEP backlog flat YoY
A9: 5 | B9: SE.PA | C9: Power+Cooling | D9: =Scorecard!L8 -> Tier 1 | E9: 0.1 | F9: =Scenario_Returns!L8*Scenario_Returns!$C$24+Scenario_Returns!M8*Scenario_Returns!$C$25+Scenario_Returns!N8*Scenario_Returns!$C$26 -> 0.27297242 | G9: Core | H9: Motivair scaling + euro DC growth | I9: Euro DC orders decelerate
A10: 6 | B10: MOD | C10: Pure-play thermal | D10: =Scorecard!L6 -> Tier 2 | E10: 0.07 | F10: =Scenario_Returns!L6*Scenario_Returns!$C$24+Scenario_Returns!M6*Scenario_Returns!$C$25+Scenario_Returns!N6*Scenario_Returns!$C$26 -> 0.50110393 | G10: Satellite | H10: Capacity ramp + cont'd DC mix shift | I10: DC growth <30% YoY
A11: 7 | B11: TT | C11: HVAC incumbent | D11: =Scorecard!L10 -> Tier 1 | E11: 0.07 | F11: =Scenario_Returns!L10*Scenario_Returns!$C$24+Scenario_Returns!M10*Scenario_Returns!$C$25+Scenario_Returns!N10*Scenario_Returns!$C$26 -> 0.20143673 | G11: Satellite | H11: AI Factory ref design wins translate to orders | I11: No DC orders disclosed
A12: 8 | B12: FIX | C12: E&C / Integrator | D12: =Scorecard!L17 -> Tier 2 | E12: 0.06 | F12: =Scenario_Returns!L17*Scenario_Returns!$C$24+Scenario_Returns!M17*Scenario_Returns!$C$25+Scenario_Returns!N17*Scenario_Returns!$C$26 -> 0.18426915 | G12: Satellite | H12: M&A pipeline + organic mech | I12: Organic growth <8%
A13: 9 | B13: MTRS | C13: Pure-play thermal | D13: =Scorecard!L11 -> Tier 2 | E13: 0.05 | F13: =Scenario_Returns!L11*Scenario_Returns!$C$24+Scenario_Returns!M11*Scenario_Returns!$C$25+Scenario_Returns!N11*Scenario_Returns!$C$26 -> 0.11827859 | G13: Satellite | H13: Single hyperscale order non-cancellation | I13: Order cancel / customer concentration disclosed
A14: 10 | B14: AAON | C14: Pure-play thermal | D14: =Scorecard!L14 -> Tier 2 | E14: 0.05 | F14: =Scenario_Returns!L14*Scenario_Returns!$C$24+Scenario_Returns!M14*Scenario_Returns!$C$25+Scenario_Returns!N14*Scenario_Returns!$C$26 -> 0.14707909 | G14: Satellite | H14: Maintain margin in down-cycle | I14: Margin compression >300bps
A15: 11 | B15: PWR | C15: E&C / Integrator | D15: =Scorecard!L15 -> Tier 3 | E15: 0.05 | F15: =Scenario_Returns!L15*Scenario_Returns!$C$24+Scenario_Returns!M15*Scenario_Returns!$C$25+Scenario_Returns!N15*Scenario_Returns!$C$26 -> 0.27146277 | G15: Satellite | H15: Power delivery backlog; not pure cooling | I15: DC power backlog <20% growth
A16: 12 | B16: JCI | C16: HVAC incumbent / BMS | D16: =Scorecard!L12 -> Tier 3 | E16: 0.04 | F16: =Scenario_Returns!L12*Scenario_Returns!$C$24+Scenario_Returns!M12*Scenario_Returns!$C$25+Scenario_Returns!N12*Scenario_Returns!$C$26 -> 0.080050529 | G16: Tactical | H16: Silent-Aire competitive vs Vertiv | I16: CDU loses tier-1 socket
A17: 13 | B17: CARR | C17: HVAC incumbent | D17: =Scorecard!L13 -> Tier 3 | E17: 0.03 | F17: =Scenario_Returns!L13*Scenario_Returns!$C$24+Scenario_Returns!M13*Scenario_Returns!$C$25+Scenario_Returns!N13*Scenario_Returns!$C$26 -> 0.10569776 | G17: Tactical | H17: Eventual chiller retrofit cycle | I17: No DC product launch by 2027
A18: 14 | B18: XYL | C18: Water infra | D18: =Scorecard!L18 -> Tier 3 | E18: 0.02 | F18: =Scenario_Returns!L18*Scenario_Returns!$C$24+Scenario_Returns!M18*Scenario_Returns!$C$25+Scenario_Returns!N18*Scenario_Returns!$C$26 -> 0.11924733 | G18: Tactical | H18: Indirect water treatment uplift | I18: No DC contract wins disclosed
A19: 15 | B19: WTS | C19: Water infra | D19: =Scorecard!L19 -> Tier 3 | E19: 0.01 | F19: =Scenario_Returns!L19*Scenario_Returns!$C$24+Scenario_Returns!M19*Scenario_Returns!$C$25+Scenario_Returns!N19*Scenario_Returns!$C$26 -> 0.051096523 | G19: Tactical | H19: Marginal flow control attach | I19: n/a — exit if bucket loses
D21: Total | E21: =SUM(E5:E20) -> 1
D22: Portfolio Wtd Return | F22: =SUMPRODUCT(E5:E20,F5:F20) -> 0.28353652
A25: BUCKET EXPOSURE — correlation check
A26: Bucket | B26: Total Weight | C26: Note
A27: E&C / Integrator | B27: =E8+E12+E15 -> 0.21
A28: HVAC incumbent | B28: =E11+E17 -> 0.1
A29: HVAC incumbent / BMS | B29: =E16 -> 0.04
A30: Power+Cooling | B30: =E5+E7+E9 -> 0.33
A31: Pure-play thermal | B31: =E6+E10+E13+E14 -> 0.29
A32: Water infra | B32: =E18+E19 -> 0.03
A34: CORRELATION WARNING: Pure-play thermal + Power+Cooling buckets together = ~57% of portfolio. These will move together on any AI capex headline. Diversification by ticker count is illusory. Consider pairing with a hedge or holding cash to reduce single-thesis exposure.

Sheet Risk_Register
A1: RISK REGISTER — disconfirming evidence
A3: Risk | B3: Description | C3: Impact | D3: Probability | E3: What would change my mind / hedge
A4: Hyperscaler capex pause | B4: MSFT/META/GOOG slow capex on AI ROI doubts; backlog cancellations begin | C4: 9 | D4: 4 | E4: Watch quarterly capex guides; VRT book-to-bill <1.0 for 2Q is a sell signal
A5: Power interconnection bottleneck | B5: New DC builds can't get connected on time; demand shifted right by 2-3 yrs | C5: 7 | D5: 5 | E5: Tracked monthly via FERC queue reports
A6: Liquid cooling commoditization | B6: Big margin compression as Asian entrants flood CDU/cold-plate market 2027+ | C6: 6 | D6: 4 | E6: Hedge by overweighting integrated platforms (ETN, SE) over single-product names
A7: Hyperscaler insourcing | B7: MSFT/GOOG design proprietary cooling, bypass OEMs | C7: 6 | D7: 3 | E7: Already partial reality; favors component vendors over system vendors
A8: Multiple compression | B8: Rates rise / risk-off / AI bubble pops; growth multiples derate 30-50% | C8: 8 | D8: 4 | E8: Bear case in Valuation tab models 30% haircut; portfolio loses ~25% in this scenario
A9: Water regulation | B9: State limits on DC withdrawals (AZ, TX, NV) | C9: 4 | D9: 5 | E9: Net positive for liquid cooling vendors (lower WUE)
A10: Efficiency-led demand softening | B10: DeepSeek-style algorithmic gains reduce compute per query | C10: 7 | D10: 4 | E10: Watch token costs; hyperscaler unit economics; if compute/query falls 50% in 12mo, demand path is bear
A11: Single-thesis correlation | B11: All names move on same AI capex headline; portfolio diversification is illusory | C11: 8 | D11: 5 | E11: Already flagged on Portfolio tab; consider 10-15% cash or hedge
A12: Modeling error in TAM | B12: TAM bridge could be 30% off either direction | C12: 5 | D12: 4 | E12: Stress-test in Control_Panel; outputs change linearly
A13: FX (SE.PA, MTRS) | B13: Euro/SEK weakness vs USD reduces reported returns | C13: 3 | D13: 3 | E13: Hedge currency or tilt to USD names

Sheet DCF_Valuation_v2_1
A1: DCF VALUATION MODEL — DATA CENTER COOLING EQUITY UNIVERSE
A2: Simplified FCF-Based DCF | Bear / Base / Bull Scenarios | April 2026 | Proprietary & Confidential
A4: SECTION 1 — GLOBAL DISCOUNT & TERMINAL VALUE ASSUMPTIONS
A5: Parameter | B5: Bear | C5: Base | D5: Bull | E5: Format | F5: Source / Note
A6: Risk-Free Rate (10yr UST) | B6: 0.043 | C6: 0.043 | D6: 0.043 | F6: Source: UST 10yr, Apr 2026
A7: Equity Risk Premium | B7: 0.055 | C7: 0.055 | D7: 0.055 | F7: Damodaran US ERP Jan 2026
A8: Average Beta (blended) | B8: 1.25 | C8: 1.15 | D8: 1.05 | F8: Bear: higher vol; Bull: de-risked compounder
A9: WACC (derived) | B9: =B6+B8*B7 -> 0.11175 | C9: =C6+C8*C7 -> 0.10625 | D9: =D6+D8*D7 -> 0.10075 | F9: RF + Beta x ERP
A10: Terminal Growth Rate | B10: 0.025 | C10: 0.03 | D10: 0.035 | F10: Bear: GDP-1%; Base: GDP; Bull: GDP+50bps
A11: Projection Horizon (years) | B11: 5 | C11: 5 | D11: 5 | F11: Standard 5-yr explicit FCF period
A12: Net Debt Adjustment Toggle | B12: 1 | C12: 1 | D12: 1 | F12: 1 = use per-company net debt; 0 = ignore
A14: Color Guide: Blue text = hardcoded inputs (editable) | Black text = formulas | Green text = cross-sheet links
A15: SECTION 2 — INDIVIDUAL COMPANY DCF MODELS (Revenue → FCF → Terminal Value → Implied Price)
A16: VRT — Vertiv Holdings
A17: Assumption / Output | B17: Bear | C17: Base | D17: Bull | E17: Year 1 | F17: Year 2 | G17: Year 3 | H17: Year 4 | I17: Year 5
A18: Revenue CAGR Assumption | B18: 0.12 | C18: 0.18 | D18: 0.26
A19: FCF Margin % Assumption | B19: 0.1 | C19: 0.13 | D19: 0.16
A20: Base Revenue 2025A ($M) | B20: 10200 | C20: 10200 | D20: 10200
A21: Net Debt 2025A ($M) | B21: 1800 | C21: 1800 | D21: 1800
A22: Diluted Shares Out (M) | B22: 380 | C22: 380 | D22: 380
A23: Projected Revenue ($M) — Base Case
A24: Revenue Projection ($M) | E24: =C20*(1+C18) -> 12036 | F24: =E24*(1+C18) -> 14202.48 | G24: =F24*(1+C18) -> 16758.926 | H24: =G24*(1+C18) -> 19775.533 | I24: =H24*(1+C18) -> 23335.129
A25: Free Cash Flow ($M) | E25: =E24*C19 -> 1564.68 | F25: =F24*C19 -> 1846.3224 | G25: =G24*C19 -> 2178.6604 | H25: =H24*C19 -> 2570.8193 | I25: =I24*C19 -> 3033.5668
A26: PV of FCF ($M) | E26: =E25/((1+C9)^1) -> 1414.4 | F26: =F25/((1+C9)^2) -> 1508.6933 | G26: =G25/((1+C9)^3) -> 1609.2729 | H26: =H25/((1+C9)^4) -> 1716.5577 | I26: =I25/((1+C9)^5) -> 1830.9949
A27: Sum PV of FCFs ($M) | B27: =(B20*(1+B18)^1*B19/((1+B9)^1))+(B20*(1+B18)^2*B19/((1+B9)^2))+(B20*(1+B18)^3*B19/((1+B9)^3))+(B20*(1+B18)^4*B19/((1+B9)^4))+(B20*(1+B18)^5*B19/((1+B9)^5)) -> 5214.6669 | C27: =(C20*(1+C18)^1*C19/((1+C9)^1))+(C20*(1+C18)^2*C19/((1+C9)^2))+(C20*(1+C18)^3*C19/((1+C9)^3))+(C20*(1+C18)^4*C19/((1+C9)^4))+(C20*(1+C18)^5*C19/((1+C9)^5)) -> 8079.9189 | D27: =(D20*(1+D18)^1*D19/((1+D9)^1))+(D20*(1+D18)^2*D19/((1+D9)^2))+(D20*(1+D18)^3*D19/((1+D9)^3))+(D20*(1+D18)^4*D19/((1+D9)^4))+(D20*(1+D18)^5*D19/((1+D9)^5)) -> 12463.318
A28: Terminal Value ($M) | B28: =(B20*(1+B18)^5*B19*(1+B10))/(B9-B10) -> 21239.518 | C28: =(C20*(1+C18)^5*C19*(1+C10))/(C9-C10) -> 40978.017 | D28: =(D20*(1+D18)^5*D19*(1+D10))/(D9-D10) -> 81586.344
A29: PV of Terminal Value ($M) | B29: =B28/((1+B9)^5) -> 12505.728 | C29: =C28/((1+C9)^5) -> 24733.44 | D29: =D28/((1+D9)^5) -> 50486.353
A30: Implied Enterprise Value ($M) | B30: =B27+B29 -> 17720.395 | C30: =C27+C29 -> 32813.359 | D30: =D27+D29 -> 62949.671
A31: (-) Net Debt ($M) | B31: =B21 -> 1800 | C31: =C21 -> 1800 | D31: =D21 -> 1800
A32: Equity Value ($M) | B32: =B30-B31 -> 15920.395 | C32: =C30-C31 -> 31013.359 | D32: =D30-D31 -> 61149.671
A33: Implied Price per Share ($) | B33: =B32/(B22) -> 41.895776 | C33: =C32/(C22) -> 81.614102 | D33: =D32/(D22) -> 160.92019
A34: Current Market Price ($) | B34: 108 | C34: 108 | D34: 108
A35: Upside / (Downside) | B35: =(B33/B34)-1 -> -0.61207615 | C35: =(C33/C34)-1 -> -0.24431387 | D35: =(D33/D34)-1 -> 0.49000173
A39: MOD — Modine Manufacturing
A40: Assumption / Output | B40: Bear | C40: Base | D40: Bull | E40: Year 1 | F40: Year 2 | G40: Year 3 | H40: Year 4 | I40: Year 5
A41: Revenue CAGR Assumption | B41: 0.1 | C41: 0.18 | D41: 0.28
A42: FCF Margin % Assumption | B42: 0.07 | C42: 0.09 | D42: 0.12
A43: Base Revenue 2025A ($M) | B43: 2580 | C43: 2580 | D43: 2580
A44: Net Debt 2025A ($M) | B44: 420 | C44: 420 | D44: 420
A45: Diluted Shares Out (M) | B45: 51 | C45: 51 | D45: 51
...
