Workbook

Sheet StudentData
A1: Mason
A2: Stephens
A3: 80679969
A4: 45716.947

Sheet DivData
A1: Ticker | B1: Monthly Calendar Date | C1: Shares Outstanding | D1: Distribution Ordinary Dividend Flag | E1: Dividend Amount | F1: Factor To Adjust Shares
A2: UVV | B2: 38016 | C2: 24992 | D2: Y | E2: 0.39 | F2: 0
A3: UVV | B3: 38044 | C3: 25141
A4: UVV | B4: 38077 | C4: 25141
A5: UVV | B5: 38107 | C5: 25141 | D5: Y | E5: 0.39 | F5: 0
A6: UVV | B6: 38135 | C6: 25141
A7: UVV | B7: 38168 | C7: 25466
A8: UVV | B8: 38198 | C8: 25515 | D8: Y | E8: 0.39 | F8: 0
A9: UVV | B9: 38230 | C9: 25532
A10: UVV | B10: 38260 | C10: 25532
A11: UVV | B11: 38289 | C11: 25532 | D11: Y | E11: 0.39 | F11: 0
A12: UVV | B12: 38321 | C12: 25535
A13: UVV | B13: 38352 | C13: 25535
A14: UVV | B14: 38383 | C14: 25535 | D14: Y | E14: 0.42 | F14: 0
A15: UVV | B15: 38411 | C15: 25622
A16: UVV | B16: 38442 | C16: 25622
A17: UVV | B17: 38471 | C17: 25622 | D17: Y | E17: 0.42 | F17: 0
A18: UVV | B18: 38503 | C18: 25669
A19: UVV | B19: 38533 | C19: 25669
A20: UVV | B20: 38562 | C20: 25683 | D20: Y | E20: 0.42 | F20: 0
A21: UVV | B21: 38595 | C21: 25705
A22: UVV | B22: 38625 | C22: 25705
A23: UVV | B23: 38656 | C23: 25705 | D23: Y | E23: 0.42 | F23: 0
A24: UVV | B24: 38686 | C24: 25715
A25: UVV | B25: 38716 | C25: 25715
A26: UVV | B26: 38748 | C26: 25715 | D26: Y | E26: 0.43 | F26: 0
A27: UVV | B27: 38776 | C27: 25723
A28: UVV | B28: 38807 | C28: 25723
A29: UVV | B29: 38835 | C29: 25723 | D29: Y | E29: 0.43 | F29: 0
A30: UVV | B30: 38868 | C30: 25723
A31: UVV | B31: 38898 | C31: 25748
A32: UVV | B32: 38929 | C32: 25748 | D32: Y | E32: 0.43 | F32: 0
A33: UVV | B33: 38960 | C33: 25748
A34: UVV | B34: 38989 | C34: 25748
A35: UVV | B35: 39021 | C35: 25748 | D35: Y | E35: 0.43 | F35: 0
A36: UVV | B36: 39051 | C36: 25775
A37: UVV | B37: 39080 | C37: 25775
A38: UVV | B38: 39113 | C38: 25775 | D38: Y | E38: 0.44 | F38: 0
A39: UVV | B39: 39141 | C39: 25969
A40: UVV | B40: 39171 | C40: 25969
...

Sheet RtrnData
A1: Ticker | B1: Monthly Calendar Date | C1: Monthly Total Return | D1: Value-weighted return including dividends
A2: UVV | B2: 43861 | C2: -0.055898687 | D2: -0.0017278557
A3: UVV | B3: 43889 | C3: -0.071495767 | D3: -0.077917925
A4: UVV | B4: 43921 | C4: -0.104154 | D4: -0.14173291
A5: UVV | B5: 43951 | C5: 0.11191323 | D5: 0.12967378
A6: UVV | B6: 43980 | C6: -0.089104817 | D6: 0.053738803 | G6: Lin Est | J6: Mkt Rtrn
A7: UVV | B7: 44012 | C7: -0.035179301 | D7: 0.025299125 | G7: {=LINEST(C2:C61,D2:D61,1,1)} -> 0.79677005 | H7: -0.0011540326 | J7: 0.1
A8: UVV | B8: 44043 | C8: 0.01029759 | D8: 0.055531515 | G8: 0.18175516 | H8: 0.0098974883
A9: UVV | B9: 44074 | C9: 0.029648956 | D9: 0.068442205 | G9: 0.24887304 | H9: 0.074951274
A10: UVV | B10: 44104 | C10: -0.035245335 | D10: -0.035055977 | G10: 19.217306 | H10: 58
A11: UVV | B11: 44134 | C11: -0.031624809 | D11: -0.020178318 | G11: 0.10795693 | H11: 0.32582622
A12: UVV | B12: 44165 | C12: 0.14203262 | D12: 0.123707
A13: UVV | B13: 44196 | C13: 0.068116897 | D13: 0.045048306
A14: UVV | B14: 44225 | C14: -0.042460832 | D14: -0.00063112875 | G14: Dicount Rate | H14: =H7+G7*J7 -> 0.078522973
A15: UVV | B15: 44253 | C15: 0.10791367 | D15: 0.029196292
A16: UVV | B16: 44286 | C16: 0.16076348 | D16: 0.030573271
A17: UVV | B17: 44316 | C17: -0.034053838 | D17: 0.048190158
A18: UVV | B18: 44344 | C18: -0.0033789792 | D18: 0.0070918504
A19: UVV | B19: 44377 | C19: 0.016595289 | D19: 0.02342178
A20: UVV | B20: 44407 | C20: -0.071358019 | D20: 0.01182778
A21: UVV | B21: 44439 | C21: -0.029907975 | D21: 0.027146419
A22: UVV | B22: 44469 | C22: -0.04486166 | D22: -0.042243373
A23: UVV | B23: 44498 | C23: -0.012133032 | D23: 0.0646505
A24: UVV | B24: 44530 | C24: -0.0091489362 | D24: -0.018350523
A25: UVV | B25: 44561 | C25: 0.17929998 | D25: 0.033341265
A26: UVV | B26: 44592 | C26: 0.0048184361 | D26: -0.059822418
... A61: UVV | B61: 45657 | C61: -0.039915966 | D61: -0.031582433

Sheet DivGrth
A1: =DivData!A1 -> Ticker | B1: =DivData!B1 -> Monthly Calendar Date | C1: =DivData!C1 -> Shares Outstanding | D1: =DivData!D1 -> Distribution Ordinary Dividend Flag | E1: =DivData!E1 -> Dividend Amount | F1: =DivData!F1 -> Factor To Adjust Shares | G1: Year | H1: OrdDiv | I1: SpltFac | J1: SplitAdj | L1: Year | M1: Ann Div | N1: Growth
A2: =DivData!A2 -> UVV | B2: =DivData!B2 -> 38016 | C2: =DivData!C2 -> 24992 | D2: =DivData!D2 -> Y | E2: =DivData!E2 -> 0.39 | F2: =DivData!F2 -> 0 | G2: =YEAR(B2) -> 2004 | H2: =IF(D2="Y",E2,) -> 0.39 | I2: =SUM($F$2:F2) -> 0 | J2: =H2*2^I2 -> 0.39 | L2: 2004 | M2: =SUMIF(G2:G253,L2,J2:J253) -> 1.56
A3: =DivData!A3 -> UVV | B3: =DivData!B3 -> 38044 | C3: =DivData!C3 -> 25141 | D3: =DivData!D3 | E3: =DivData!E3 -> 0 | F3: =DivData!F3 -> 0 | G3: =YEAR(B3) -> 2004 | H3: =IF(D3="Y",E3,) -> 0 | I3: =SUM($F$2:F3) -> 0 | J3: =H3*2^I3 -> 0 | L3: 2005 | M3: =SUMIF(G3:G254,L3,J3:J254) -> 1.68 | N3: =(M3-M2)/M2 -> 0.076923077
A4: =DivData!A4 -> UVV | B4: =DivData!B4 -> 38077 | C4: =DivData!C4 -> 25141 | D4: =DivData!D4 | E4: =DivData!E4 -> 0 | F4: =DivData!F4 -> 0 | G4: =YEAR(B4) -> 2004 | H4: =IF(D4="Y",E4,) -> 0 | I4: =SUM($F$2:F4) -> 0 | J4: =H4*2^I4 -> 0 | L4: 2006 | M4: =SUMIF(G4:G255,L4,J4:J255) -> 1.72 | N4: =(M4-M3)/M3 -> 0.023809524 | P4: Median | Q4: =MEDIAN(N3:N22) -> 0.020620748
A5: =DivData!A5 -> UVV | B5: =DivData!B5 -> 38107 | C5: =DivData!C5 -> 25141 | D5: =DivData!D5 -> Y | E5: =DivData!E5 -> 0.39 | F5: =DivData!F5 -> 0 | G5: =YEAR(B5) -> 2004 | H5: =IF(D5="Y",E5,) -> 0.39 | I5: =SUM($F$2:F5) -> 0 | J5: =H5*2^I5 -> 0.39 | L5: 2007 | M5: =SUMIF(G5:G256,L5,J5:J256) -> 1.76 | N5: =(M5-M4)/M4 -> 0.023255814 | P5: Average | Q5: =AVERAGE(N3:N22) -> 0.038034073
A6: =DivData!A6 -> UVV | B6: =DivData!B6 -> 38135 | C6: =DivData!C6 -> 25141 | D6: =DivData!D6 | E6: =DivData!E6 -> 0 | F6: =DivData!F6 -> 0 | G6: =YEAR(B6) -> 2004 | H6: =IF(D6="Y",E6,) -> 0 | I6: =SUM($F$2:F6) -> 0 | J6: =H6*2^I6 -> 0 | L6: 2008 | M6: =SUMIF(G6:G257,L6,J6:J257) -> 1.8 | N6: =(M6-M5)/M5 -> 0.022727273 | P6: Std | Q6: =_xlfn.STDEV.S(N3:N22) -> 0.05171414
A7: =DivData!A7 -> UVV | B7: =DivData!B7 -> 38168 | C7: =DivData!C7 -> 25466 | D7: =DivData!D7 | E7: =DivData!E7 -> 0 | F7: =DivData!F7 -> 0 | G7: =YEAR(B7) -> 2004 | H7: =IF(D7="Y",E7,) -> 0 | I7: =SUM($F$2:F7) -> 0 | J7: =H7*2^I7 -> 0 | L7: 2009 | M7: =SUMIF(G7:G258,L7,J7:J258) -> 1.84 | N7: =(M7-M6)/M6 -> 0.022222222
A8: =DivData!A8 -> UVV | B8: =DivData!B8 -> 38198 | C8: =DivData!C8 -> 25515 | D8: =DivData!D8 -> Y | E8: =DivData!E8 -> 0.39 | F8: =DivData!F8 -> 0 | G8: =YEAR(B8) -> 2004 | H8: =IF(D8="Y",E8,) -> 0.39 | I8: =SUM($F$2:F8) -> 0 | J8: =H8*2^I8 -> 0.39 | L8: 2010 | M8: =SUMIF(G8:G259,L8,J8:J259) -> 1.88 | N8: =(M8-M7)/M7 -> 0.02173913
A9: =DivData!A9 -> UVV | B9: =DivData!B9 -> 38230 | C9: =DivData!C9 -> 25532 | D9: =DivData!D9 | E9: =DivData!E9 -> 0 | F9: =DivData!F9 -> 0 | G9: =YEAR(B9) -> 2004 | H9: =IF(D9="Y",E9,) -> 0 | I9: =SUM($F$2:F9) -> 0 | J9: =H9*2^I9 -> 0 | L9: 2011 | M9: =SUMIF(G9:G260,L9,J9:J260) -> 1.92 | N9: =(M9-M8)/M8 -> 0.021276596 | P9: Sub Sample
A10: =DivData!A10 -> UVV | B10: =DivData!B10 -> 38260 | C10: =DivData!C10 -> 25532 | D10: =DivData!D10 | E10: =DivData!E10 -> 0 | F10: =DivData!F10 -> 0 | G10: =YEAR(B10) -> 2004 | H10: =IF(D10="Y",E10,) -> 0 | I10: =SUM($F$2:F10) -> 0 | J10: =H10*2^I10 -> 0 | L10: 2012 | M10: =SUMIF(G10:G261,L10,J10:J261) -> 1.96 | N10: =(M10-M9)/M9 -> 0.020833333 | P10: Median | Q10: =MEDIAN(N3:N15) -> 0.021276596
A11: =DivData!A11 -> UVV | B11: =DivData!B11 -> 38289 | C11: =DivData!C11 -> 25532 | D11: =DivData!D11 -> Y | E11: =DivData!E11 -> 0.39 | F11: =DivData!F11 -> 0 | G11: =YEAR(B11) -> 2004 | H11: =IF(D11="Y",E11,) -> 0.39 | I11: =SUM($F$2:F11) -> 0 | J11: =H11*2^I11 -> 0.39 | L11: 2013 | M11: =SUMIF(G11:G262,L11,J11:J262) -> 2 | N11: =(M11-M10)/M10 -> 0.020408163 | P11: Average | Q11: =AVERAGE(N3:N15) -> 0.025453975
A12: =DivData!A12 -> UVV | B12: =DivData!B12 -> 38321 | C12: =DivData!C12 -> 25535 | D12: =DivData!D12 | E12: =DivData!E12 -> 0 | F12: =DivData!F12 -> 0 | G12: =YEAR(B12) -> 2004 | H12: =IF(D12="Y",E12,) -> 0 | I12: =SUM($F$2:F12) -> 0 | J12: =H12*2^I12 -> 0 | L12: 2014 | M12: =SUMIF(G12:G263,L12,J12:J263) -> 2.04 | N12: =(M12-M11)/M11 -> 0.02 | P12: Std | Q12: =_xlfn.STDEV.S(N3:N15) -> 0.015541805
A13: =DivData!A13 -> UVV | B13: =DivData!B13 -> 38352 | C13: =DivData!C13 -> 25535 | D13: =DivData!D13 | E13: =DivData!E13 -> 0 | F13: =DivData!F13 -> 0 | G13: =YEAR(B13) -> 2004 | H13: =IF(D13="Y",E13,) -> 0 | I13: =SUM($F$2:F13) -> 0 | J13: =H13*2^I13 -> 0 | L13: 2015 | M13: =SUMIF(G13:G264,L13,J13:J264) -> 2.08 | N13: =(M13-M12)/M12 -> 0.019607843
A14: =DivData!A14 -> UVV | B14: =DivData!B14 -> 38383 | C14: =DivData!C14 -> 25535 | D14: =DivData!D14 -> Y | E14: =DivData!E14 -> 0.42 | F14: =DivData!F14 -> 0 | G14: =YEAR(B14) -> 2005 | H14: =IF(D14="Y",E14,) -> 0.42 | I14: =SUM($F$2:F14) -> 0 | J14: =H14*2^I14 -> 0.42 | L14: 2016 | M14: =SUMIF(G14:G265,L14,J14:J265) -> 2.12 | N14: =(M14-M13)/M13 -> 0.019230769
A15: =DivData!A15 -> UVV | B15: =DivData!B15 -> 38411 | C15: =DivData!C15 -> 25622 | D15: =DivData!D15 | E15: =DivData!E15 -> 0 | F15: =DivData!F15 -> 0 | G15: =YEAR(B15) -> 2005 | H15: =IF(D15="Y",E15,) -> 0 | I15: =SUM($F$2:F15) -> 0 | J15: =H15*2^I15 -> 0 | L15: 2017 | M15: =SUMIF(G15:G266,L15,J15:J266) -> 2.16 | N15: =(M15-M14)/M14 -> 0.018867925
A16: =DivData!A16 -> UVV | B16: =DivData!B16 -> 38442 | C16: =DivData!C16 -> 25622 | D16: =DivData!D16 | E16: =DivData!E16 -> 0 | F16: =DivData!F16 -> 0 | G16: =YEAR(B16) -> 2005 | H16: =IF(D16="Y",E16,) -> 0 | I16: =SUM($F$2:F16) -> 0 | J16: =H16*2^I16 -> 0 | L16: 2018 | M16: =SUMIF(G16:G267,L16,J16:J267) -> 2.6 | N16: =(M16-M15)/M15 -> 0.2037037
A17: =DivData!A17 -> UVV | B17: =DivData!B17 -> 38471 | C17: =DivData!C17 -> 25622 | D17: =DivData!D17 -> Y | E17: =DivData!E17 -> 0.42 | F17: =DivData!F17 -> 0 | G17: =YEAR(B17) -> 2005 | H17: =IF(D17="Y",E17,) -> 0.42 | I17: =SUM($F$2:F17) -> 0 | J17: =H17*2^I17 -> 0.42 | L17: 2019 | M17: =SUMIF(G17:G268,L17,J17:J268) -> 3.02 | N17: =(M17-M16)/M16 -> 0.16153846
A18: =DivData!A18 -> UVV | B18: =DivData!B18 -> 38503 | C18: =DivData!C18 -> 25669 | D18: =DivData!D18 | E18: =DivData!E18 -> 0 | F18: =DivData!F18 -> 0 | G18: =YEAR(B18) -> 2005 | H18: =IF(D18="Y",E18,) -> 0 | I18: =SUM($F$2:F18) -> 0 | J18: =H18*2^I18 -> 0 | L18: 2020 | M18: =SUMIF(G18:G269,L18,J18:J269) -> 3.06 | N18: =(M18-M17)/M17 -> 0.013245033
A19: =DivData!A19 -> UVV | B19: =DivData!B19 -> 38533 | C19: =DivData!C19 -> 25669 | D19: =DivData!D19 | E19: =DivData!E19 -> 0 | F19: =DivData!F19 -> 0 | G19: =YEAR(B19) -> 2005 | H19: =IF(D19="Y",E19,) -> 0 | I19: =SUM($F$2:F19) -> 0 | J19: =H19*2^I19 -> 0 | L19: 2021 | M19: =SUMIF(G19:G270,L19,J19:J270) -> 3.1 | N19: =(M19-M18)/M18 -> 0.013071895
A20: =DivData!A20 -> UVV | B20: =DivData!B20 -> 38562 | C20: =DivData!C20 -> 25683 | D20: =DivData!D20 -> Y | E20: =DivData!E20 -> 0.42 | F20: =DivData!F20 -> 0 | G20: =YEAR(B20) -> 2005 | H20: =IF(D20="Y",E20,) -> 0.42 | I20: =SUM($F$2:F20) -> 0 | J20: =H20*2^I20 -> 0.42 | L20: 2022 | M20: =SUMIF(G20:G271,L20,J20:J271) -> 3.14 | N20: =(M20-M19)/M19 -> 0.012903226
A21: =DivData!A21 -> UVV | B21: =DivData!B21 -> 38595 | C21: =DivData!C21 -> 25705 | D21: =DivData!D21 | E21: =DivData!E21 -> 0 | F21: =DivData!F21 -> 0 | G21: =YEAR(B21) -> 2005 | H21: =IF(D21="Y",E21,) -> 0 | I21: =SUM($F$2:F21) -> 0 | J21: =H21*2^I21 -> 0 | L21: 2023 | M21: =SUMIF(G21:G272,L21,J21:J272) -> 3.18 | N21: =(M21-M20)/M20 -> 0.012738854
A22: =DivData!A22 -> UVV | B22: =DivData!B22 -> 38625 | C22: =DivData!C22 -> 25705 | D22: =DivData!D22 | E22: =DivData!E22 -> 0 | F22: =DivData!F22 -> 0 | G22: =YEAR(B22) -> 2005 | H22: =IF(D22="Y",E22,) -> 0 | I22: =SUM($F$2:F22) -> 0 | J22: =H22*2^I22 -> 0 | L22: 2024 | M22: =SUMIF(G22:G273,L22,J22:J273) -> 3.22 | N22: =(M22-M21)/M21 -> 0.012578616
A23: =DivData!A23 -> UVV | B23: =DivData!B23 -> 38656 | C23: =DivData!C23 -> 25705 | D23: =DivData!D23 -> Y | E23: =DivData!E23 -> 0.42 | F23: =DivData!F23 -> 0 | G23: =YEAR(B23) -> 2005 | H23: =IF(D23="Y",E23,) -> 0.42 | I23: =SUM($F$2:F23) -> 0 | J23: =H23*2^I23 -> 0.42
A24: =DivData!A24 -> UVV | B24: =DivData!B24 -> 38686 | C24: =DivData!C24 -> 25715 | D24: =DivData!D24 | E24: =DivData!E24 -> 0 | F24: =DivData!F24 -> 0 | G24: =YEAR(B24) -> 2005 | H24: =IF(D24="Y",E24,) -> 0 | I24: =SUM($F$2:F24) -> 0 | J24: =H24*2^I24 -> 0
A25: =DivData!A25 -> UVV | B25: =DivData!B25 -> 38716 | C25: =DivData!C25 -> 25715 | D25: =DivData!D25 | E25: =DivData!E25 -> 0 | F25: =DivData!F25 -> 0 | G25: =YEAR(B25) -> 2005 | H25: =IF(D25="Y",E25,) -> 0 | I25: =SUM($F$2:F25) -> 0 | J25: =H25*2^I25 -> 0
A26: =DivData!A26 -> UVV | B26: =DivData!B26 -> 38748 | C26: =DivData!C26 -> 25715 | D26: =DivData!D26 -> Y | E26: =DivData!E26 -> 0.43 | F26: =DivData!F26 -> 0 | G26: =YEAR(B26) -> 2006 | H26: =IF(D26="Y",E26,) -> 0.43 | I26: =SUM($F$2:F26) -> 0 | J26: =H26*2^I26 -> 0.43
A27: =DivData!A27 -> UVV | B27: =DivData!B27 -> 38776 | C27: =DivData!C27 -> 25723 | D27: =DivData!D27 | E27: =DivData!E27 -> 0 | F27: =DivData!F27 -> 0 | G27: =YEAR(B27) -> 2006 | H27: =IF(D27="Y",E27,) -> 0 | I27: =SUM($F$2:F27) -> 0 | J27: =H27*2^I27 -> 0
A28: =DivData!A28 -> UVV | B28: =DivData!B28 -> 38807 | C28: =DivData!C28 -> 25723 | D28: =DivData!D28 | E28: =DivData!E28 -> 0 | F28: =DivData!F28 -> 0 | G28: =YEAR(B28) -> 2006 | H28: =IF(D28="Y",E28,) -> 0 | I28: =SUM($F$2:F28) -> 0 | J28: =H28*2^I28 -> 0
A29: =DivData!A29 -> UVV | B29: =DivData!B29 -> 38835 | C29: =DivData!C29 -> 25723 | D29: =DivData!D29 -> Y | E29: =DivData!E29 -> 0.43 | F29: =DivData!F29 -> 0 | G29: =YEAR(B29) -> 2006 | H29: =IF(D29="Y",E29,) -> 0.43 | I29: =SUM($F$2:F29) -> 0 | J29: =H29*2^I29 -> 0.43
A30: =DivData!A30 -> UVV | B30: =DivData!B30 -> 38868 | C30: =DivData!C30 -> 25723 | D30: =DivData!D30 | E30: =DivData!E30 -> 0 | F30: =DivData!F30 -> 0 | G30: =YEAR(B30) -> 2006 | H30: =IF(D30="Y",E30,) -> 0 | I30: =SUM($F$2:F30) -> 0 | J30: =H30*2^I30 -> 0
A31: =DivData!A31 -> UVV | B31: =DivData!B31 -> 38898 | C31: =DivData!C31 -> 25748 | D31: =DivData!D31 | E31: =DivData!E31 -> 0 | F31: =DivData!F31 -> 0 | G31: =YEAR(B31) -> 2006 | H31: =IF(D31="Y",E31,) -> 0 | I31: =SUM($F$2:F31) -> 0 | J31: =H31*2^I31 -> 0
A32: =DivData!A32 -> UVV | B32: =DivData!B32 -> 38929 | C32: =DivData!C32 -> 25748 | D32: =DivData!D32 -> Y | E32: =DivData!E32 -> 0.43 | F32: =DivData!F32 -> 0 | G32: =YEAR(B32) -> 2006 | H32: =IF(D32="Y",E32,) -> 0.43 | I32: =SUM($F$2:F32) -> 0 | J32: =H32*2^I32 -> 0.43
A33: =DivData!A33 -> UVV | B33: =DivData!B33 -> 38960 | C33: =DivData!C33 -> 25748 | D33: =DivData!D33 | E33: =DivData!E33 -> 0 | F33: =DivData!F33 -> 0 | G33: =YEAR(B33) -> 2006 | H33: =IF(D33="Y",E33,) -> 0 | I33: =SUM($F$2:F33) -> 0 | J33: =H33*2^I33 -> 0
A34: =DivData!A34 -> UVV | B34: =DivData!B34 -> 38989 | C34: =DivData!C34 -> 25748 | D34: =DivData!D34 | E34: =DivData!E34 -> 0 | F34: =DivData!F34 -> 0 | G34: =YEAR(B34) -> 2006 | H34: =IF(D34="Y",E34,) -> 0 | I34: =SUM($F$2:F34) -> 0 | J34: =H34*2^I34 -> 0
... A253: =DivData!A253 -> UVV | B253: =DivData!B253 -> 45657 | C253: =DivData!C253 -> 24693 | D253: =DivData!D253 | E253: =DivData!E253 -> 0 | F253: =DivData!F253 -> 0 | G253: =YEAR(B253) -> 2024 | H253: =IF(D253="Y",E253,) -> 0 | I253: =SUM($F$2:F253) -> 0 | J253: =H253*2^I253 -> 0

Sheet RndGrth
B1: 1 | C1: 2 | D1: 3 | E1: 4 | F1: 5 | G1: 6 | H1: 7 | I1: 8 | J1: 9 | K1: 10 | L1: 11 | M1: 12 | N1: 13 | O1: 14 | P1: 15 | Q1: 16 | R1: 17 | S1: 18 | T1: 19 | U1: 20 | V1: 21 | W1: 22 | X1: 23 | Y1: 24 | Z1: 25 | AA1: 26 | AB1: 27 | AC1: 28 | AD1: 29 | AE1: 30 | AF1: 31 | AG1: 32 | AH1: 33 | AI1: 34 | AJ1: 35 | AK1: 36 | AL1: 37 | AM1: 38 | AN1: 39 | AO1: 40 | AP1: 41 | AQ1: 42 | AR1: 43 | AS1: 44 | AT1: 45 | AU1: 46 | AV1: 47 | AW1: 48 | AX1: 49 | AY1: 50 | AZ1: 51 | BA1: 52 | BB1: 53 | BC1: 54 | BD1: 55 | BE1: 56 | BF1: 57 | BG1: 58 | BH1: 59 | BI1: 60 | BJ1: 61 | BK1: 62 | BL1: 63 | BM1: 64 | BN1: 65 | BO1: 66 | BP1: 67 | BQ1: 68 | BR1: 69 | BS1: 70 | BT1: 71 | BU1: 72 | BV1: 73 | BW1: 74 | BX1: 75 | BY1: 76 | BZ1: 77 | CA1: 78 | CB1: 79 | CC1: 80 | CD1: 81 | CE1: 82 | CF1: 83 | CG1: 84 | CH1: 85 | CI1: 86 | CJ1: 87 | CK1: 88 | CL1: 89 | CM1: 90 | CN1: 91 | CO1: 92 | CP1: 93 | CQ1: 94 | CR1: 95 | CS1: 96 | CT1: 97 | CU1: 98 | CV1: 99 | CW1: 100 | CX1: 101 | CY1: 102 | CZ1: 103 | DA1: 104 | DB1: 105 | DC1: 106 | DD1: 107 | DE1: 108 | DF1: 109 | DG1: 110 | DH1: 111 | DI1: 112 | DJ1: 113 | DK1: 114 | DL1: 115 | DM1: 116 | DN1: 117 | DO1: 118 | DP1: 119 | DQ1: 120 | DR1: 121 | DS1: 122 | DT1: 123 | DU1: 124 | DV1: 125 | DW1: 126 | DX1: 127 | DY1: 128 | DZ1: 129 | EA1: 130 | EB1: 131 | EC1: 132 | ED1: 133 | EE1: 134 | EF1: 135 | EG1: 136 | EH1: 137 | EI1: 138 | EJ1: 139 | EK1: 140 | EL1: 141 | EM1: 142 | EN1: 143 | EO1: 144 | EP1: 145 | EQ1: 146 | ER1: 147 | ES1: 148 | ET1: 149 | EU1: 150 | EV1: 151 | EW1: 152 | EX1: 153 | EY1: 154 | EZ1: 155 | FA1: 156 | FB1: 157 | FC1: 158 | FD1: 159 | FE1: 160 | FF1: 161 | FG1: 162 | FH1: 163 | FI1: 164 | FJ1: 165 | FK1: 166 | FL1: 167 | FM1: 168 | FN1: 169 | FO1: 170 | FP1: 171 | FQ1: 172 | FR1: 173 | FS1: 174 | FT1: 175 | FU1: 176 | FV1: 177 | FW1: 178 | FX1: 179 | FY1: 180 | FZ1: 181 | GA1: 182 | GB1: 183 | GC1: 184 | GD1: 185 | GE1: 186 | GF1: 187 | GG1: 188 | GH1: 189 | GI1: 190 | GJ1: 191 | GK1: 192 | GL1: 193 | GM1: 194 | GN1: 195 | GO1: 196 | GP1: 197 | GQ1: 198 | GR1: 199 | GS1: 200 | GT1: 201 | GU1: 202 | GV1: 203 | GW1: 204 | GX1: 205 | GY1: 206 | GZ1: 207 | HA1: 208 | HB1: 209 | HC1: 210 | HD1: 211 | HE1: 212 | HF1: 213 | HG1: 214 | HH1: 215 | HI1: 216 | HJ1: 217 | HK1: 218 | HL1: 219 | HM1: 220 | HN1: 221 | HO1: 222 | HP1: 223 | HQ1: 224 | HR1: 225 | HS1: 226 | HT1: 227 | HU1: 228 | HV1: 229 | HW1: 230 | HX1: 231 | HY1: 232 | HZ1: 233 | IA1: 234 | IB1: 235 | IC1: 236 | ID1: 237 | IE1: 238 | IF1: 239 | IG1: 240 | IH1: 241 | II1: 242 | IJ1: 243 | IK1: 244 | IL1: 245 | IM1: 246 | IN1: 247 | IO1: 248 | IP1: 249 | IQ1: 250 | IR1: 251 | IS1: 252 | IT1: 253 | IU1: 254 | IV1: 255 | IW1: 256 | IX1: 257 | IY1: 258 | IZ1: 259 | JA1: 260 | JB1: 261 | JC1: 262 | JD1: 263 | JE1: 264 | JF1: 265 | JG1: 266 | JH1: 267 | JI1: 268 | JJ1: 269 | JK1: 270 | JL1: 271 | JM1: 272 | JN1: 273 | JO1: 274 | JP1: 275 | JQ1: 276 | JR1: 277 | JS1: 278 | JT1: 279 | JU1: 280 | JV1: 281 | JW1: 282 | JX1: 283 | JY1: 284 | JZ1: 285 | KA1: 286 | KB1: 287 | KC1: 288 | KD1: 289 | KE1: 290 | KF1: 291 | KG1: 292 | KH1: 293 | KI1: 294 | KJ1: 295 | KK1: 296 | KL1: 297 | KM1: 298 | KN1: 299 | KO1: 300 | KP1: 301 | KQ1: 302 | KR1: 303 | KS1: 304 | KT1: 305 | KU1: 306 | KV1: 307 | KW1: 308 | KX1: 309 | KY1: 310 | KZ1: 311 | LA1: 312 | LB1: 313 | LC1: 314 | LD1: 315 | LE1: 316 | LF1: 317 | LG1: 318 | LH1: 319 | LI1: 320 | LJ1: 321 | LK1: 322 | LL1: 323 | LM1: 324 | LN1: 325 | LO1: 326 | LP1: 327 | LQ1: 328 | LR1: 329 | LS1: 330 | LT1: 331 | LU1: 332 | LV1: 333 | LW1: 334 | LX1: 335 | LY1: 336 | LZ1: 337 | MA1: 338 | MB1: 339 | MC1: 340 | MD1: 341 | ME1: 342 | MF1: 343 | MG1: 344 | MH1: 345 | MI1: 346 | MJ1: 347 | MK1: 348 | ML1: 349 | MM1: 350 | MN1: 351 | MO1: 352 | MP1: 353 | MQ1: 354 | MR1: 355 | MS1: 356 | MT1: 357 | MU1: 358 | MV1: 359 | MW1: 360 | MX1: 361 | MY1: 362 | MZ1: 363 | NA1: 364 | NB1: 365 | NC1: 366 | ND1: 367 | NE1: 368 | NF1: 369 | NG1: 370 | NH1: 371 | NI1: 372 | NJ1: 373 | NK1: 374 | NL1: 375 | NM1: 376 | NN1: 377 | NO1: 378 | NP1: 379 | NQ1: 380 | NR1: 381 | NS1: 382 | NT1: 383 | NU1: 384 | NV1: 385 | NW1: 386 | NX1: 387 | NY1: 388 | NZ1: 389 | OA1: 390 | OB1: 391 | OC1: 392 | OD1: 393 | OE1: 394 | OF1: 395 | OG1: 396 | OH1: 397 | OI1: 398 | OJ1: 399 | OK1: 400 | OL1: 401 | OM1: 402 | ON1: 403 | OO1: 404 | OP1: 405 | OQ1: 406 | OR1: 407 | OS1: 408 | OT1: 409 | OU1: 410 | OV1: 411 | OW1: 412 | OX1: 413 | OY1: 414 | OZ1: 415 | PA1: 416 | PB1: 417 | PC1: 418 | PD1: 419 | PE1: 420 | PF1: 421 | PG1: 422 | PH1: 423 | PI1: 424 | PJ1: 425 | PK1: 426 | PL1: 427 | PM1: 428 | PN1: 429 | PO1: 430 | PP1: 431 | PQ1: 432 | PR1: 433 | PS1: 434 | PT1: 435 | PU1: 436 | PV1: 437 | PW1: 438 | PX1: 439 | PY1: 440 | PZ1: 441 | QA1: 442 | QB1: 443 | QC1: 444 | QD1: 445 | QE1: 446 | QF1: 447 | QG1: 448 | QH1: 449 | QI1: 450 | QJ1: 451 | QK1: 452 | QL1: 453 | QM1: 454 | QN1: 455 | QO1: 456 | QP1: 457 | QQ1: 458 | QR1: 459 | QS1: 460 | QT1: 461 | QU1: 462 | QV1: 463 | QW1: 464 | QX1: 465 | QY1: 466 | QZ1: 467 | RA1: 468 | RB1: 469 | RC1: 470 | RD1: 471 | RE1: 472 | RF1: 473 | RG1: 474 | RH1: 475 | RI1: 476 | RJ1: 477 | RK1: 478 | RL1: 479 | RM1: 480 | RN1: 481 | RO1: 482 | RP1: 483 | RQ1: 484 | RR1: 485 | RS1: 486 | RT1: 487 | RU1: 488 | RV1: 489 | RW1: 490 | RX1: 491 | RY1: 492 | RZ1: 493 | SA1: 494 | SB1: 495 | SC1: 496 | SD1: 497 | SE1: 498 | SF1: 499 | SG1: 500
A2: 1 | B2: 0.05132696 | C2: 0.074328536 | D2: 0.083943827 | E2: 0.058984631 | F2: 0.052273011 | G2: 0.036361883 | H2: 0.087267407 | I2: 0.11662664 | J2: 0.073894502 | K2: 0.054488616 | L2: 0.018788077 | M2: 0.03834205 | N2: 0.059382939 | O2: 0.09789954 | P2: 0.050790019 | Q2: 0.095572834 | R2: 0.067542485 | S2: 0.061157234 | T2: 0.10035385 | U2: 0.10663465 | V2: 0.06001362 | W2: 0.049502472 | X2: 0.038464038 | Y2: 0.081718825 | Z2: 0.066654736 | AA2: 0.036726184 | AB2: 0.08019412 | AC2: 0.070673113 | AD2: 0.019067806 | AE2: 0.020018498 | AF2: 0.075204596 | AG2: 0.096044799 | AH2: 0.022617084 | AI2: 0.11149617 | AJ2: 0.041849615 | AK2: 0.085484231 | AL2: 0.093299815 | AM2: 0.026318316 | AN2: 0.055181179 | AO2: 0.034200481 | AP2: 0.070319326 | AQ2: 0.049752063 | AR2: 0.046483145 | AS2: 0.063353273 | AT2: 0.058064766 | AU2: 0.032989714 | AV2: 0.09237594 | AW2: 0.11398268 | AX2: 0.043642589 | AY2: 0.046839425 | AZ2: 0.038279251 | BA2: 0.11064128 | BB2: 0.079686917 | BC2: 0.02362748 | BD2: 0.0023846432 | BE2: 0.068457307 | BF2: 0.081969733 | BG2: 0.057399621 | BH2: 0.066298971 | BI2: 0.06182387 | BJ2: 0.071745821 | BK2: 0.091913601 | BL2: 0.10457856 | BM2: 0.031586711 | BN2: 0.072962949 | BO2: 0.11087024 | BP2: 0.073768074 | BQ2: 0.066835798 | BR2: 0.075438344 | BS2: 0.040732816 | BT2: 0.065889519 | BU2: 0.089851898 | BV2: 0.058681323 | BW2: 0.077301537 | BX2: 0.078717604 | BY2: 0.097869688 | BZ2: 0.069377143 | CA2: 0.061466559 | CB2: 0.07736021 | CC2: 0.0043524914 | CD2: 0.076690166 | CE2: 0.060242784 | CF2: 0.06028742 | CG2: 0.111889 | CH2: 0.065976784 | CI2: 0.091341765 | CJ2: 0.013567412 | CK2: 0.1076667 | CL2: 0.022889594 | CM2: 0.041510954 | CN2: 0.07058857 | CO2: 0.01332378 | CP2: 0.077459623 | CQ2: 0.070429739 | CR2: 0.053710793 | CS2: 0.049080414 | CT2: 0.034200481 | CU2: 0.091715235 | CV2: 0.086373097 | CW2: 0.010567509 | CX2: 0.10376183 | CY2: 0.033397046 | CZ2: 0.075614335 | DA2: 0.053675612 | DB2: 0.086995069 | DC2: 0.078654719 | DD2: 0.054380065 | DE2: 0.11292656 | DF2: 0.063143132 | DG2: 0.073436403 | DH2: 0.024000147 | DI2: 0.064925735 | DJ2: 0.074894556 | DK2: 0.052579269 | DL2: 0.042642277 | DM2: 0.010481791 | DN2: 0.10408912 | DO2: 0.075118305 | DP2: 0.068618974 | DQ2: 0.018306314 | DR2: 0.046552763 | DS2: 0.042121609 | DT2: 0.031822493 | DU2: 0.016281282 | DV2: 0.042146247 | DW2: 0.081167645 | DX2: 0.072836291 | DY2: 0.059191735 | DZ2: 0.082010472 | EA2: 0.017531528 | EB2: 0.088199476 | EC2: 0.10440139 | ED2: 0.072975411 | EE2: 0.037671604 | EF2: 0.042189908 | EG2: 0.076756975 | EH2: 0.084281084 | EI2: 0.071332443 | EJ2: 0.067848027 | EK2: 0.073854422 | EL2: 0.059008095 | EM2: 0.13272605 | EN2: 0.040915769 | EO2: 0.10999908 | EP2: 0.02785746 | EQ2: 0.053355946 | ER2: 0.053642437 | ES2: 0.067137988 | ET2: 0.087545704 | EU2: 0.033009482 | EV2: 0.029940535 | EW2: 0.089394258 | EX2: 0.063370605 | EY2: 0.048733989 | EZ2: 0.07724974 | FA2: 0.075284584 | FB2: 0.083849285 | FC2: 0.061607569 | FD2: 0.071097234 | FE2: 0.059599269 | FF2: 0.039181182 | FG2: 0.11510366 | FH2: 0.05772579 | FI2: 0.063800542 | FJ2: 0.067601187 | FK2: 0.045487475 | FL2: 0.063310843 | FM2: 0.095963894 | FN2: 0.070556368 | FO2: 0.087564154 | FP2: 0.051087311 | FQ2: 0.054609229 | FR2: 0.06259559 | FS2: 0.06151678 | FT2: 0.056816039 | FU2: 0.074765893 | FV2: 0.034434659 | FW2: 0.028335556 | FX2: 0.053557464 | FY2: 0.061205565 | FZ2: 0.090356351 | GA2: 0.059421931 | GB2: 0.1174577 | GC2: 0.053258109 | GD2: 0.043133151 | GE2: 0.059986404 | GF2: 0.072900637 | GG2: 0.067820581 | GH2: 0.11055098 | GI2: 0.0671263 | GJ2: 0.029899051 | GK2: 0.031454982 | GL2: 0.0398942 | GM2: 0.055565564 | GN2: 0.082043591 | GO2: 0.047500245 | GP2: 0.046314632 | GQ2: 0.11258025 | GR2: 0.01845632 | GS2: 0.088990649 | GT2: 0.087261334 | GU2: 0.10199762 | GV2: 0.026980569 | GW2: 0.092485494 | GX2: 0.065666629 | GY2: 0.078304885 | GZ2: 0.015179094 | HA2: 0.095950371 | HB2: 0.0512256 | HC2: 0.049587302 | HD2: 0.041708518 | HE2: 0.0014192836 | HF2: 0.061143683 | HG2: 0.06859531 | HH2: 0.078166682 | HI2: 0.055294658 | HJ2: 0.027738509 | HK2: 0.091180528 | HL2: 0.074500946 | HM2: 0.075924318 | HN2: 0.12303395 | HO2: 0.062593671 | HP2: 0.09672848 | HQ2: 0.033880414 | HR2: 0.10114353 | HS2: 0.025517861 | HT2: 0.074599069 | HU2: 0.041382233 | HV2: 0.015226537 | HW2: 0.070455839 | HX2: 0.049428672 | HY2: 0.052860947 | HZ2: 0.048499239 | IA2: 0.075405827 | IB2: 0.091580355 | IC2: 0.05653098 | ID2: 0.044678654 | IE2: 0.02142299 | IF2: 0.059256139 | IG2: 0.084735888 | IH2: 0.058910344 | II2: 0.094155105 | IJ2: 0.057767217 | IK2: 0.089761023 | IL2: 0.092706264 | IM2: 0.035130087 | IN2: 0.085228853 | IO2: 0.076388577 | IP2: 0.027597899 | IQ2: 0.090133461 | IR2: 0.024757973 | IS2: 0.059916414 | IT2: 0.095489407 | IU2: 0.055736943 | IV2: 0.10429906 | IW2: 0.032030657 | IX2: 0.090494554 | IY2: 0.014322601 | IZ2: 0.057445144 | JA2: 0.074188442 | JB2: 0.0071688108 | JC2: 0.02570557 | JD2: 0.082497965 | JE2: 0.030323573 | JF2: 0.027836832 | JG2: 0.11352108 | JH2: 0.045985024 | JI2: 0.064912184 | JJ2: 0.15748803 | JK2: 0.056441108 | JL2: 0.013419124 | JM2: 0.059464818 | JN2: 0.065337565 | JO2: 0.10142739 | JP2: 0.02405183 | JQ2: 0.02965284 | JR2: 0.030565829 | JS2: 0.051741112 | JT2: 0.081711233 | JU2: 0.11453824 | JV2: 0.061145632 | JW2: 0.0955816 | JX2: 0.071901185 | JY2: 0.072674739 | JZ2: 0.064441021 | KA2: 0.01193831 | KB2: 0.034234058 | KC2: 0.068095326 | KD2: 0.073591509 | KE2: 0.056827986 | KF2: 0.084390724 | KG2: 0.06180648 | KH2: 0.03077428 | KI2: 0.096826804 | KJ2: 0.018860845 | KK2: 0.078640767 | KL2: 0.071507317 | KM2: 0.091406569 | KN2: 0.049005926 | KO2: 0.048781719 | KP2: 0.023844296 | KQ2: 0.054833637 | KR2: 0.043252045 | KS2: 0.083047913 | KT2: 0.10871996 | KU2: 0.072946303 | KV2: 0.077930499 | KW2: 0.042717481 | KX2: 0.096588902 | KY2: 0.023461201 | KZ2: 0.038410922 | LA2: 0.08317437 | LB2: 0.082998006 | LC2: 0.071631568 | LD2: 0.078834263 | LE2: 0.063411086 | LF2: 0.060347583 | LG2: 0.088095652 | LH2: 0.055565564 | LI2: 0.10496945 | LJ2: 0.051106764 | LK2: 0.062464463 | LL2: 0.041775012 | LM2: 0.085607021 | LN2: 0.10775849 | LO2: 0.054148093 | LP2: 0.072998273 | LQ2: 0.081522407 | LR2: 0.069944911 | LS2: 0.067857825 | LT2: 0.069498386 | LU2: 0.028380707 | LV2: 0.057108231 | LW2: 0.045368811 | LX2: 0.061089537 | LY2: 0.077085638 | LZ2: 0.053416281 | MA2: 0.057662591 | MB2: 0.064103363 | MC2: 0.030712455 | MD2: 0.092069108 | ME2: 0.093319526 | MF2: 0.068412013 | MG2: 0.069387056 | MH2: 0.089078659 | MI2: 0.088268922 | MJ2: 0.044754345 | MK2: 0.072229303 | ML2: 0.02970418 | MM2: 0.099997455 | MN2: 0.075675301 | MO2: 0.066954663 | MP2: 0.029806514 | MQ2: 0.07989044 | MR2: 0.062389231 | MS2: 0.047884659 | MT2: 0.023273033 | MU2: 0.050119631 | MV2: 0.043814054 | MW2: 0.07190935 | MX2: 0.11041644 | MY2: 0.060727527 | MZ2: 0.051781679 | NA2: 0.080295882 | NB2: 0.085546972 | NC2: 0.099209491 | ND2: 0.047798769 | NE2: 0.13128489 | NF2: 0.069089478 | NG2: 0.080705822 | NH2: 0.029568498 | NI2: 0.024856411 | NJ2: 0.053109965 | NK2: 0.0074841799 | NL2: 0.072832166 | NM2: 0.083973565 | NN2: 0.080981684 | NO2: 0.061632695 | NP2: 0.065817781 | NQ2: 0.028445683 | NR2: 0.069434785 | NS2: 0.018390886 | NT2: 0.023266272 | NU2: 0.071927771 | NV2: 0.06552917 | NW2: 0.083084756 | NX2: 0.028415716 | NY2: 0.090212074 | NZ2: 0.071022346 | OA2: 0.047963386 | OB2: 0.055897922 | OC2: 0.074462585 | OD2: 0.10809369 | OE2: 0.023367461 | OF2: 0.035905446 | OG2: 0.064303992 | OH2: 0.088341748 | OI2: 0.13543603 | OJ2: 0.036739592 | OK2: 0.052416829 | OL2: 0.093037905 | OM2: 0.054851972 | ON2: 0.071670331 | OO2: 0.085475636 | OP2: 0.059832816 | OQ2: 0.050816147 | OR2: 0.0097371438 | OS2: 0.07427118 | OT2: 0.095798531 | OU2: 0.072243685 | OV2: 0.069518269 | OW2: 0.047691736 | OX2: 0.098760388 | OY2: 0.067799037 | OZ2: 0.064327141 | PA2: 0.051475363 | PB2: 0.061673233 | PC2: 0.055020801 | PD2: 0.10113757 | PE2: 0.11646346 | PF2: 0.074723062 | PG2: 0.061041177 | PH2: 0.085865837 | PI2: 0.033697518 | PJ2: 0.031943507 | PK2: 0.020026978 | PL2: 0.045843555 | PM2: 0.011003433 | PN2: 0.087115796 | PO2: 0.076097645 | PP2: 0.07274513 | PQ2: 0.0511781 | PR2: 0.075347326 | PS2: 0.030971844 | PT2: 0.089127707 | PU2: 0.060343686 | PV2: 0.0295167 | PW2: 0.04997163 | PX2: 0.05490695 | PY2: 0.057883561 | PZ2: 0.10196611 | QA2: 0.069256015 | QB2: 0.092188346 | QC2: 0.017748803 | QD2: 0.083620895 | QE2: 0.069117239 | QF2: 0.036112464 | QG2: 0.073772285 | QH2: 0.01049898 | QI2: 0.058984631 | QJ2: 0.06417086 | QK2: 0.060801155 | QL2: 0.011280069 | QM2: 0.078736226 | QN2: 0.042942004 | QO2: 0.034681098 | QP2: 0.042709431 | QQ2: 0.046844181 | QR2: 0.055446412 | QS2: 0.049953925 | QT2: 0.095004722 | QU2: 0.096298916 | QV2: 0.053888532 | QW2: 0.059626514 | QX2: 0.080325018 | QY2: 0.10451186 | QZ2: 0.1174577 | RA2: 0.064060905 | RB2: 0.10940662 | RC2: 0.037748728 | RD2: 0.05857747 | RE2: 0.035633508 | RF2: 0.085521303 | RG2: 0.080666601 | RH2: 0.054870308 | RI2: 0.071552096 | RJ2: 0.077848219 | RK2: 0.085880276 | RL2: 0.014054217 | RM2: 0.070498067 | RN2: 0.066619726 | RO2: 0.021184974 | RP2: 0.087976587 | RQ2: 0.064412057 | RR2: 0.044875072 | RS2: 0.067953972 | RT2: 0.050165928 | RU2: 0.080315306 | RV2: 0.05346613 | RW2: 0.07611303 | RX2: 0.085062688 | RY2: 0.085152704 | RZ2: 0.10368459 | SA2: 0.039416964 | SB2: 0.093620972 | SC2: 0.033812 | SD2: 0.032529896 | SE2: 0.027002227 | SF2: 0.085744766 | SG2: 0.097598496
A3: 2 | B3: 0.066147504 | C3: 0.077525286 | D3: 0.10092935 | E3: 0.088208931 | F3: 0.0802183 | G3: 0.076084467 | H3: 0.07076989 | I3: 0.07672357 | J3: 0.13629779 | K3: 0.070572469 | L3: 0.050060041 | M3: 0.017391262 | N3: 0.080524674 | O3: 0.060147669 | P3: 0.059379043 | Q3: 0.082927243 | R3: 0.075012762 | S3: 0.038039229 | T3: 0.089757643 | U3: 0.10462314 | V3: 0.095301928 | W3: 0.063636669 | X3: 0.051954461 | Y3: 0.056853856 | Z3: 0.073574721 | AA3: 0.076315665 | AB3: 0.093402379 | AC3: 0.073860754 | AD3: 0.027355642 | AE3: 0.083808833 | AF3: 0.07255278 | AG3: 0.11998661 | AH3: 0.028400761 | AI3: 0.061105007 | AJ3: 0.07403176 | AK3: 0.059279545 | AL3: 0.046951128 | AM3: 0.036235769 | AN3: 0.075083812 | AO3: 0.051251499 | AP3: 0.076457163 | AQ3: 0.011312385 | AR3: 0.034692042 | AS3: 0.075721082 | AT3: 0.067712804 | AU3: 0.018659958 | AV3: 0.056453084 | AW3: 0.049206527 | AX3: 0.063447729 | AY3: 0.050165928 | AZ3: 0.073560024 | BA3: 0.069032037 | BB3: 0.063372525 | BC3: 0.1375501 | BD3: 0.047761582 | BE3: 0.052728674 | BF3: 0.063326285 | BG3: 0.052873524 | BH3: 0.014976259 | BI3: 0.049172779 | BJ3: 0.045531881 | BK3: 0.067889225 | BL3: 0.050855282 | BM3: 0.06156895 | BN3: 0.070397595 | BO3: 0.066892294 | BP3: 0.059244421 | BQ3: 0.080488089 | BR3: 0.03460048 | BS3: 0.11584968 | BT3: 0.037658712 | BU3: 0.10142131 | BV3: 0.075096761 | BW3: 0.077575193 | BX3: 0.076561302 | BY3: 0.046471141 | BZ3: 0.045277076 | CA3: 0.053977201 | CB3: 0.050282587 | CC3: 0.061902999 | CD3: 0.07151342 | CE3: 0.06193775 | CF3: 0.06600973 | CG3: 0.060033044 | CH3: 0.029554402 | CI3: 0.071786675 | CJ3: 0.062875177 | CK3: 0.049341293 | CL3: 0.077750182 | CM3: 0.070481967 | CN3: 0.013446398 | CO3: 0.033846264 | CP3: 0.061843179 | CQ3: 0.020283903 | CR3: 0.040614954 | CS3: 0.064311699 | CT3: 0.10426995 | CU3: 0.083717385 | CV3: 0.029063873 | CW3: 0.064001114 | CX3: 0.058493128 | CY3: 0.046564738 | CZ3: 0.038792757 | DA3: 0.058655854 | DB3: 0.068099251 | DC3: 0.020528451 | DD3: 0.045726065 | DE3: 0.050137279 | DF3: 0.04785217 | DG3: 0.032678986 | DH3: 0.050187959 | DI3: 0.042116166 | DJ3: 0.081217408 | DK3: 0.086535366 | DL3: 0.05452543 | DM3: 0.042467002 | DN3: 0.09199124 | DO3: 0.016226734 | DP3: 0.0564171 | DQ3: 0.05225393 | DR3: 0.052448515 | DS3: 0.075475215 | DT3: 0.070447817 | DU3: 0.041527714 | DV3: 0.10319481 | DW3: 0.12023322 | DX3: 0.038476529 | DY3: 0.074222391 | DZ3: 0.075599094 | EA3: 0.071432028 | EB3: 0.062508812 | EC3: 0.053378865 | ED3: 0.063420713 | EE3: 0.038004277 | EF3: 0.054957802 | EG3: 0.026861045 | EH3: 0.084802612 | EI3: 0.00035353776 | EJ3: 0.0047288257 | EK3: 0.051486135 | EL3: 0.06102181 | EM3: 0.038891138 | EN3: 0.023096211 | EO3: 0.07709237 | EP3: 0.056275087 | EQ3: 0.033338831 | ER3: 0.0048700084 | ES3: 0.059632358 | ET3: 0.052913346 | EU3: 0.1097103 | EV3: 0.09415098 | EW3: 0.10283211 | EX3: 0.038121567 | EY3: 0.05596625 | EZ3: 0.06736062 | FA3: 0.059725783 | FB3: 0.026735218 | FC3: 0.053158009 | FD3: 0.074821615 | FE3: 0.093577081 | FF3: 0.042984577 | FG3: 0.040243776 | FH3: 0.066050469 | FI3: 0.084409948 | FJ3: 0.12509852 | FK3: 0.021184974 | FL3: 0.10742181 | FM3: 0.06686502 | FN3: 0.067122403 | FO3: 0.046490365 | FP3: 0.049017214 | FQ3: 0.076497014 | FR3: 0.095314935 | FS3: 0.065625976 | FT3: 0.08096438 | FU3: 0.073837576 | FV3: 0.08310842 | FW3: 0.085271254 | FX3: 0.05671846 | FY3: 0.073421735 | FZ3: 0.047617133 | GA3: 0.055120328 | GB3: 0.059297135 | GC3: 0.0028361527 | GD3: 0.082853959 | GE3: 0.041694623 | GF3: 0.075219723 | GG3: 0.077652374 | GH3: 0.068755172 | GI3: 0.042973919 | GJ3: 0.075718904 | GK3: 0.065207957 | GL3: 0.074680289 | GM3: 0.044020728 | GN3: 0.041125939 | GO3: 0.050926962 | GP3: 0.085113283 | GQ3: 0.058863388 | GR3: 0.073044054 | GS3: 0.10987004 | GT3: 0.087179397 | GU3: 0.030610407 | GV3: 0.056261077 | GW3: 0.079368282 | GX3: 0.10028544 | GY3: 0.056808103 | GZ3: 0.036194744 | HA3: 0.034906681 | HB3: 0.12541847 | HC3: 0.13205681 | HD3: 0.061958979 | HE3: 0.04583622 | HF3: 0.076940014 | HG3: 0.052770702 | HH3: 0.01332378 | HI3: 0.086651051 | HJ3: 0.067808835 | HK3: 0.046593502 | HL3: 0.084385252 | HM3: 0.081011364 | HN3: 0.062117237 | HO3: 0.088086198 | HP3: 0.07603393 | HQ3: 0.055250109 | HR3: 0.012693271 | HS3: 0.040371895 | HT3: 0.056269071 | HU3: 0.045366347 | HV3: 0.036235769 | HW3: 0.11342253 | HX3: 0.076267133 | HY3: 0.084542077 | HZ3: 0.054688873 | IA3: 0.063600027 | IB3: 0.074511603 | IC3: 0.072190254 | ID3: 0.041772233 | IE3: 0.028184346 | IF3: 0.060795339 | IG3: 0.068544028 | IH3: 0.088997181 | II3: 0.059162427 | IJ3: 0.04520001 | IK3: 0.063983753 | IL3: 0.12626465 | IM3: 0.031976739 | IN3: 0.038498359 | IO3: 0.029169702 | IP3: 0.075146324 | IQ3: 0.053952477 | IR3: 0.082598924 | IS3: 0.044711486 | IT3: 0.0194556 | IU3: 0.071911384 | IV3: 0.07755024 | IW3: 0.069283805 | IX3: 0.11210261 | IY3: 0.036304012 | IZ3: 0.036605343 | JA3: 0.087992229 | JB3: 0.06146461 | JC3: 0.063559546 | JD3: 0.092898442 | JE3: 0.10758465 | JF3: 0.077848219 | JG3: 0.031197599 | JH3: 0.063962553 | JI3: 0.0638642 | JJ3: 0.071182322 | JK3: 0.026436121 | JL3: 0.063829478 | JM3: 0.095811824 | JN3: 0.10705796 | JO3: 0.06574994 | JP3: 0.075198121 | JQ3: 0.074258431 | JR3: 0.07976341 | JS3: 0.027686597 | JT3: 0.096280638 | JU3: 0.09661205 | JV3: 0.020275766 | JW3: 0.10560706 | JX3: 0.064321354 | JY3: 0.075976918 | JZ3: 0.086692707 | KA3: 0.038795852 | KB3: 0.050598128 | KC3: 0.081946871 | KD3: 0.016753075 | KE3: 0.088792914 | KF3: 0.062007224 | KG3: 0.047821974 | KH3: 0.066720915 | KI3: 0.13246936 | KJ3: 0.064082134 | KK3: 0.080605349 | KL3: 0.042685251 | KM3: 0.038616508 | KN3: 0.05137002 | KO3: 0.054754164 | KP3: 0.05759346 | KQ3: 0.0067736827 | KR3: 0.070066899 | KS3: 0.054894745 | KT3: 0.078136801 | KU3: 0.055322992 | KV3: 0.090532715 | KW3: 0.0876968 | KX3: 0.090075533 | KY3: 0.085467099 | KZ3: 0.087127886 | LA3: 0.083800753 | LB3: 0.055014728 | LC3: 0.037451637 | LD3: 0.10283211 | LE3: 0.070642917 | LF3: 0.074639665 | LG3: 0.037402819 | LH3: 0.067067769 | LI3: 0.09453992 | LJ3: 0.062159694 | LK3: 0.075386317 | LL3: 0.060533744 | LM3: 0.070275178 | LN3: 0.058732233 | LO3: 0.068660401 | LP3: 0.059570047 | LQ3: 0.095380197 | LR3: 0.10188451 | LS3: 0.071558198 | LT3: 0.065593058 | LU3: 0.035542175 | LV3: 0.020275766 | LW3: 0.076576859 | LX3: 0.070044896 | LY3: 0.075105356 | LZ3: 0.051041845 | MA3: 0.074443419 | MB3: 0.088974377 | MC3: 0.016061486 | MD3: 0.063833317 | ME3: 0.0099186644 | MF3: 0.020324928 | MG3: 0.073837576 | MH3: 0.038426565 | MI3: 0.077875636 | MJ3: 0.0051198284 | MK3: 0.055067557 | ML3: 0.077713769 | MM3: 0.061435618 | MN3: 0.029615367 | MO3: 0.053834844 | MP3: 0.056297089 | MQ3: 0.077716032 | MR3: 0.038851202 | MS3: 0.087576473 | MT3: 0.057749455 | MU3: 0.067214138 | MV3: 0.019993516 | MW3: 0.064112989 | MX3: 0.083943827 | MY3: 0.029398608 | MZ3: 0.072319805 | NA3: 0.072319805 | NB3: 0.048960718 | NC3: 0.030409176 | ND3: 0.094510698 | NE3: 0.10086438 | NF3: 0.075668769 | NG3: 0.084972902 | NH3: 0.07997696 | NI3: 0.040912961 | NJ3: 0.038557491 | NK3: 0.067382136 | NL3: 0.041455059 | NM3: 0.088583947 | NN3: 0.075793106 | NO3: 0.026564126 | NP3: 0.077348923 | NQ3: 0.045994736 | NR3: 0.054010176 | NS3: 0.037838456 | NT3: 0.021544348 | NU3: 0.10684046 | NV3: 0.069924943 | NW3: 0.072935933 | NX3: 0.078698953 | NY3: 0.086473312 | NZ3: 0.032371638 | OA3: 0.055302766 | OB3: 0.043984659 | OC3: 0.034637151 | OD3: 0.059819179 | OE3: 0.083779209 | OF3: 0.035383173 | OG3: 0.070804154 | OH3: 0.040461853 | OI3: 0.050506308 | OJ3: 0.055531242 | OK3: 0.071393409 | OL3: 0.068646592 | OM3: 0.08593236 | ON3: 0.076430605 | OO3: 0.036338104 | OP3: 0.067036571 | OQ3: 0.062136517 | OR3: 0.060093265 | OS3: 0.024559263 | OT3: 0.0092324616 | OU3: 0.049215523 | OV3: 0.025879642 | OW3: 0.058479376 | OX3: 0.048649818 | OY3: 0.056672622 | OZ3: 0.033005528 | PA3: 0.097010846 | PB3: 0.080288605 | PC3: 0.089232677 | PD3: 0.050181341 | PE3: 0.054594933 | PF3: 0.056841909 | PG3: 0.071613204 | PH3: 0.058139541 | PI3: 0.074650351 | PJ3: 0.052915438 | PK3: 0.07246815 | PL3: 0.066678085 | PM3: 0.07706544 | PN3: 0.024825699 | PO3: 0.069713426 | PP3: 0.06421137 | PQ3: 0.074776607 | PR3: 0.064547194 | PS3: 0.056604809 | PT3: 0.092177172 | PU3: 0.072106083 | PV3: 0.078038105 | PW3: 0.10487078 | PX3: 0.064413976 | PY3: 0.060605482 | PZ3: 0.11314475 | QA3: 0.031163048 | QB3: 0.035083389 | QC3: -0.007934069 | QD3: 0.060557007 | QE3: 0.065738309 | QF3: 0.063343618 | QG3: 0.086662969 | QH3: 0.045339073 | QI3: 0.052522372 | QJ3: 0.025582608 | QK3: 0.038301254 | QL3: 0.059848372 | QM3: 0.028535297 | QN3: 0.069966913 | QO3: 0.062859735 | QP3: 0.077105835 | QQ3: 0.042200852 | QR3: 0.06124619 | QS3: 0.060634532 | QT3: 0.065480754 | QU3: 0.057134044 | QV3: 0.048320612 | QW3: 0.056668639 | QX3: 0.08413377 | QY3: 0.095051821 | QZ3: 0.061416308 | RA3: 0.051522634 | RB3: 0.10529261 | RC3: 0.050504102 | RD3: 0.071870473 | RE3: 0.067999123 | RF3: 0.041267035 | RG3: 0.095354069 | RH3: 0.11783586 | RI3: 0.11379313 | RJ3: 0.03552808 | RK3: 0.028816173 | RL3: 0.10542543 | RM3: 0.077877899 | RN3: 0.047003298 | RO3: 0.083386201 | RP3: 0.045554056 | RQ3: 0.085279734 | RR3: 0.076073465 | RS3: 0.073216951 | RT3: 0.04854035 | RU3: 0.052328045 | RV3: 0.067079487 | RW3: 0.075453528 | RX3: 0.061700278 | RY3: 0.051664103 | RZ3: 0.062553161 | SA3: 0.049716481 | SB3: 0.039531044 | SC3: 0.063997247 | SD3: 0.06280384 | SE3: 0.051616947 | SF3: 0.078077096 | SG3: 0.080080555
A4: 3 | B4: 0.087985926 | C4: 0.02087224 | D4: 0.067253186 | E4: 0.054271341 | F4: 0.025081822 | G4: 0.078351068 | H4: 0.079546307 | I4: 0.046832263 | J4: 0.088883502 | K4: 0.076022986 | L4: 0.079610596 | M4: 0.013186493 | N4: 0.083171734 | O4: 0.065798415 | P4: 0.026463968 | Q4: 0.086103739 | R4: 0.091678736 | S4: 0.057678405 | T4: 0.061711852 | U4: 0.053022184 | V4: 0.075623045 | W4: 0.11043867 | X4: 0.042580395 | Y4: 0.073654509 | Z4: 0.030346148 | AA4: 0.0069148654 | AB4: 0.045831321 | AC4: 0.037160734 | AD4: 0.061572789 | AE4: 0.052612989 | AF4: 0.094114137 | AG4: 0.05551305 | AH4: 0.045625392 | AI4: 0.08621759 | AJ4: 0.069922966 | AK4: 0.039444008 | AL4: 0.082536756 | AM4: 0.048865632 | AN4: 0.066265939 | AO4: 0.073333897 | AP4: 0.05678421 | AQ4: 0.040120929 | AR4: 0.074742343 | AS4: 0.067483783 | AT4: 0.067626627 | AU4: 0.068559785 | AV4: 0.088054856 | AW4: 0.069727378 | AX4: 0.11529824 | AY4: 0.068907356 | AZ4: 0.080823799 | BA4: 0.028415716 | BB4: 0.07403176 | BC4: 0.06833128 | BD4: 0.051516159 | BE4: 0.079198106 | BF4: 0.085110475 | BG4: 0.059850321 | BH4: 0.024764161 | BI4: 0.089055798 | BJ4: 0.055654319 | BK4: 0.046863204 | BL4: 0.047645095 | BM4: 0.068542051 | BN4: 0.051175951 | BO4: 0.058941629 | BP4: 0.068794708 | BQ4: 0.081944293 | BR4: 0.049705365 | BS4: 0.10084673 | BT4: 0.068417915 | BU4: 0.094274285 | BV4: 0.094093681 | BW4: 0.064026182 | BX4: 0.029755404 | BY4: 0.06894099 | BZ4: 0.036625569 | CA4: 0.067302004 | CB4: 0.089140828 | CC4: 0.062047763 | CD4: 0.050933437 | CE4: 0.06754641 | CF4: 0.043692037 | CG4: 0.064456463 | CH4: 0.089108111 | CI4: 0.076839485 | CJ4: 0.064047411 | CK4: 0.078244951 | CL4: 0.054028741 | CM4: 0.072805207 | CN4: 0.078747915 | CO4: 0.066027206 | CP4: 0.072431021 | CQ4: 0.024301192 | CR4: 0.040464775 | CS4: 0.071798936 | CT4: 0.062433608 | CU4: 0.08931828 | CV4: 0.09188415 | CW4: 0.051803051 | CX4: 0.054398486 | CY4: 0.075200299 | CZ4: 0.021947154 | DA4: 0.068826307 | DB4: 0.075788751 | DC4: 0.086399569 | DD4: 0.090208694 | DE4: 0.079118004 | DF4: 0.087249186 | DG4: 0.083121598 | DH4: 0.059684929 | DI4: 0.075256451 | DJ4: 0.059275649 | DK4: 0.094261909 | DL4: 0.062412379 | DM4: 0.012878917 | DN4: 0.054839739 | DO4: 0.040798709 | DP4: 0.063603895 | DQ4: 0.076545774 | DR4: 0.081150255 | DS4: 0.08646741 | DT4: 0.093150897 | DU4: 0.068933083 | DV4: 0.060822441 | DW4: 0.055310845 | DX4: 0.12339562 | DY4: 0.077060942 | DZ4: 0.061089537 | EA4: 0.041089096 | EB4: 0.053551247 | EC4: 0.057433283 | ED4: 0.063640508 | EE4: 0.042599247 | EF4: 0.04146904 | EG4: 0.048437471 | EH4: 0.060620981 | EI4: 0.056042542 | EJ4: 0.055081767 | EK4: 0.023320247 | EL4: 0.077827706 | EM4: 0.042485911 | EN4: 0.14057911 | EO4: 0.052904952 | EP4: 0.04253725 | EQ4: 0.046605477 | ER4: 0.077857387 | ES4: 0.054868274 | ET4: 0.03703548 | EU4: 0.064624404 | EV4: 0.02304132 | EW4: 0.07311688 | EX4: 0.051098112 | EY4: 0.052082093 | EZ4: 0.075183023 | FA4: 0.079231167 | FB4: 0.087079526 | FC4: 0.062765279 | FD4: 0.0278986 | FE4: 0.09494072 | FF4: 0.045757923 | FG4: 0.078559461 | FH4: 0.059793911 | FI4: -0.0035079003 | FJ4: 0.017421516 | FK4: 0.087267407 | FL4: 0.048747626 | FM4: 0.056881731 | FN4: 0.034874079 | FO4: 0.073131491 | FP4: 0.06764035 | FQ4: 0.003746506 | FR4: 0.075806227 | FS4: 0.059441441 | FT4: 0.097790445 | FU4: 0.062815415 | FV4: 0.080148167 | FW4: 0.064095628 | FX4: 0.069865037 | FY4: 0.079909635 | FZ4: 0.093473658 | GA4: 0.091223387 | GB4: 0.10397452 | GC4: 0.061257793 | GD4: 0.069351302 | GE4: 0.075603449 | GF4: 0.087073453 | GG4: 0.036876306 | GH4: 0.063796703 | GI4: 0.053685926 | GJ4: 0.091584022 | GK4: 0.040858729 | GL4: 0.030009464 | GM4: 0.095245604 | GN4: 0.032662885 | GO4: 0.062961926 | GP4: 0.017709611 | GQ4: 0.065465283 | GR4: 0.070862713 | GS4: 0.049860872 | GT4: 0.099145317 | GU4: 0.043096079 | GV4: 0.096845598 | GW4: 0.060467852 | GX4: 0.057235204 | GY4: 0.081209902 | GZ4: 0.071411687 | HA4: 0.028903953 | HB4: 0.062007224 | HC4: 0.074866652 | HD4: 0.054275467 | HE4: 0.079460761 | HF4: 0.023259511 | HG4: 0.016160727 | HH4: 0.14079547 | HI4: 0.10409622 | HJ4: 0.060865042 | HK4: 0.067875473 | HL4: 0.066166928 | HM4: 0.056028504 | HN4: 0.023109848 | HO4: 0.06676959 | HP4: 0.085325057 | HQ4: 0.062080566 | HR4: 0.067587492 | HS4: 0.048978796 | HT4: 0.087873622 | HU4: 0.074931055 | HV4: 0.055504971 | HW4: 0.10809369 | HX4: 0.065503988 | HY4: 0.043839981 | HZ4: 0.052554001 | IA4: 0.086089185 | IB4: 0.055793324 | IC4: 0.074260552 | ID4: 0.050319945 | IE4: 0.03077428 | IF4: 0.06978121 | IG4: 0.11131602 | IH4: 0.030323573 | II4: 0.097588755 | IJ4: 0.079632025 | IK4: 0.05346613 | IL4: 0.099403159 | IM4: 0.062047763 | IN4: 0.023961414 | IO4: 0.083663754 | IP4: 0.023034444 | IQ4: 0.085750495 | IR4: 0.069430774 | IS4: 0.058767471 | IT4: 0.084300279 | IU4: 0.054131648 | IV4: 0.055660364 | IW4: 0.068601212 | IX4: 0.063526771 | IY4: 0.072054801 | IZ4: 0.07178464 | JA4: 0.080395523 | JB4: 0.077871081 | JC4: 0.057185641 | JD4: 0.056722442 | JE4: 0.051839349 | JF4: 0.037154202 | JG4: 0.055407965 | JH4: 0.064508576 | JI4: 0.051659806 | JJ4: 0.070108898 | JK4: 0.017381178 | JL4: 0.052686646 | JM4: 0.096565696 | JN4: 0.067636425 | JO4: 0.065930229 | JP4: 0.015927638 | JQ4: 0.11306247 | JR4: 0.065200222 | JS4: 0.052978265 | JT4: 0.0042635646 | JU4: 0.070283199 | JV4: 0.083938384 | JW4: 0.056696544 | JX4: 0.047824324 | JY4: 0.073171084 | JZ4: 0.08941414 | KA4: 0.074620441 | KB4: 0.030919359 | KC4: 0.042577702 | KD4: 0.010652539 | KE4: 0.089550281 | KF4: 0.022274899 | KG4: 0.051533348 | KH4: 0.062414328 | KI4: 0.085935225 | KJ4: 0.069693487 | KK4: 0.074686707 | KL4: 0.058622535 | KM4: 0.10690968 | KN4: 0.05508784 | KO4: 0.063249162 | KP4: 0.051395833 | KQ4: 0.085262773 | KR4: 0.054300076 | KS4: 0.066824109 | KT4: 0.038112113 | KU4: 0.020496135 | KV4: 0.01845632 | KW4: 0.0586676 | KX4: 0.076501454 | KY4: 0.056347139 | KZ4: 0.081011364 | LA4: 0.09873426 | LB4: 0.055714797 | LC4: 0.061130161 | LD4: 0.056036526 | LE4: 0.08871877 | LF4: 0.031726003 | LG4: 0.026154444 | LH4: 0.063663657 | LI4: 0.10882882 | LJ4: 0.063640508 | LK4: 0.11969737 | LL4: 0.039374792 | LM4: 0.056742382 | LN4: 0.095146306 | LO4: 0.08465547 | LP4: 0.067816656 | LQ4: 0.045336609 | LR4: 0.063898894 | LS4: 0.082578183 | LT4: 0.065149943 | LU4: 0.075692748 | LV4: 0.044100458 | LW4: 0.051432389 | LX4: 0.044915238 | LY4: 0.062709356 | LZ4: 0.057074482 | MA4: 0.022847996 | MB4: 0.032359377 | MC4: 0.0990337 | MD4: 0.01845632 | ME4: 0.025717259 | MF4: 0.046499991 | MG4: 0.036416201 | MH4: 0.084824901 | MI4: 0.051475363 | MJ4: 0.050137279 | MK4: 0.041390656 | ML4: 0.04530435 | MM4: 0.082015572 | MN4: 0.040082768 | MO4: 0.055728892 | MP4: 0.072869495 | MQ4: 0.046722623 | MR4: 0.069843092 | MS4: 0.056959256 | MT4: 0.10348955 | MU4: 0.0714483 | MV4: 0.081809843 | MW4: 0.094344533 | MX4: 0.013540596 | MY4: 0.043496364 | MZ4: 0.032326717 | NA4: 0.083161134 | NB4: 0.093741126 | NC4: 0.03362091 | ND4: 0.066079577 | NE4: 0.041006845 | NF4: 0.033853827 | NG4: 0.054378002 | NH4: 0.034129317 | NI4: 0.027603056 | NJ4: 0.099997455 | NK4: 0.060762421 | NL4: 0.060950216 | NM4: 0.07014895 | NN4: 0.051676938 | NO4: 0.057749455 | NP4: 0.095056119 | NQ4: 0.049902986 | NR4: 0.076852892 | NS4: 0.0736356 | NT4: 0.078134509 | NU4: 0.094402519 | NV4: 0.057207443 | NW4: 0.015355573 | NX4: 0.062522306 | NY4: 0.037739101 | NZ4: 0.057253052 | OA4: 0.043164894 | OB4: 0.075180875 | OC4: 0.057773119 | OD4: 0.091998631 | OE4: 0.084989748 | OF4: 0.081140285 | OG4: 0.029322631 | OH4: 0.073290035 | OI4: 0.058019501 | OJ4: 0.098373282 | OK4: 0.016259509 | OL4: 0.057792858 | OM4: 0.098271405 | ON4: 0.06237187 | OO4: 0.099577116 | OP4: 0.065618212 | OQ4: 0.051423794 | OR4: 0.056634719 | OS4: 0.066330027 | OT4: 0.062368031 | OU4: 0.054119272 | OV4: 0.068790754 | OW4: 0.038638224 | OX4: 0.079806498 | OY4: 0.04797496 | OZ4: 0.082374144 | PA4: 0.08697702 | PB4: 0.01051617 | PC4: 0.087221855 | PD4: 0.063278069 | PE4: 0.094307289 | PF4: 0.088303759 | PG4: 0.035315733 | PH4: 0.087453626 | PI4: 0.062950352 | PJ4: 0.045797114 | PK4: 0.04511286 | PL4: 0.074021217 | PM4: 0.050560999 | PN4: 0.073419644 | PO4: 0.027908913 | PP4: 0.0012226363 | PQ4: 0.050532579 | PR4: 0.073930371 | PS4: 0.086556108 | PT4: 0.03561947 | PU4: 0.094962035 | PV4: 0.08603097 | PW4: 0.021498968 | PX4: 0.029184141 | PY4: 0.031914284 | PZ4: 0.033743414 | QA4: 0.099209491 | QB4: 0.051503296 | QC4: 0.042159884 | QD4: 0.055146685 | QE4: 0.084658221 | QF4: 0.0033009554 | QG4: 0.058832075 | QH4: 0.003494394 | QI4: 0.052896586 | QJ4: 0.088702669 | QK4: 0.045806855 | QL4: 0.068624876 | QM4: 0.071147886 | QN4: 0.081804772 | QO4: 0.078612863 | QP4: 0.070032864 | QQ4: 0.053710793 | QR4: 0.065457548 | QS4: 0.066689773 | QT4: 0.084619487 | QU4: 0.071452368 | QV4: 0.06291179 | QW4: 0.04320718 | QX4: 0.065403344 | QY4: 0.052680343 | QZ4: 0.066001995 | RA4: 0.087346651 | RB4: 0.062913738 | RC4: 0.077063205 | RD4: 0.069980894 | RE4: 0.052052355 | RF4: 0.052499166 | RG4: 0.016160727 | RH4: 0.067977521 | RI4: 0.04428748 | RJ4: 0.056485056 | RK4: 0.030923714 | RL4: 0.033594038 | RM4: 0.089603625 | RN4: 0.040310815 | RO4: 0.056923502 | RP4: 0.046502369 | RQ4: 0.046996193 | RR4: 0.081122924 | RS4: 0.067691259 | RT4: 0.02766574 | RU4: 0.070612721 | RV4: 0.077040773 | RW4: 0.038039229 | RX4: 0.070485978 | RY4: 0.053520105 | RZ4: 0.082731398 | SA4: 0.045356434 | SB4: 0.030906181 | SC4: 0.089497051 | SD4: 0.11043867 | SE4: 0.092782929 | SF4: 0.077166485 | SG4: 0.11314475
A5: 4 | B5: 0.028295332 | C5: 0.009626673 | D5: 0.021392508 | E5: 0.039001437 | F5: 0.064448728 | G5: 0.081175122 | H5: 0.054067847 | I5: 0.060772105 | J5: 0.055976306 | K5: 0.074362542 | L5: 0.088494447 | M5: 0.036692665 | N5: 0.071054719 | O5: -0.0014919216 | P5: 0.13205681 | Q5: 0.055909983 | R5: 0.047826616 | S5: 0.064487347 | T5: 0.055164964 | U5: 0.067052156 | V5: 0.06832343 | W5: 0.085532705 | X5: 0.074631127 | Y5: 0.070907119 | Z5: 0.025033348 | AA5: 0.080066059 | AB5: 0.067518993 | AC5: 0.044514094 | AD5: 0.041524906 | AE5: 0.011582374 | AF5: 0.038891138 | AG5: 0.11759567 | AH5: 0.09188415 | AI5: 0.053216425 | AJ5: 0.066130056 | AK5: 0.062246501 | AL5: 0.05314549 | AM5: 0.053729415 | AN5: 0.043016434 | AO5: 0.065505907 | AP5: 0.077437047 | AQ5: 0.074845222 | AR5: 0.10201653 | AS5: 0.048048932 | AT5: 0.076183421 | AU5: 0.05015931 | AV5: 0.091755515 | AW5: 0.061868276 | AX5: 0.084079366 | AY5: 0.074571337 | AZ5: 0.050165928 | BA5: 0.09250446 | BB5: 0.065385925 | BC5: 0.071397477 | BD5: 0.01391143 | BE5: 0.076154829 | BF5: 0.096649237 | BG5: 0.072598217 | BH5: 0.074853788 | BI5: 0.047050684 | BJ5: 0.077727434 | BK5: 0.06247409 | BL5: 0.11459966 | BM5: 0.097736126 | BN5: 0.10182194 | BO5: 0.078346426 | BP5: 0.047026991 | BQ5: 0.020292154 | BR5: 0.08128714 | BS5: 0.041805438 | BT5: 0.042518342 | BU5: 0.062335227 | BV5: 0.064400483 | BW5: 0.10226463 | BX5: 0.042195409 | BY5: 0.031227852 | BZ5: 0.022439804 | CA5: 0.069605849 | CB5: 0.042604633 | CC5: 0.084437451 | CD5: 0.084566945 | CE5: 0.094044692 | CF5: 0.065670525 | CG5: 0.08309527 | CH5: 0.038513945 | CI5: 0.027072475 | CJ5: 0.063312763 | CK5: 0.051257973 | CL5: 0.053066103 | CM5: 0.027350371 | CN5: 0.045398491 | CO5: 0.081572657 | CP5: 0.051894785 | CQ5: 0.039096037 | CR5: 0.079489238 | CS5: 0.044736697 | CT5: 0.035076226 | CU5: 0.088555126 | CV5: 0.055759088 | CW5: 0.064388908 | CX5: 0.003746506 | CY5: 0.088731662 | CZ5: 0.10331066 | DA5: 0.080429587 | DB5: 0.078443547 | DC5: 0.10044553 | DD5: 0.060655847 | DE5: 0.057169769 | DF5: 0.070876837 | DG5: 0.054306236 | DH5: 0.090868425 | DI5: 0.0106695 | DJ5: 0.065264052 | DK5: 0.075027831 | DL5: 0.083765802 | DM5: 0.057375871 | DN5: 0.052944774 | DO5: 0.083040034 | DP5: 0.061489736 | DQ5: 0.071501186 | DR5: 0.040952841 | DS5: 0.089036259 | DT5: 0.030137583 | DU5: 0.061594047 | DV5: 0.029629463 | DW5: 0.031514572 | DX5: 0.068203419 | DY5: 0.085079534 | DZ5: 0.029903692 | EA5: 0.018567708 | EB5: 0.036012593 | EC5: 0.062364163 | ED5: 0.069369179 | EE5: 0.13801215 | EF5: 0.067048259 | EG5: 0.040525511 | EH5: 0.020585062 | EI5: 0.082796546 | EJ5: 0.067479887 | EK5: 0.090794568 | EL5: 0.070058877 | EM5: 0.042612712 | EN5: 0.044925266 | EO5: 0.042714817 | EP5: 0.0088639198 | EQ5: 0.043525128 | ER5: 0.084699819 | ES5: 0.082627459 | ET5: 0.044182567 | EU5: 0.065523355 | EV5: 0.088098746 | EW5: 0.040252543 | EX5: 0.018869784 | EY5: 0.057751431 | EZ5: 0.032918378 | FA5: 0.0095524146 | FB5: 0.054328811 | FC5: 0.062611032 | FD5: 0.037065218 | FE5: 0.09839368 | FF5: 0.04520001 | FG5: 0.050755182 | FH5: 0.083084756 | FI5: 0.05893186 | FJ5: 0.051574087 | FK5: 0.064558769 | FL5: 0.077921331 | FM5: 0.01724985 | FN5: 0.10753022 | FO5: 0.048570002 | FP5: 0.057670498 | FQ5: 0.02440238 | FR5: 0.063652083 | FS5: 0.097101148 | FT5: 0.045475127 | FU5: 0.089291923 | FV5: 0.023673662 | FW5: 0.05187559 | FX5: 0.052879798 | FY5: 0.087836263 | FZ5: 0.04620588 | GA5: 0.047940238 | GB5: 0.015472003 | GC5: 0.10070612 | GD5: 0.048051253 | GE5: 0.094669815 | GF5: 0.042304333 | GG5: 0.10085853 | GH5: 0.081974833 | GI5: 0.075144175 | GJ5: 0.072451648 | GK5: 0.046186513 | GL5: 0.08129711 | GM5: 0.051037519 | GN5: 0.069853062 | GO5: 0.080015465 | GP5: 0.047244294 | GQ5: 0.058841873 | GR5: 0.070905114 | GS5: 0.10831211 | GT5: 0.07956533 | GU5: 0.091755515 | GV5: 0.097969329 | GW5: 0.06280384 | GX5: 0.029722859 | GY5: 0.057149915 | GZ5: 0.052697132 | HA5: 0.087282648 | HB5: 0.046220405 | HC5: 0.062607165 | HD5: 0.042738939 | HE5: 0.058194604 | HF5: 0.035344153 | HG5: 0.02900583 | HH5: 0.0014967508 | HI5: 0.045704005 | HJ5: 0.02218815 | HK5: 0.02362748 | HL5: 0.049683133 | HM5: 0.074116389 | HN5: 0.044842412 | HO5: 0.040989798 | HP5: 0.082557441 | HQ5: 0.09420845 | HR5: 0.073000364 | HS5: 0.054232321 | HT5: 0.097849805 | HU5: 0.078545538 | HV5: 0.082531542 | HW5: 0.095798531 | HX5: 0.11962632 | HY5: 0.01855854 | HZ5: 0.059347844 | IA5: 0.073139799 | IB5: 0.014585485 | IC5: 0.066847487 | ID5: 0.057846117 | IE5: 0.082526385 | IF5: 0.063977966 | IG5: 0.059599269 | IH5: 0.10775849 | II5: 0.089150626 | IJ5: 0.045277076 | IK5: 0.048972006 | IL5: 0.092538609 | IM5: 0.044907732 | IN5: 0.047453404 | IO5: 0.093757227 | IP5: 0.050974691 | IQ5: 0.052429492 | IR5: 0.054022553 | IS5: 0.067889225 | IT5: 0.10256877 | IU5: 0.074802306 | IV5: 0.085113283 | IW5: 0.052655075 | IX5: 0.073700748 | IY5: 0.057895393 | IZ5: 0.025594411 | JA5: 0.068230951 | JB5: 0.063681018 | JC5: 0.04730079 | JD5: 0.028031875 | JE5: 0.078794555 | JF5: 0.093307665 | JG5: 0.055682538 | JH5: 0.078413465 | JI5: 0.066890346 | JJ5: 0.085687296 | JK5: 0.048129723 | JL5: 0.048469501 | JM5: 0.056008421 | JN5: 0.053059829 | JO5: 0.041558368 | JP5: 0.049674195 | JQ5: 0.028947729 | JR5: 0.081043566 | JS5: 0.033655461 | JT5: 0.087276575 | JU5: 0.018623173 | JV5: 0.082809581 | JW5: 0.085090764 | JX5: 0.055952183 | JY5: 0.096869147 | JZ5: 0.054888615 | KA5: 0.11050605 | KB5: 0.06399146 | KC5: 0.062799973 | KD5: 0.052564544 | KE5: 0.031603614 | KF5: 0.059484329 | KG5: 0.057373894 | KH5: 0.054963904 | KI5: -0.0040341266 | KJ5: 0.075871805 | KK5: 0.099225534 | KL5: 0.07558603 | KM5: 0.061420147 | KN5: 0.015587516 | KO5: 0.076922109 | KP5: 0.095856402 | KQ5: 0.049643025 | KR5: 0.075540392 | KS5: 0.081784546 | KT5: 0.052099082 | KU5: 0.11630257 | KV5: 0.0482057 | KW5: 0.055936111 | KX5: 0.053112085 | KY5: 0.050827005 | KZ5: 0.046670052 | LA5: 0.048464946 | LB5: 0.10698795 | LC5: 0.043522492 | LD5: 0.057551948 | LE5: 0.088067404 | LF5: 0.048512933 | LG5: 0.020431159 | LH5: 0.042604633 | LI5: 0.074082526 | LJ5: 0.15028588 | LK5: 0.076812698 | LL5: 0.05987367 | LM5: 0.044827343 | LN5: 0.067881375 | LO5: 0.081344553 | LP5: 0.036198182 | LQ5: 0.095271617 | LR5: 0.045938756 | LS5: 0.12125267 | LT5: 0.11417497 | LU5: 0.033731954 | LV5: 0.068250604 | LW5: 0.056580859 | LX5: 0.051195404 | LY5: 0.031015448 | LZ5: 0.071819363 | MA5: 0.051251499 | MB5: 0.031759579 | MC5: 0.073171084 | MD5: 0.061466559 | ME5: 0.065006898 | MF5: 0.071566363 | MG5: 0.069492427 | MH5: 0.034754096 | MI5: 0.10767587 | MJ5: 0.062641859 | MK5: 0.058824254 | ML5: 0.076917639 | MM5: 0.018400168 | MN5: 0.079089813 | MO5: 0.067848027 | MP5: 0.080671471 | MQ5: 0.037503549 | MR5: 0.06502042 | MS5: 0.11233272 | MT5: 0.069367202 | MU5: 0.053101628 | MV5: 0.048722644 | MW5: 0.053366374 | MX5: 0.078923161 | MY5: 0.073599904 | MZ5: 0.072869495 | NA5: 0.086707604 | NB5: 0.013200245 | NC5: 0.049354729 | ND5: 0.04830454 | NE5: 0.049956131 | NF5: 0.080293475 | NG5: 0.10884865 | NH5: 0.07976341 | NI5: 0.047298441 | NJ5: 0.047689386 | NK5: 0.072792773 | NL5: 0.067714752 | NM5: 0.056219021 | NN5: 0.05412546 | NO5: 0.029666821 | NP5: 0.077695577 | NQ5: 0.073930371 | NR5: 0.11097429 | NS5: 0.045371274 | NT5: 0.061652004 | NU5: 0.052342857 | NV5: 0.06263802 | NW5: 0.019782429 | NX5: 0.038048741 | NY5: 0.060744974 | NZ5: 0.042499433 | OA5: 0.076375312 | OB5: 0.063135425 | OC5: 0.054890677 | OD5: 0.031704917 | OE5: 0.091013275 | OF5: 0.036975947 | OG5: 0.079960115 | OH5: 0.076077877 | OI5: 0.089278745 | OJ5: 0.042936675 | OK5: 0.075725436 | OL5: 0.10689237 | OM5: 0.053101628 | ON5: 0.040191176 | OO5: 0.063112277 | OP5: 0.035936616 | OQ5: 0.076721336 | OR5: 0.04447347 | OS5: 0.06049885 | OT5: 0.06291179 | OU5: 0.051281695 | OV5: 0.043088114 | OW5: 0.058277171 | OX5: 0.074505215 | OY5: 0.030632639 | OZ5: 0.052353428 | PA5: 0.061619172 | PB5: 0.091887817 | PC5: 0.0708526 | PD5: 0.088648064 | PE5: 0.058630385 | PF5: 0.059836712 | PG5: 0.10262767 | PH5: 0.076835015 | PI5: 0.061327381 | PJ5: 0.030945602 | PK5: 0.07235894 | PL5: 0.07058453 | PM5: 0.078244951 | PN5: 0.052526584 | PO5: 0.030431637 | PP5: 0.049276202 | PQ5: -0.0037022556 | PR5: 0.050961656 | PS5: 0.065238898 | PT5: 0.059086278 | PU5: 0.066073761 | PV5: 0.081898569 | PW5: 0.093597021 | PX5: 0.048795298 | PY5: -0.0014919216 | PZ5: 0.038734141 | QA5: -8.83457e-05 | QB5: 0.034775984 | QC5: 0.062786479 | QD5: 0.076084467 | QE5: 0.043475393 | QF5: 0.080068466 | QG5: 0.10079974 | QH5: 0.053393419 | QI5: 0.083436738 | QJ5: 0.033435837 | QK5: 0.064195957 | QL5: 0.072757563 | QM5: 0.052617201 | QN5: 0.053468222 | QO5: 0.06683385 | QP5: 0.045100369 | QQ5: 0.075258628 | QR5: 0.043506792 | QS5: 0.063212548 | QT5: 0.10995599 | QU5: 0.043286309 | QV5: 0.043780334 | QW5: 0.055318952 | QX5: 0.073294189 | QY5: 0.047095606 | QZ5: 0.067019009 | RA5: 0.063094944 | RB5: 0.034932007 | RC5: 0.065728625 | RD5: 0.10429906 | RE5: 0.072767906 | RF5: 0.082655993 | RG5: 0.039852774 | RH5: 0.073185667 | RI5: 0.067846079 | RJ5: 0.042094278 | RK5: 0.053896783 | RL5: 0.075710195 | RM5: 0.020431159 | RN5: 0.03698586 | RO5: 0.03260255 | RP5: 0.066499114 | RQ5: 0.047870735 | RR5: 0.057907225 | RS5: 0.050837863 | RT5: 0.057371917 | RU5: 0.10424084 | RV5: 0.085675836 | RW5: 0.052873524 | RX5: 0.037668338 | RY5: 0.078042689 | RZ5: 0.09494072 | SA5: 0.065829413 | SB5: 0.045137784 | SC5: 0.053721136 | SD5: 0.069904974 | SE5: 0.098729103 | SF5: 0.072165616 | SG5: 0.054012239
