Workbook
Name collateData: #REF!
Name exportToCSV: #REF!

Sheet StudentData
A1: Mason
A2: Stephens
A3: 80679969
A4: 45776.001

Sheet Data
A1: Global Company Key | B1: Data Date | C1: Fiscal Year | D1: Fiscal Quarter | E1: Industry Format | F1: Level of Consolidation - Company Interim Descriptor | G1: Population Source | H1: Data Format | I1: Ticker Symbol | J1: ISO Currency Code | K1: Calendar Data Year and Quarter | L1: Fiscal Data Year and Quarter | M1: Sales/Turnover (Net) | N1: Active/Inactive Status Marker
A2: 004194 | B2: 42094 | C2: 2015 | D2: 1 | E2: INDL | F2: C | G2: D | H2: STD | I2: KODK | J2: USD | K2: 2015Q1 | L2: 2015Q1 | M2: 411 | N2: A
A3: 004194 | B3: 42185 | C3: 2015 | D3: 2 | E3: INDL | F3: C | G3: D | H3: STD | I3: KODK | J3: USD | K3: 2015Q2 | L3: 2015Q2 | M3: 434 | N3: A
A4: 004194 | B4: 42277 | C4: 2015 | D4: 3 | E4: INDL | F4: C | G4: D | H4: STD | I4: KODK | J4: USD | K4: 2015Q3 | L4: 2015Q3 | M4: 425 | N4: A
A5: 004194 | B5: 42369 | C5: 2015 | D5: 4 | E5: INDL | F5: C | G5: D | H5: STD | I5: KODK | J5: USD | K5: 2015Q4 | L5: 2015Q4 | M5: 439 | N5: A
A6: 004194 | B6: 42460 | C6: 2016 | D6: 1 | E6: INDL | F6: C | G6: D | H6: STD | I6: KODK | J6: USD | K6: 2016Q1 | L6: 2016Q1 | M6: 377 | N6: A
A7: 004194 | B7: 42551 | C7: 2016 | D7: 2 | E7: INDL | F7: C | G7: D | H7: STD | I7: KODK | J7: USD | K7: 2016Q2 | L7: 2016Q2 | M7: 423 | N7: A
A8: 004194 | B8: 42643 | C8: 2016 | D8: 3 | E8: INDL | F8: C | G8: D | H8: STD | I8: KODK | J8: USD | K8: 2016Q3 | L8: 2016Q3 | M8: 411 | N8: A
A9: 004194 | B9: 42735 | C9: 2016 | D9: 4 | E9: INDL | F9: C | G9: D | H9: STD | I9: KODK | J9: USD | K9: 2016Q4 | L9: 2016Q4 | M9: 432 | N9: A
A10: 004194 | B10: 42825 | C10: 2017 | D10: 1 | E10: INDL | F10: C | G10: D | H10: STD | I10: KODK | J10: USD | K10: 2017Q1 | L10: 2017Q1 | M10: 357 | N10: A
A11: 004194 | B11: 42916 | C11: 2017 | D11: 2 | E11: INDL | F11: C | G11: D | H11: STD | I11: KODK | J11: USD | K11: 2017Q2 | L11: 2017Q2 | M11: 381 | N11: A
A12: 004194 | B12: 43008 | C12: 2017 | D12: 3 | E12: INDL | F12: C | G12: D | H12: STD | I12: KODK | J12: USD | K12: 2017Q3 | L12: 2017Q3 | M12: 379 | N12: A
A13: 004194 | B13: 43100 | C13: 2017 | D13: 4 | E13: INDL | F13: C | G13: D | H13: STD | I13: KODK | J13: USD | K13: 2017Q4 | L13: 2017Q4 | M13: 269 | N13: A
... A41: 004194 | B41: 45657 | C41: 2024 | D41: 4 | E41: INDL | F41: C | G41: D | H41: STD | I41: KODK | J41: USD | K41: 2024Q4 | L41: 2024Q4 | M41: 266 | N41: A

Sheet Sales
A1: =Data!A1 -> Global Company Key | B1: =Data!B1 -> Data Date | C1: =Data!C1 -> Fiscal Year | D1: =Data!D1 -> Fiscal Quarter | E1: =Data!E1 -> Industry Format | F1: =Data!F1 -> Level of Consolidation - Company Interim Descriptor | G1: =Data!G1 -> Population Source | H1: =Data!H1 -> Data Format | ... N1: =Data!N1 -> Active/Inactive Status Marker
A2: =Data!A2 -> 004194 | B2: =Data!B2 -> 42094 | C2: =Data!C2 -> 2015 | D2: =Data!D2 -> 1 | E2: =Data!E2 -> INDL | F2: =Data!F2 -> C | G2: =Data!G2 -> D | H2: =Data!H2 -> STD | ... N2: =Data!N2 -> A
A3: =Data!A3 -> 004194 | B3: =Data!B3 -> 42185 | C3: =Data!C3 -> 2015 | D3: =Data!D3 -> 2 | E3: =Data!E3 -> INDL | F3: =Data!F3 -> C | G3: =Data!G3 -> D | H3: =Data!H3 -> STD | ... M3: =Data!M3 -> 434 | N3: A | O3: =IF(OR(D3=2,D3=3,D3=4),1,0) -> 1 | P3: =M2 -> 411 | R3: Seasonal
A4: =Data!A4 -> 004194 | B4: =Data!B4 -> 42277 | C4: =Data!C4 -> 2015 | D4: =Data!D4 -> 3 | E4: =Data!E4 -> INDL | F4: =Data!F4 -> C | G4: =Data!G4 -> D | H4: =Data!H4 -> STD | ... M4: =Data!M4 -> 425 | N4: A | O4: =IF(OR(D4=2,D4=3,D4=4),1,0) -> 1 | P4: =M3 -> 434 | Q4: 1 | R4: {=AVERAGEIF(D2:D41,Q4:Q7,M2:M41)} -> 310.3
A5: =Data!A5 -> 004194 | B5: =Data!B5 -> 42369 | C5: =Data!C5 -> 2015 | D5: =Data!D5 -> 4 | E5: =Data!E5 -> INDL | F5: =Data!F5 -> C | G5: =Data!G5 -> D | H5: =Data!H5 -> STD | ... M5: =Data!M5 -> 439 | N5: A | O5: =IF(OR(D5=2,D5=3,D5=4),1,0) -> 1 | P5: =M4 -> 425 | Q5: 2 | R5: 326.4
A6: =Data!A6 -> 004194 | B6: =Data!B6 -> 42460 | C6: =Data!C6 -> 2016 | D6: =Data!D6 -> 1 | E6: =Data!E6 -> INDL | F6: =Data!F6 -> C | G6: =Data!G6 -> D | H6: =Data!H6 -> STD | ... M6: =Data!M6 -> 377 | N6: A | O6: =IF(OR(D6=2,D6=3,D6=4),1,0) -> 0 | P6: =M5 -> 439 | Q6: 3 | R6: 321.7
A7: =Data!A7 -> 004194 | B7: =Data!B7 -> 42551 | C7: =Data!C7 -> 2016 | D7: =Data!D7 -> 2 | E7: =Data!E7 -> INDL | F7: =Data!F7 -> C | G7: =Data!G7 -> D | H7: =Data!H7 -> STD | ... M7: =Data!M7 -> 423 | N7: A | O7: =IF(OR(D7=2,D7=3,D7=4),1,0) -> 1 | P7: =M6 -> 377 | Q7: 4 | R7: 326
A8: =Data!A8 -> 004194 | B8: =Data!B8 -> 42643 | C8: =Data!C8 -> 2016 | D8: =Data!D8 -> 3 | E8: =Data!E8 -> INDL | F8: =Data!F8 -> C | G8: =Data!G8 -> D | H8: =Data!H8 -> STD | ... M8: =Data!M8 -> 411 | N8: A | O8: =IF(OR(D8=2,D8=3,D8=4),1,0) -> 1 | P8: =M7 -> 423
A9: =Data!A9 -> 004194 | B9: =Data!B9 -> 42735 | C9: =Data!C9 -> 2016 | D9: =Data!D9 -> 4 | E9: =Data!E9 -> INDL | F9: =Data!F9 -> C | G9: =Data!G9 -> D | H9: =Data!H9 -> STD | ... M9: =Data!M9 -> 432 | N9: A | O9: =IF(OR(D9=2,D9=3,D9=4),1,0) -> 1 | P9: =M8 -> 411
A10: =Data!A10 -> 004194 | B10: =Data!B10 -> 42825 | C10: =Data!C10 -> 2017 | D10: =Data!D10 -> 1 | E10: =Data!E10 -> INDL | F10: =Data!F10 -> C | G10: =Data!G10 -> D | H10: =Data!H10 -> STD | ... M10: =Data!M10 -> 357 | N10: A | O10: =IF(OR(D10=2,D10=3,D10=4),1,0) -> 0 | P10: =M9 -> 432 | R10: Linest
A11: =Data!A11 -> 004194 | B11: =Data!B11 -> 42916 | C11: =Data!C11 -> 2017 | D11: =Data!D11 -> 2 | E11: =Data!E11 -> INDL | F11: =Data!F11 -> C | G11: =Data!G11 -> D | H11: =Data!H11 -> STD | ... M11: =Data!M11 -> 381 | N11: A | O11: =IF(OR(D11=2,D11=3,D11=4),1,0) -> 1 | P11: =M10 -> 357 | R11: {=LINEST(M3:M41,O3:P41,1,1)} -> 0.83028612 | S11: 36.548666 | T11: 22.902594
A12: =Data!A12 -> 004194 | B12: =Data!B12 -> 43008 | C12: =Data!C12 -> 2017 | D12: =Data!D12 -> 3 | E12: =Data!E12 -> INDL | F12: =Data!F12 -> C | G12: =Data!G12 -> D | H12: =Data!H12 -> STD | ... M12: =Data!M12 -> 379 | N12: A | O12: =IF(OR(D12=2,D12=3,D12=4),1,0) -> 1 | P12: =M11 -> 381 | R12: 0.083140424 | S12: 11.773285 | T12: 29.507023
A13: =Data!A13 -> 004194 | B13: =Data!B13 -> 43100 | C13: =Data!C13 -> 2017 | D13: =Data!D13 -> 4 | E13: =Data!E13 -> INDL | F13: =Data!F13 -> C | G13: =Data!G13 -> D | H13: =Data!H13 -> STD | ... M13: =Data!M13 -> 269 | N13: A | O13: =IF(OR(D13=2,D13=3,D13=4),1,0) -> 1 | P13: =M12 -> 379 | R13: 0.74376602 | S13: 30.842685 | T13: #N/A
A14: =Data!A14 -> 004194 | B14: =Data!B14 -> 43190 | C14: =Data!C14 -> 2018 | D14: =Data!D14 -> 1 | E14: =Data!E14 -> INDL | F14: =Data!F14 -> C | G14: =Data!G14 -> D | H14: =Data!H14 -> STD | ... M14: =Data!M14 -> 318 | N14: A | O14: =IF(OR(D14=2,D14=3,D14=4),1,0) -> 0 | P14: =M13 -> 269 | R14: 52.248295 | S14: 36 | T14: #N/A
A15: =Data!A15 -> 004194 | B15: =Data!B15 -> 43281 | C15: =Data!C15 -> 2018 | D15: =Data!D15 -> 2 | E15: =Data!E15 -> INDL | F15: =Data!F15 -> C | G15: =Data!G15 -> D | H15: =Data!H15 -> STD | ... M15: =Data!M15 -> 332 | N15: A | O15: =IF(OR(D15=2,D15=3,D15=4),1,0) -> 1 | P15: =M14 -> 318 | R15: 99404.596 | S15: 34245.763 | T15: #N/A
A16: =Data!A16 -> 004194 | B16: =Data!B16 -> 43373 | C16: =Data!C16 -> 2018 | D16: =Data!D16 -> 3 | E16: =Data!E16 -> INDL | F16: =Data!F16 -> C | G16: =Data!G16 -> D | H16: =Data!H16 -> STD | ... M16: =Data!M16 -> 329 | N16: A | O16: =IF(OR(D16=2,D16=3,D16=4),1,0) -> 1 | P16: =M15 -> 332
A17: =Data!A17 -> 004194 | B17: =Data!B17 -> 43465 | C17: =Data!C17 -> 2018 | D17: =Data!D17 -> 4 | E17: =Data!E17 -> INDL | F17: =Data!F17 -> C | G17: =Data!G17 -> D | H17: =Data!H17 -> STD | ... M17: =Data!M17 -> 341 | N17: A | O17: =IF(OR(D17=2,D17=3,D17=4),1,0) -> 1 | P17: =M16 -> 329
A18: =Data!A18 -> 004194 | B18: =Data!B18 -> 43555 | C18: =Data!C18 -> 2019 | D18: =Data!D18 -> 1 | E18: =Data!E18 -> INDL | F18: =Data!F18 -> C | G18: =Data!G18 -> D | H18: =Data!H18 -> STD | ... M18: =Data!M18 -> 291 | N18: A | O18: =IF(OR(D18=2,D18=3,D18=4),1,0) -> 0 | P18: =M17 -> 341
A19: =Data!A19 -> 004194 | B19: =Data!B19 -> 43646 | C19: =Data!C19 -> 2019 | D19: =Data!D19 -> 2 | E19: =Data!E19 -> INDL | F19: =Data!F19 -> C | G19: =Data!G19 -> D | H19: =Data!H19 -> STD | ... M19: =Data!M19 -> 307 | N19: A | O19: =IF(OR(D19=2,D19=3,D19=4),1,0) -> 1 | P19: =M18 -> 291 | R19: Forcast Sales | S19: Quarter | T19: Dummy
A20: =Data!A20 -> 004194 | B20: =Data!B20 -> 43738 | C20: =Data!C20 -> 2019 | D20: =Data!D20 -> 3 | E20: =Data!E20 -> INDL | F20: =Data!F20 -> C | G20: =Data!G20 -> D | H20: =Data!H20 -> STD | ... M20: =Data!M20 -> 315 | N20: A | O20: =IF(OR(D20=2,D20=3,D20=4),1,0) -> 1 | P20: =M19 -> 307 | R20: =$T$11+$S$11*T20+$R$11*M41 -> 243.7587 | S20: 1 | T20: 0
A21: =Data!A21 -> 004194 | B21: =Data!B21 -> 43830 | C21: =Data!C21 -> 2019 | D21: =Data!D21 -> 4 | E21: =Data!E21 -> INDL | F21: =Data!F21 -> C | G21: =Data!G21 -> D | H21: =Data!H21 -> STD | ... M21: =Data!M21 -> 329 | N21: A | O21: =IF(OR(D21=2,D21=3,D21=4),1,0) -> 1 | P21: =M20 -> 315 | R21: =$T$11+$S$11*T21+$R$11*R20 -> 261.84073 | S21: 2 | T21: 1
A22: =Data!A22 -> 004194 | B22: =Data!B22 -> 43921 | C22: =Data!C22 -> 2020 | D22: =Data!D22 -> 1 | E22: =Data!E22 -> INDL | F22: =Data!F22 -> C | G22: =Data!G22 -> D | H22: =Data!H22 -> STD | ... M22: =Data!M22 -> 267 | N22: A | O22: =IF(OR(D22=2,D22=3,D22=4),1,0) -> 0 | P22: =M21 -> 329 | R22: =$T$11+$S$11*T22+$R$11*R21 -> 276.85398 | S22: 3 | T22: 1
A23: =Data!A23 -> 004194 | B23: =Data!B23 -> 44012 | C23: =Data!C23 -> 2020 | D23: =Data!D23 -> 2 | E23: =Data!E23 -> INDL | F23: =Data!F23 -> C | G23: =Data!G23 -> D | H23: =Data!H23 -> STD | ... M23: =Data!M23 -> 213 | N23: A | O23: =IF(OR(D23=2,D23=3,D23=4),1,0) -> 1 | P23: =M22 -> 267 | R23: =$T$11+$S$11*T23+$R$11*R22 -> 289.31928 | S23: 4 | T23: 1
A24: =Data!A24 -> 004194 | B24: =Data!B24 -> 44104 | C24: =Data!C24 -> 2020 | D24: =Data!D24 -> 3 | E24: =Data!E24 -> INDL | F24: =Data!F24 -> C | G24: =Data!G24 -> D | H24: =Data!H24 -> STD | ... M24: =Data!M24 -> 252 | N24: A | O24: =IF(OR(D24=2,D24=3,D24=4),1,0) -> 1 | P24: =M23 -> 213
A25: =Data!A25 -> 004194 | B25: =Data!B25 -> 44196 | C25: =Data!C25 -> 2020 | D25: =Data!D25 -> 4 | E25: =Data!E25 -> INDL | F25: =Data!F25 -> C | G25: =Data!G25 -> D | H25: =Data!H25 -> STD | ... M25: =Data!M25 -> 297 | N25: A | O25: =IF(OR(D25=2,D25=3,D25=4),1,0) -> 1 | P25: =M24 -> 252
A26: =Data!A26 -> 004194 | B26: =Data!B26 -> 44286 | C26: =Data!C26 -> 2021 | D26: =Data!D26 -> 1 | E26: =Data!E26 -> INDL | F26: =Data!F26 -> C | G26: =Data!G26 -> D | H26: =Data!H26 -> STD | ... M26: =Data!M26 -> 265 | N26: A | O26: =IF(OR(D26=2,D26=3,D26=4),1,0) -> 0 | P26: =M25 -> 297
A27: =Data!A27 -> 004194 | B27: =Data!B27 -> 44377 | C27: =Data!C27 -> 2021 | D27: =Data!D27 -> 2 | E27: =Data!E27 -> INDL | F27: =Data!F27 -> C | G27: =Data!G27 -> D | H27: =Data!H27 -> STD | ... M27: =Data!M27 -> 291 | N27: A | O27: =IF(OR(D27=2,D27=3,D27=4),1,0) -> 1 | P27: =M26 -> 265
A28: =Data!A28 -> 004194 | B28: =Data!B28 -> 44469 | C28: =Data!C28 -> 2021 | D28: =Data!D28 -> 3 | E28: =Data!E28 -> INDL | F28: =Data!F28 -> C | G28: =Data!G28 -> D | H28: =Data!H28 -> STD | ... M28: =Data!M28 -> 287 | N28: A | O28: =IF(OR(D28=2,D28=3,D28=4),1,0) -> 1 | P28: =M27 -> 291
A29: =Data!A29 -> 004194 | B29: =Data!B29 -> 44561 | C29: =Data!C29 -> 2021 | D29: =Data!D29 -> 4 | E29: =Data!E29 -> INDL | F29: =Data!F29 -> C | G29: =Data!G29 -> D | H29: =Data!H29 -> STD | ... M29: =Data!M29 -> 307 | N29: A | O29: =IF(OR(D29=2,D29=3,D29=4),1,0) -> 1 | P29: =M28 -> 287
A30: =Data!A30 -> 004194 | B30: =Data!B30 -> 44651 | C30: =Data!C30 -> 2022 | D30: =Data!D30 -> 1 | E30: =Data!E30 -> INDL | F30: =Data!F30 -> C | G30: =Data!G30 -> D | H30: =Data!H30 -> STD | ... M30: =Data!M30 -> 290 | N30: A | O30: =IF(OR(D30=2,D30=3,D30=4),1,0) -> 0 | P30: =M29 -> 307
A31: =Data!A31 -> 004194 | B31: =Data!B31 -> 44742 | C31: =Data!C31 -> 2022 | D31: =Data!D31 -> 2 | E31: =Data!E31 -> INDL | F31: =Data!F31 -> C | G31: =Data!G31 -> D | H31: =Data!H31 -> STD | ... M31: =Data!M31 -> 321 | N31: A | O31: =IF(OR(D31=2,D31=3,D31=4),1,0) -> 1 | P31: =M30 -> 290
A32: =Data!A32 -> 004194 | B32: =Data!B32 -> 44834 | C32: =Data!C32 -> 2022 | D32: =Data!D32 -> 3 | E32: =Data!E32 -> INDL | F32: =Data!F32 -> C | G32: =Data!G32 -> D | H32: =Data!H32 -> STD | ... M32: =Data!M32 -> 289 | N32: A | O32: =IF(OR(D32=2,D32=3,D32=4),1,0) -> 1 | P32: =M31 -> 321
A33: =Data!A33 -> 004194 | B33: =Data!B33 -> 44926 | C33: =Data!C33 -> 2022 | D33: =Data!D33 -> 4 | E33: =Data!E33 -> INDL | F33: =Data!F33 -> C | G33: =Data!G33 -> D | H33: =Data!H33 -> STD | ... M33: =Data!M33 -> 305 | N33: A | O33: =IF(OR(D33=2,D33=3,D33=4),1,0) -> 1 | P33: =M32 -> 289
A34: =Data!A34 -> 004194 | B34: =Data!B34 -> 45016 | C34: =Data!C34 -> 2023 | D34: =Data!D34 -> 1 | E34: =Data!E34 -> INDL | F34: =Data!F34 -> C | G34: =Data!G34 -> D | H34: =Data!H34 -> STD | ... M34: =Data!M34 -> 278 | N34: A | O34: =IF(OR(D34=2,D34=3,D34=4),1,0) -> 0 | P34: =M33 -> 305
A35: =Data!A35 -> 004194 | B35: =Data!B35 -> 45107 | C35: =Data!C35 -> 2023 | D35: =Data!D35 -> 2 | E35: =Data!E35 -> INDL | F35: =Data!F35 -> C | G35: =Data!G35 -> D | H35: =Data!H35 -> STD | ... M35: =Data!M35 -> 295 | N35: A | O35: =IF(OR(D35=2,D35=3,D35=4),1,0) -> 1 | P35: =M34 -> 278
... A41: =Data!A41 -> 004194 | B41: =Data!B41 -> 45657 | C41: =Data!C41 -> 2024 | D41: =Data!D41 -> 4 | E41: =Data!E41 -> INDL | F41: =Data!F41 -> C | G41: =Data!G41 -> D | H41: =Data!H41 -> STD | ... M41: =Data!M41 -> 266 | N41: A | O41: =IF(OR(D41=2,D41=3,D41=4),1,0) -> 1 | P41: =M40 -> 261

Sheet Sheet1
C6: Parameter | D6: Value
C7: Slope (Dummy variable) | D7: 0.8303
C8: Intercept | D8: 36.5487
C9: Standard Error (Slope) | D9: 0.0831
C10: Standard Error (Intercept) | D10: 11.7733
C11: R-squared | D11: 0.7438
C12: Standard Error of Estimate | D12: 30.8427
C13: F-statistic | D13: 52.2483
C14: Degrees of Freedom | D14: 36
C15: SSR (Regression SS) | D15: 99404.6
C16: SSE (Residual SS) | D16: 34245.76

Sheet BalData
A1: Global Company Key | B1: 004194
A2: Data Date | B2: 45657
A3: Data Year - Fiscal | B3: 2024
A4: Industry Format | B4: INDL
A5: Level of Consolidation - Company Annual Descriptor | B5: C
A6: Population Source | B6: D
A7: Data Format | B7: STD
A8: Ticker Symbol | B8: KODK
A9: ISO Currency Code | B9: USD
A10: Acceptances Outstanding
A11: Current Assets of Discontinued Operations | B11: 0
A12: Current Assets - Other - Total | B12: 22
A13: Other Current Assets Excl Discontinued Operations | B13: 22
A14: Accumulated Other Comprehensive Income (Loss) | B14: -104
A15: Current Assets - Other - Sundry | B15: 22
A16: Current Assets - Other - Total As Reported
A17: Current Assets - Total | B17: 595
A18: Accrued Expenses and Deferred Income
A19: Long-term Assets of Discontinued Operations | B19: 0
A20: Assets - Other | B20: 1158
A21: Accum Other Comp Inc - Derivatives Unrealized Gain/Loss | B21: 0
A22: Accum Other Comp Inc - Other Adjustments | B22: 0
A23: Accum Other Comp Inc - Min Pension Liab Adj | B23: 32
A24: Accum Other Comp Inc - Unreal G/L Ret Int in Sec Assets | B24: 0
A25: Other Assets excluding Discontinued Operations | B25: 1158
A26: Assets - Other - Sundry | B26: 1158
A27: Accounts Payable - Trade | B27: 120
A28: Accounts Payable/Creditors - Brokers, Dealers, and Clearing Organizations
A29: Accounts Payable/Creditors - Customer
A30: Accounts Payable/Creditors - Other - FS
A31: Accounts Receivable/Debtors - Brokers, Dealers, and Clearing Organizations
A32: Accounts Receivable/Debtors - Customer
A33: Accounts Receivable/Debtors - Total
A34: Assets - Total | B34: 2001
A35: Average Short-Term Borrowings
A36: Book Value Per Share | B36: 7.9627
A37: Customers'' Acceptance
A38: Capital Surplus/Share Premium Reserve | B38: 1150
A39: Compensating Balance
A40: Common/Ordinary Equity - Total | B40: 641
...

Sheet IncomeData
A1: Global Company Key | B1: 004194
A2: Data Date | B2: 45657
A3: Data Year - Fiscal | B3: 2024
A4: Industry Format | B4: INDL
A5: Level of Consolidation - Company Annual Descriptor | B5: C
A6: Population Source | B6: D
A7: Data Format | B7: STD
A8: Ticker Symbol | B8: KODK
A9: ISO Currency Code | B9: USD
A10: Accounting Changes - Cumulative Effect | B10: 0
A11: Amortization of Deferred Policy Acquisition Costs
A12: Amortization of Intangibles | B12: 4
A13: Amortization of Deferred Charges
A14: Amortization of Goodwill
A15: Acquisition/Merger After-tax
A16: Acquisition/Merger Diluted EPS Effect
A17: Acquisition/Merger Basic EPS Effect
A18: Acquisitions - Income Contribution
A19: Acquisition/Merger Pretax
A20: Acquisitions - Sales Contribution
A21: As Reported Core - After-tax
A22: As Reported Core - Diluted EPS Effect
A23: As Reported Core - Basic EPS Effect
A24: Appropriations to Untaxed Reserves
... A46: Capital Gains - Unrealized (Insurance)
A47: Comp Inc - Beginning Net Income | B47: 102
A48: Comp Inc - Currency Trans Adj | B48: -16
A49: Comp Inc - Derivative Gains/Losses | B49: 0
A50: Comp Inc - Other Adj | B50: 0
A51: Comp Inc - Minimum Pension Adj | B51: -369
A52: Comp Inc - Securities Gains/Losses | B52: 0
A53: Comprehensive Income - Parent | B53: -283
A54: Claims - Non-Life - Total (Business Line)
A55: Cost of Goods Sold | B55: 812
A56: Commercial Property and Casualty Claims (Business Line)
A57: Claims Paid - Other
A58: Claims Paid - Non-Life
A59: Commercial Property and Casualty Premiums (Business Line)
A60: Claims Paid - Reinsurance
A61: Common Stock Equivalents - Dollar Savings | B61: 0
...

Sheet CshFlwData
A1: Global Company Key | B1: 004194
A2: Data Date | B2: 45657
A3: Data Year - Fiscal | B3: 2024
A4: Industry Format | B4: INDL
A5: Level of Consolidation - Company Annual Descriptor | B5: C
A6: Population Source | B6: D
A7: Data Format | B7: STD
A8: Ticker Symbol | B8: KODK
A9: ISO Currency Code | B9: USD
A10: Allowance for Funds Used During Construction (Cash Flow)
A11: Allowance for Funds Used During Construction (Investing) (Cash Flow)
A12: Amortization (Cash Flow) - Utility
A13: Assets and Liabilities - Other - Net Change | B13: -46
A14: Accounts Payable and Accrued Liabilities - Increase/(Decrease) | B14: -3
A15: Acquisitions | B15: 0
A16: Capital Expenditures | B16: 56
A17: Capital Expend Property, Plant and Equipment Schd V | B17: 56
A18: Cash Dividends on Common Stock (Cash Flow)
A19: Cash and Cash Equivalents - Increase/(Decrease) | B19: -76
A20: Depreciation and Depletion (Cash Flow)
A21: Current Debt - Changes | B21: 0
A22: Long-Term Debt - Issuance | B22: 0
A23: Long-Term Debt - Reduction | B23: 18
A24: Depreciation and Amortization (Cash Flow) | B24: 28
A25: Cash Dividends (Cash Flow) | B25: 4
A26: Equity in Net Loss - Earnings | B26: 0
A27: Exchange Rate Effect | B27: -7
A28: Financing Activities - Other | B28: 0
A29: Financing Activities - Net Cash Flow | B29: -23
A30: Funds from Operations - Other | B30: -115
A31: Funds from Operations - Other excluding Option Tax Benefit | B31: -115
A32: Funds From Operations - Total
A33: Sources of Funds - Other
A34: Sources of Funds - Total
A35: Uses of Funds - Other
A36: Uses of Funds - Total
A37: Income Before Extraordinary Items (Cash Flow) | B37: 102
A38: Interest Paid - Net | B38: 31
A39: Inventory - Decrease (Increase) | B39: -7
A40: Investment Tax Credit - Net (Cash Flow) - Utility
...

Sheet Index
A1: Bal | B1: Income | C1: Cash Flows
A2: 44 | B2: 240 | C2: 37
A3: 289 | B3: 55 | C3: 24
A4: 169 | B4: 68 | C4: 62
A5: 13 | B5: 327 | C5: 30
A6: 17
B7: 83
C8: 45
A9: 124 | B9: 306
A10: 126 | B10: 192
B11: 260 | C11: 16
A12: 253 | C12: 15
A13: 95 | B13: 161 | C13: 41
A15: 198 | C15: 43
A17: 160
C18: 21
A19: 34 | C19: 22
C20: 23
C21: 56
A22: 27 | C22: 47
A23: 73 | C23: 25
A24: 355
C25: 29
A26: 217
A27: 84 | C27: 27
A28: 346 | C28: 19
C29: 63
A30: 229 | C30: 38
A33: 14
A34: 294
A35: 342
A36: 40
A37: 34

Sheet BalSheet
B1: Sales | C1: =SUM(Sales!M38:M41) -> 1043 | E1: Forecast Sales | F1: =SUM(Sales!R20:R23) -> 1071.7727
A3: ASSETS | C3: Common
A4: Cash & Short Term Investments | B4: {=INDEX(BalData!$B$1:$B$392,Index!A2)} -> 209 | C4: =B4/$C$1 -> 0.20038351 | F4: =$F$1*C4 -> 214.76557
A5: Receivables - Net | B5: {=INDEX(BalData!$B$1:$B$392,Index!A3)} -> 145 | C5: =B5/$C$1 -> 0.13902205 | F5: =$F$1*C5 -> 149.00004
A6: Inventories - Total | B6: {=INDEX(BalData!$B$1:$B$392,Index!A4)} -> 219 | C6: =B6/$C$1 -> 0.20997124 | F6: =$F$1*C6 -> 225.04144
A7: Other Current Assets | B7: {=INDEX(BalData!$B$1:$B$392,Index!A5)} -> 22 | C7: =B7/$C$1 -> 0.021093001 | F7: =$F$1*C7 -> 22.606902
A8: CURRENT ASSETS - TOTAL | B8: {=INDEX(BalData!$B$1:$B$392,Index!A6)} -> 595 | C8: =B8/$C$1 -> 0.5704698 | F8: =$F$1*C8 -> 611.41395
A10: Long Term Assets
A11: Buildings | B11: {=INDEX(BalData!$B$1:$B$392,Index!A9)} -> 137 | C11: =B11/$C$1 -> 0.13135187 | F11: =$F$1*C11 -> 140.77935
A12: Machinery & Equipment | B12: {=INDEX(BalData!$B$1:$B$392,Index!A10)} -> 434 | C12: =B12/$C$1 -> 0.41610738 | F12: =$F$1*C12 -> 445.97253
A13: Land and other | B13: =B14-SUM(B11:B12) -> 127 | C13: =B13/$C$1 -> 0.12176414 | F13: =$F$1*C13 -> 130.50348
A14: Property, Plant and Equipment - Gross | B14: {=INDEX(BalData!$B$1:$B$392,Index!A12)} -> 698 | C14: =B14/$C$1 -> 0.66922339 | F14: =$F$1*C14 -> 717.25536
A15: Accumulated Depreciation | B15: {=INDEX(BalData!$B$1:$B$392,Index!A13)} -> 482 | C15: =B15/$C$1 -> 0.46212848 | F15: =$F$1*C15 -> 495.29668
A16: Property, Plant and Equipment - Net | B16: =B14-B15 -> 216 | C16: =B16/$C$1 -> 0.20709492 | F16: =$F$1*C16 -> 221.95868
A17: Investments in Associated Companies | B17: {=INDEX(BalData!$B$1:$B$392,Index!A15)} -> 0 | C17: =B17/$C$1 -> 0 | F17: =$F$1*C17 -> 0 | I17: =SUM(B11:B17) -> 2094 | O17: 9234
O18: 11247
A19: Total Intangible Other Assets - Net | B19: {=INDEX(BalData!$B$1:$B$392,Index!A17)} -> 32 | C19: =B19/$C$1 -> 0.030680729 | F19: =$F$1*C19 -> 32.882767 | O19: =SUM(O17:O18) -> 20481
A20: Other Assets - Total | B20: =B21-SUM(B16:B19) -> 1753 | C20: =B20/$C$1 -> 1.6807287 | F20: =$F$1*C20 -> 1801.3591
A21: TOTAL ASSETS | B21: {=INDEX(BalData!$B$1:$B$392,Index!A19)} -> 2001 | C21: =B21/$C$1 -> 1.9185043 | F21: =$F$1*C21 -> 2056.2005
A23: LIABILITIES
A24: Accounts Payable | B24: {=INDEX(BalData!$B$1:$B$392,Index!A22)} -> 120 | C24: =B24/$C$1 -> 0.11505273 | F24: =$F$1*C24 -> 123.31038
A25: Short Term Debt & Current Portion of Long Term Debt | B25: {=INDEX(BalData!$B$1:$B$392,Index!A23)} -> 12 | C25: =B25/$C$1 -> 0.011505273 | F25: =$F$1*C25 -> 12.331038
A26: Income Taxes Payable | B26: {=INDEX(BalData!$B$1:$B$392,Index!A24)} -> 0 | C26: =B26/$C$1 -> 0 | F26: =$F$1*C26 -> 0
A27: Other Current Liabilities | B27: =B28-SUM(B24:B26) -> 129 | C27: =B27/$C$1 -> 0.12368169 | F27: =$F$1*C27 -> 132.55866
A28: CURRENT LIABILITIES - TOTAL | B28: {=INDEX(BalData!$B$1:$B$392,Index!A26)} -> 261 | C28: =B28/$C$1 -> 0.25023969 | F28: =$F$1*C28 -> 268.20007
A29: Long Term Debt | B29: {=INDEX(BalData!$B$1:$B$392,Index!A27)} -> 487 | C29: =B29/$C$1 -> 0.46692234 | F29: =$F$1*C29 -> 500.43461
A30: DEFERRED TAXES | B30: {=INDEX(BalData!$B$1:$B$392,Index!A28)} -> 24 | C30: =B30/$C$1 -> 0.023010547 | F30: =$F$1*C30 -> 24.662075
A31: Other Liabilities | B31: =B32-SUM(B24:B30) -> 109 | C31: =B31/$C$1 -> 0.10450623 | F31: =$F$1*C31 -> 112.00693
A32: TOTAL LIABILITIES | B32: {=INDEX(BalData!$B$1:$B$392,Index!A30)} -> 1142 | C32: =B32/$C$1 -> 1.0949185 | F32: =$F$1*C32 -> 1173.5038
A33: EQUITY
A34: Capital Surplus | B34: =B39-SUM(B35:B38) -> 1869 | C34: =B34/$C$1 -> 1.7919463 | F34: =$F$1*C34 -> 1920.5591
A35: Other Appropriated Reserves | B35: {=INDEX(BalData!$B$1:$B$392,Index!A33)} -> -104 | C35: =B35/$C$1 -> -0.099712368 | F35: =$F$1*C35 -> -106.86899
A36: Retained Earnings | B36: {=INDEX(BalData!$B$1:$B$392,Index!A34)} -> -393 | C36: =B36/$C$1 -> -0.3767977 | F36: =$F$1*C36 -> -403.84149
A37: Treasury Stock | B37: {=-INDEX(BalData!$B$1:$B$392,Index!A35)} -> -12 | C37: =B37/$C$1 -> -0.011505273 | F37: =$F$1*C37 -> -12.331038
A38: COMMON EQUITY | B38: {=INDEX(BalData!$B$1:$B$392,Index!A36)} -> 641 | C38: =B38/$C$1 -> 0.61457335 | F38: =$F$1*C38 -> 658.68293
A39: TOTAL LIABILITIES & SHAREHOLDERS’ EQUITY | B39: {=INDEX(BalData!$B$1:$B$392,Index!A37)} -> 2001 | C39: =B39/$C$1 -> 1.9185043 | F39: =$F$1*C39 -> 2056.2005

Sheet IncomeStat
D1: Sales Forecast | E1: =Sales!R20 -> 243.7587
C2: Common
A3: NET SALES OR REVENUES | B3: {=INDEX(IncomeData!$B$1:$B$338,Index!B2)} -> 1043 | C3: =B3/$B$3 -> 1 | E3: =$E$1*C3 -> 243.7587
A4: Cost of Goods Sold (Excl Depreciation) | B4: {=INDEX(IncomeData!$B$1:$B$338,Index!B3)} -> 812 | C4: =B4/$B$3 -> 0.77852349 | E4: =$E$1*C4 -> 189.77188
A5: Depreciation, Depletion And Amortization | B5: {=INDEX(IncomeData!$B$1:$B$338,Index!B4)} -> 28 | C5: =B5/$B$3 -> 0.026845638 | E5: =$E$1*C5 -> 6.5438578
A6: Other Dep and Amort | B6: =B3-SUM(B4:B5,B7:B8) -> 0 | C6: =B6/$B$3 -> 0 | E6: =$E$1*C6 -> 0
A7: Selling, General & Admin Expenses | B7: {=INDEX(IncomeData!$B$1:$B$338,Index!B5)} -> 212 | C7: =B7/$B$3 -> 0.20325983 | E7: =$E$1*C7 -> 49.546352
A8: OPERATING INCOME | B8: {=INDEX(IncomeData!$B$1:$B$338,Index!B7)} -> -9 | C8: =B8/$B$3 -> -0.0086289549 | E8: =$E$1*C8 -> -2.1033829
A9: Other Income/Expenses - Net | B9: =B11-(B8-B10) -> 178 | C9: =B9/$B$3 -> 0.17066155 | E9: =$E$1*C9 -> 41.600239
A10: Interest Expense On Debt | B10: {=INDEX(IncomeData!$B$1:$B$338,Index!B9)} -> 59 | C10: =B10/$B$3 -> 0.056567593 | E10: =$E$1*C10 -> 13.788843
A11: PRETAX INCOME | B11: {=INDEX(IncomeData!$B$1:$B$338,Index!B10)} -> 110 | C11: =B11/$B$3 -> 0.105465 | E11: =$E$1*C11 -> 25.708013
A12: Income Taxes | B12: {=INDEX(IncomeData!$B$1:$B$338,Index!B11)} -> 9 | C12: =B12/$B$3 -> 0.0086289549 | E12: =$E$1*C12 -> 2.1033829
A13: Other Taxes and Extra Items | B13: =B14-(B11-B12) -> 1 | C13: =B13/$B$3 -> 0.00095877277 | E13: =$E$1*C13 -> 0.23370921
A14: Net Income | B14: {=INDEX(IncomeData!$B$1:$B$338,Index!B13)} -> 102 | C14: =B14/$B$3 -> 0.097794823 | E14: =$E$1*C14 -> 23.838339

Sheet CshFlow
B1: Sales | C1: =BalSheet!C1 -> 1043 | D1: Sales Forecast | E1: =IncomeStat!E1 -> 243.7587
A3: Operations | C3: Common
A4: Net Income / Starting Line | B4: {=INDEX(CshFlwData!$B$1:$B$76,Index!C2)} -> 102 | C4: =B4/$C$1 -> 0.097794823 | E4: =C4*$E$1 -> 23.838339
A5: Depreciation and Depletion | B5: {=INDEX(CshFlwData!$B$1:$B$76,Index!C3)} -> 28 | C5: =B5/$C$1 -> 0.026845638 | E5: =C5*$E$1 -> 6.5438578
A6: Deferred Income Taxes | B6: {=INDEX(CshFlwData!$B$1:$B$76,Index!C4)} -> -1 | C6: =B6/$C$1 -> -0.00095877277 | E6: =C6*$E$1 -> -0.23370921
A7: Total Other Cash Flow | B7: {=INDEX(CshFlwData!$B$1:$B$76,Index!C5)} -> -115 | C7: =B7/$C$1 -> -0.11025887 | E7: =C7*$E$1 -> -26.876559
A8: Funds From Operations | B8: =SUM(B4:B7) -> 14 | C8: =B8/$C$1 -> 0.013422819 | E8: =C8*$E$1 -> 3.2719289
A9: Change in WC | B9: =B10-B8 -> -21 | C9: =B9/$C$1 -> -0.020134228 | E9: =C9*$E$1 -> -4.9078933
A10: NET CASH FLOW - OPERATING ACTIVITIES | B10: {=INDEX(CshFlwData!$B$1:$B$76,Index!C8)} -> -7 | C10: =B10/$C$1 -> -0.0067114094 | E10: =C10*$E$1 -> -1.6359644
A12: Investing
A13: Capital Expenditures | B13: {=INDEX(CshFlwData!$B$1:$B$76,Index!C11)} -> 56 | C13: =B13/$C$1 -> 0.053691275 | E13: =C13*$E$1 -> 13.087716
A14: Acquisitions | B14: {=INDEX(CshFlwData!$B$1:$B$76,Index!C12)} -> 0 | C14: =B14/$C$1 -> 0 | E14: =C14*$E$1 -> 0
A15: Disposal Of Fixed Assets | B15: {=INDEX(CshFlwData!$B$1:$B$76,Index!C13)} -> 0 | C15: =B15/$C$1 -> 0 | E15: =C15*$E$1 -> 0
A16: Other Investing | B16: =B17-SUM(B13:B15) -> -95 | C16: =B16/$C$1 -> -0.091083413 | E16: =C16*$E$1 -> -22.202375
A17: Net Investing Cash Flow | B17: {=INDEX(CshFlwData!$B$1:$B$76,Index!C15)} -> -39 | C17: =B17/$C$1 -> -0.037392138 | E17: =C17*$E$1 -> -9.1146591
A19: Financing
A20: Change in Current Debt | B20: {=INDEX(CshFlwData!$B$1:$B$76,Index!C18)} -> 0 | C20: =B20/$C$1 -> 0 | E20: =C20*$E$1 -> 0
A21: Long-Term Debt Issuance | B21: {=INDEX(CshFlwData!$B$1:$B$76,Index!C19)} -> 0 | C21: =B21/$C$1 -> 0 | E21: =C21*$E$1 -> 0
A22: Long-Term Debt Reduction | B22: {=-INDEX(CshFlwData!$B$1:$B$76,Index!C20)} -> -18 | C22: =B22/$C$1 -> -0.01725791 | E22: =C22*$E$1 -> -4.2067657
A23: Sale of Common Stock | B23: {=INDEX(CshFlwData!$B$1:$B$76,Index!C21)} -> 0 | C23: =B23/$C$1 -> 0 | E23: =C23*$E$1 -> 0
A24: Purchase of Common/Perferred Stock | B24: {=-INDEX(CshFlwData!$B$1:$B$76,Index!C22)} -> -1 | C24: =B24/$C$1 -> -0.00095877277 | E24: =C24*$E$1 -> -0.23370921
A25: Dividends paid | B25: {=-INDEX(CshFlwData!$B$1:$B$76,Index!C23)} -> -4 | C25: =B25/$C$1 -> -0.0038350911 | E25: =C25*$E$1 -> -0.93483683
A26: Other Financing Activities | B26: =B27-SUM(B20:B25) -> 0 | C26: =B26/$C$1 -> 0 | E26: =C26*$E$1 -> 0
A27: Net Financing Cash Flow | B27: {=INDEX(CshFlwData!$B$1:$B$76,Index!C25)} -> -23 | C27: =B27/$C$1 -> -0.022051774 | E27: =C27*$E$1 -> -5.3753118
A29: Exchange Rate Effect | B29: {=INDEX(CshFlwData!$B$1:$B$76,Index!C27)} -> -7 | C29: =B29/$C$1 -> -0.0067114094 | E29: =C29*$E$1 -> -1.6359644
A30: Change in Cash and Short Term Invest | B30: {=INDEX(CshFlwData!$B$1:$B$76,Index!C28)} -> -76 | C30: =B30/$C$1 -> -0.072866731 | E30: =C30*$E$1 -> -17.7619
A31: Taxes Paid | B31: {=INDEX(CshFlwData!$B$1:$B$76,Index!C29)} -> 13 | C31: =B31/$C$1 -> 0.012464046 | E31: =C31*$E$1 -> 3.0382197
A32: Interest Paid | B32: {=INDEX(CshFlwData!$B$1:$B$76,Index!C30)} -> 31 | C32: =B32/$C$1 -> 0.029721956 | E32: =C32*$E$1 -> 7.2449854
